Workbook

Sheet DICIEMBRE.2025
A5: CTA.CTE DICIEMBRE - 2025 - CARGAS + HIELO | K5: SEMANA DEL 1/12 AL 7/12
A6: CARGAS COMBUSTIBLE YPF | K6: RESUMEN CONSUMO
A7: FECHA | B7: FACTURA | C7: N° COMP | D7: VEHICULO | E7: PAGOS | F7: CONSUMOS | G7: SALDO | H7: LITROS | I7: OBSEVACIONES | K7: RESUMEN | L7: CONSUMO | M7: LTS
D8: SALDO ANTERIOR | G8: =SUM(E8:F8) -> 0
G9: =+G8+E9-F9 -> 0
G10: =+G9+E10-F10 -> 0
G11: =+G10+E11-F11 -> 0
G12: =+G11+E12-F12 -> 0
G13: =+G12+E13-F13 -> 0
G14: =+G13+E14-F14 -> 0
G15: =+G14+E15-F15 -> 0
G16: =+G15+E16-F16 -> 0
G17: =+G16+E17-F17 -> 0
G18: =+G17+E18-F18 -> 0
G19: =+G18+E19-F19 -> 0
G20: =+G19+E20-F20 -> 0
... G39: =+G38+E39-F39 -> 0
A40: 45991 | C40: SALDO ANTERIOR | F40: 973849.91 | G40: =+G39+E40-F40 -> -973849.91 | K40: AG 378 AV | L40: COMBUSTIBLE | M40: 0
A41: 45992 | B41: FA | C41: 92-0586 | D41: PFG 964 | F41: 26149.13 | G41: =+G40+E41-F41 -> -999999.04 | H41: 7.119 | I41: COMBUSTIBLE + HIELO | K41: AG 337 MY | L41: COMBUSTIBLE | M41: =SUM(H61) -> 11.627
A42: 45992 | B42: FA | C42: 60-7935 | D42: PFG 964 | F42: 81338.21 | G42: =+G41+E42-F42 -> -1081337.2 | H42: 45.335 | I42: COMBUSTIBLE | K42: AG 962 EW | L42: COMBUSTIBLE | M42: 0
A43: 45992 | B43: RE | C43: 50-0011 | D43: TRANSF | E43: 2000000 | G43: =+G42+E43-F43 -> 918662.75 | I43: PAGO - SALDO A FAVOR | K43: AA 183 PK | L43: COMBUSTIBLE | M43: =SUM(H46+H70+H88) -> 73.344
A44: 45992 | B44: FA | C44: 63-0528 | D44: WNO 918 | F44: 224384.16 | G44: =+G43+E44-F44 -> 694278.59 | H44: 128 | I44: COMBUSTIBLE | K44: OHA 122 | L44: COMBUSTIBLE | M44: 0
A45: 45992 | B45: FA | C45: 63-0531 | D45: HKQ 258 | F45: 528508.89 | G45: =+G44+E45-F45 -> 165769.7 | H45: 223.376 | I45: COMBUSTIBLE | K45: KEX 251 | L45: COMBUSTIBLE | M45: =SUM(H67+H87) -> 48.794
A46: 45992 | B46: FA | C46: 55-6980 | D46: AA 183 PK | F46: 58100.15 | G46: =+G45+E46-F46 -> 107669.55 | H46: 24.55 | I46: COMBUSTIBLE | K46: AF 728 AT | L46: COMBUSTIBLE | M46: =SUM(H76+H85) -> 94.965
A47: 45992 | B47: FA | C47: 55-6982 | D47: LVX 455 | F47: 13100 | G47: =+G46+E47-F47 -> 94569.55 | H47: * | I47: HIELO | K47: PFG 964 | L47: COMBUSTIBLE | M47: =SUM(H41+H42+H62+H71+H83) -> 163.838
A48: 45992 | B48: FA | C48: 63-0537 | D48: AG 958 JV | F48: 291286.9 | G48: =+G47+E48-F48 -> -196717.35 | H48: 157.565 | I48: COMBUSTIBLE | K48: NSN 325 | L48: COMBUSTIBLE | M48: 0
A49: 45992 | B49: FA | C49: 55-7000 | D49: KJR 926 | F49: 45000.15 | G49: =+G48+E49-F49 -> -241717.5 | H49: 24.55 | I49: COMBUSTIBLE | K49: LVX 455 | L49: COMBUSTIBLE | M49: =SUM(H56+H74+H84) -> 106.229
A50: 45993 | B50: FA | C50: 92-0622 | D50: LVX 455 | F50: 26200 | G50: =+G49+E50-F50 -> -267917.5 | H50: * | I50: 2 HIELO | K50: AG 958 JV | L50: COMBUSTIBLE | M50: =SUM(H48+H81) -> 340.41
A51: 45993 | B51: FA | C51: 55-7023 | D51: HLW 156 | F51: 58100.49 | G51: =+G50+E51-F51 -> -326017.99 | H51: 24.577 | I51: COMBUSTIBLE+HIELO | K51: AG 768 OI | L51: COMBUSTIBLE | M51: =SUM(H52+H54+H72+H82) -> 1217.501
A52: 45993 | B52: FA | C52: 63-0556 | D52: AG 768 OI | F52: 342355.58 | G52: =+G51+E52-F52 -> -668373.57 | H52: 185.272 | I52: COMBUSTIBLE | K52: KJR 926 | L52: COMBUSTIBLE | M52: =SUM(H49+H58+H65+H86+H89) -> 123.236
A53: 45993 | B53: RE | C53: 50-0016 | D53: TRANSF | E53: 1500000 | G53: =+G52+E53-F53 -> 831626.43 | I53: PAGO - SALDO A FAVOR | K53: IHX 980 | L53: COMBUSTIBLE | M53: 0
A54: 45993 | B54: FA | C54: 63-0571 | D54: AG 768 OI | F54: 646685.28 | G54: =+G53+E54-F54 -> 184941.15 | H54: 351.672 | I54: COMBUSTIBLE | K54: HLW 156 | L54: COMBUSTIBLE | M54: =SUM(H51) -> 24.577
A55: 45993 | B55: FA | C55: 63-0572 | D55: HKQ 258 | F55: 547935.91 | G55: =+G54+E55-F55 -> -362994.76 | H55: 299.255 | I55: COMBUSTIBLE | K55: WNO 918 | L55: COMBUSTIBLE | M55: =SUM(H44+H80) -> 287.577
A56: 45994 | B56: FA | C56: 55-7079 | D56: LVX 455 | F56: 44999.11 | G56: =+G55+E56-F56 -> -407993.87 | H56: 24.337 | I56: COMBUSTIBLE | K56: HKQ 258 | L56: COMBUSTIBLE | M56: =SUM(H45+H55+H66+H79+H90) -> 1329.765
A57: 45994 | B57: FA | C57: 55-7080 | D57: LVX 455 | F57: 12200 | G57: =+G56+E57-F57 -> -420193.87 | H57: * | I57: HIELO | K57: FTL 303 | L57: COMBUSTIBLE | M57: 0
A58: 45994 | B58: FA | C58: 92-0690 | D58: KJR 926 | F58: 69399.11 | G58: =+G57+E58-F58 -> -489592.98 | H58: 24.337 | I58: COMBUSTIBLE + 4 HIELO | K58: AUTOELEVADOR-1 | L58: COMBUSTIBLE | M58: =SUM(H60) -> 40.634
A59: 45994 | B59: FA | C59: 92-0692 | D59: HLW 156 | F59: 24400 | G59: =+G58+E59-F59 -> -513992.98 | H59: * | I59: 4 HIELO | K59: HIELO | L59: HIELO 3 Y 12 KG | M59: 49 BOLSAS
A60: 45994 | B60: FA | C60: 55-7096 | D60: MULITA | F60: 118974.92 | G60: =+G59+E60-F60 -> -632967.9 | H60: 40.634 | I60: COMBUSTIBLE + 8 HIELOS | K60: LITROS SEMANAL | M60: =SUM(M40:M58) -> 3862.497
A61: 45994 | B61: FA | C61: 92-0708 | D61: AG 337 MY | F61: 21649.47 | G61: =+G60+E61-F61 -> -654617.37 | H61: 11.627 | I61: COMBUSTIBLE
A62: 45994 | B62: FA | C62: 60-8065 | D62: PFG 964 | F62: 69399.11 | G62: =+G61+E62-F62 -> -724016.48 | H62: 24.337 | I62: COMBUSTIBLE + 4 HIELOS
...

Sheet ENERO.2026
A5: CTA.CTE ENERO - 2026 - CARGAS+HIELO | K5: SEMANA DEL 1/1 AL 4/1
A6: CARGAS COMBUSTIBLE YPF | K6: RESUMEN CONSUMO
A7: FECHA | B7: FACTURA | C7: N° FA/COMP | D7: VEHICULO | E7: PAGOS | F7: CONSUMOS | G7: SALDO | H7: LITROS | I7: OBSEVACIONES | K7: RESUMEN | L7: CONSUMO | M7: LTS
D8: SALDO ANTERIOR | G8: =SUM(E8:F8) -> 0
G9: =+G8+E9-F9 -> 0
G10: =+G9+E10-F10 -> 0
G11: =+G10+E11-F11 -> 0
G12: =+G11+E12-F12 -> 0
G13: =+G12+E13-F13 -> 0
G14: =+G13+E14-F14 -> 0
G15: =+G14+E15-F15 -> 0
G16: =+G15+E16-F16 -> 0
G17: =+G16+E17-F17 -> 0
G18: =+G17+E18-F18 -> 0
G19: =+G18+E19-F19 -> 0
G20: =+G19+E20-F20 -> 0
... G39: =+G38+E39-F39 -> 0
C40: SALDO ANTERIOR | F40: 329222.61 | G40: =SUM(G39+E40-F40) -> -329222.61 | K40: AG 378 AV | L40: COMBUSTIBLE | M40: 0
A41: 46024 | B41: FA | C41: 92-2374 | D41: HLW 156 | F41: 37500 | G41: =+G40-F41+E41 -> -366722.61 | H41: * | I41: 5 HIELOS | K41: AG 337 MY | L41: COMBUSTIBLE | M41: 0
A42: 46024 | B42: FA | C42: 92-2375 | D42: AF 728 AT | F42: 24400 | G42: =+G41-F42+E42 -> -391122.61 | H42: * | I42: 5 HIELOS | K42: AG 962 EW | L42: COMBUSTIBLE | M42: 0
A43: 46024 | B43: FA | C43: 60-9527 | D43: MULITA | F43: 95719.32 | G43: =+G42-F43+E43 -> -486841.93 | H43: 51.462 | I43: COMBUSTIBLE | K43: AA 183 PK | L43: COMBUSTIBLE | M43: =SUM(H58) -> 24.142
A44: 46024 | B44: FA | C44: 98-0109 | D44: KJR 926 | F44: 69400.84 | G44: =+G43-F44+E44 -> -556242.77 | H44: 24.194 | I44: COMBUSTIBLE Y 4 HIELOS | K44: KEX 251 | L44: COMBUSTIBLE | M44: =SUM(H52+H60) -> 43.416
A45: 46024 | B45: FA | C45: 55-8742 | D45: LVX 455 | F45: 88465.73 | G45: =+G44-F45+E45 -> -644708.5 | H45: 35.051 | I45: COMBUSTIBLE Y 4 HIELOS | K45: AF 728 AT | L45: COMBUSTIBLE | M45: =SUM(H59) -> 77.955
A46: 46024 | B46: FA | C46: 98-0110 | D46: AG 958 JV | F46: 333935.1 | G46: =+G45-F46+E46 -> -978643.6 | H46: 179.535 | I46: COMBUSTIBLE | K46: PFG 964 | L46: COMBUSTIBLE | M46: =SUM(H54) -> 24.103
A47: 46024 | B47: RE | C47: 50-0063 | D47: TRANSF | E47: 1000000 | G47: =+G46-F47+E47 -> 21356.4 | I47: PAGO - SALDO A FAVOR | K47: LVX 455 | L47: COMBUSTIBLE | M47: =SUM(H45) -> 35.051
A48: 46024 | B48: FA | C48: 98-0124 | D48: AG 768 OI | F48: 517846.32 | G48: =+G47-F48+E48 -> -496489.92 | H48: 278.412 | I48: COMBUSTIBLE | K48: AG 958 JV | L48: COMBUSTIBLE | M48: =SUM(H46+H50) -> 214.692
A49: 46025 | B49: FA | C49: 98-0127 | D49: MULITA | F49: 66039.52 | G49: =+G48-F49+E49 -> -562529.44 | H49: 35.372 | I49: COMBUSTIBLE | K49: AG 768 OI | L49: COMBUSTIBLE | M49: =SUM(H48) -> 278.412
A50: 46025 | B50: FA | C50: 98-0128 | D50: AG 958 JV | F50: 65638.12 | G50: =+G49-F50+E50 -> -628167.56 | H50: 35.157 | I50: COMBUSTIBLE | K50: KJR 926 | L50: COMBUSTIBLE | M50: =SUM(H44+H57) -> 43.514
A51: 46025 | B51: FA | C51: 60-9578 | D51: MULITA | F51: 74035.32 | G51: =+G50-F51+E51 -> -702202.88 | H51: 21.355 | I51: COMBUSTIBLE Y 6 HIELOS | K51: HLW 156 | L51: COMBUSTIBLE | M51: 0
A52: 46025 | B52: FA | C52: 92-2446 | D52: KEX 251 | F52: 45000.3 | G52: =+G51-F52+E52 -> -747203.18 | H52: 24.103 | I52: COMBUSTIBLE | K52: WNO 918 | L52: COMBUSTIBLE | M52: =SUM(H55) -> 114.09
A53: 46025 | B53: FA | C53: 92-2447 | D53: KEX 251 | F53: 6100 | G53: =+G52-F53+E53 -> -753303.18 | H53: * | I53: HIELO | K53: HKQ 258 | L53: COMBUSTIBLE | M53: 0
A54: 46025 | B54: FA | C54: 55-8784 | D54: PFG 964 | F54: 45000.3 | G54: =+G53-F54+E54 -> -798303.48 | H54: 24.103 | I54: COMBUSTIBLE | K54: FTL 303 | L54: COMBUSTIBLE | M54: 0
A55: 46025 | B55: FA | C55: 98-0135 | D55: WNO 918 | F55: 199999.77 | G55: =+G54-F55+E55 -> -998303.25 | H55: 114.09 | I55: COMBUSTIBLE | K55: AUTOELEVADOR | L55: COMBUSTIBLE | M55: =SUM(H43+H49+H51) -> 108.189
A56: 46026 | B56: FA | C56: 55-8814 | D56: KEX 251 | F56: 13100 | G56: =+G55-F56+E56 -> -1011403.2 | H56: * | I56: HIELO | K56: HIELO | L56: HIELO 3 Y 12 KG | M56: 27 BOLSAS
A57: 46026 | B57: FA | C57: 92-2479 | D57: KJR 926 | F57: 62212.48 | G57: =+G56-F57+E57 -> -1073615.7 | H57: 19.32 | I57: COMBUSTIBLE Y 2 HIELOS | K57: LITROS SEMANAL | M57: =SUM(M43:M55) -> 963.564
A58: 46026 | B58: FA | C58: 55-8847 | D58: AA 183 PK | F58: 45000.69 | G58: =+G57-F58+E58 -> -1118616.4 | H58: 24.142 | I58: COMBUSTIBLE
A59: 46026 | B59: FA | C59: 55-8851 | D59: AF 728 AT | F59: 145308.12 | G59: =+G58-F59+E59 -> -1263924.5 | H59: 77.955 | I59: COMBUSTIBLE
A60: 46026 | B60: FA | C60: 55-8856 | D60: KEX 251 | F60: 35999.43 | G60: =+G59-F60+E60 -> -1299924 | H60: 19.313 | I60: COMBUSTIBLE
A61: TOTAL DE LITROS SEMANAL | H61: =SUM(H41:H60) -> 963.564
A62: SEMANA DEL 1/1 AL 4/1 | K62: SEMANA DEL 5/1 AL 11/1
...

Sheet FEBRERO.2026
A5: CTA.CTE FEBRERO - 2026 - CARGAS | K5: SEMANA DEL 1/2 AL 7/2
A6: CARGAS COMBUSTIBLE YPF | K6: RESUMEN CONSUMO
A7: FECHA | B7: FACTURA | C7: N° FA/COMP | D7: VEHICULO | E7: PAGOS | F7: CONSUMOS | G7: SALDO | H7: LITROS | I7: OBSEVACIONES | K7: RESUMEN | L7: CONSUMO | M7: LTS
D8: SALDO ANTERIOR | G8: =SUM(E8:F8) -> 0 | K8: AG 337 MY | L8: COMBUSTIBLE
G9: =+G8+E9-F9 -> 0 | K9: AG 962 EW | L9: COMBUSTIBLE
G10: =+G9+E10-F10 -> 0 | K10: AE 919 JA | L10: COMBUSTIBLE
G11: =+G10+E11-F11 -> 0 | K11: AA 183 PK | L11: COMBUSTIBLE
G12: =+G11+E12-F12 -> 0 | K12: MOTO AMARILLA | L12: COMBUSTIBLE
G13: =+G12+E13-F13 -> 0 | K13: KEX 251 | L13: COMBUSTIBLE | M13: =SUM(H9) -> 0
G14: =+G13+E14-F14 -> 0 | K14: AF 728 AT | L14: COMBUSTIBLE | M14: =SUM(H6) -> 0
G15: =+G14+E15-F15 -> 0 | K15: PFG 964 | L15: COMBUSTIBLE
G16: =+G15+E16-F16 -> 0 | K16: LVX 455 | L16: COMBUSTIBLE
G17: =+G16+E17-F17 -> 0 | K17: AG 958 JV | L17: COMBUSTIBLE | M17: =SUM(H8) -> 0
G18: =+G17+E18-F18 -> 0 | K18: AG 768 OI | L18: COMBUSTIBLE
G19: =+G18+E19-F19 -> 0 | K19: KJR 926 | L19: COMBUSTIBLE
G20: =+G19+E20-F20 -> 0 | K20: HLW 156 | L20: COMBUSTIBLE
G21: =+G20+E21-F21 -> 0 | K21: WNO 918 | L21: COMBUSTIBLE
G22: =+G21+E22-F22 -> 0 | K22: HKQ 258 | L22: COMBUSTIBLE | M22: =SUM(H10) -> 0
G23: =+G22+E23-F23 -> 0 | K23: FTL 303 | L23: COMBUSTIBLE
G24: =+G23+E24-F24 -> 0 | K24: AUTOELEVADOR-1 | L24: COMBUSTIBLE | M24: =SUM(H11) -> 0
G25: =+G24+E25-F25 -> 0 | K25: BIDON -(COMPRESOR/HIDROLAV)
G26: =+G25+E26-F26 -> 0 | K26: HIELO | L26: HIELO 3 Y 12 KG | M26: -
G27: =+G26+E27-F27 -> 0
G28: =+G27+E28-F28 -> 0
G29: =+G28+E29-F29 -> 0
G30: =+G29+E30-F30 -> 0
G31: =+G30+E31-F31 -> 0
G32: =+G31+E32-F32 -> 0
G33: =+G32+E33-F33 -> 0
G34: =+G33+E34-F34 -> 0
G35: =+G34+E35-F35 -> 0
G36: =+G35+E36-F36 -> 0
G37: =+G36+E37-F37 -> 0
G38: =+G37+E38-F38 -> 0
G39: =+G38+E39-F39 -> 0
A40: 46053 | C40: SALDO ANTERIOR | F40: 571397.1 | G40: =+G39+E40-F40 -> -571397.1 | K40: AG 378 AV | L40: COMBUSTIBLE | M40: 0
A41: 46054 | B41: FA | C41: 94-0207 | D41: FTL 303 | F41: 350351.16 | G41: =+G40+E41-F41 -> -921748.26 | H41: 186.357 | I41: COMBUSTIBLE | K41: AG 337 MY | L41: COMBUSTIBLE | M41: =SUM(H95) -> 66.411
A42: 46054 | B42: FA | C42: 60-0907 | D42: LVX 455 | F42: 77000.87 | G42: =+G41+E42-F42 -> -998749.13 | H42: 42.1392 | I42: COMBUSTIBLE | K42: AG 962 EW | L42: COMBUSTIBLE | M42: 0
A43: 46054 | B43: FA | C43: 92-4355 | D43: LVX 455 | F43: 45001.56 | G43: =+G42+E43-F43 -> -1043750.7 | H43: 23.937 | I43: COMBUSTIBLE | K43: AE 919 JA | L43: COMBUSTIBLE | M43: 0
A44: 46054 | B44: RE | C44: 50-0099 | D44: TRANSF | E44: 1000000 | G44: =+G43+E44-F44 -> -43750.69 | I44: PAGO - SALDO PENDIENTE | K44: AA 183 PK | L44: COMBUSTIBLE | M44: =SUM(H54+H62+H63+H75+H80+H85+H89) -> 167.3632
...

Sheet MARZO.2026
A5: CTA.CTE MARZO - 2026 - CARGAS | K5: SEMANA DEL 1/3 AL 7/3
A6: CARGAS COMBUSTIBLE YPF | K6: RESUMEN CONSUMO
A7: FECHA | B7: FACTURA | C7: N° FA/COMP | D7: VEHICULO | E7: PAGOS | F7: CONSUMOS | G7: SALDO | H7: LITROS | I7: OBSEVACIONES | K7: RESUMEN | L7: CONSUMO | M7: LTS
A8: 46081 | C8: SALDO ANTERIOR | E8: 2937839.1 | G8: =+E8-F8 -> 2937839.1 | K8: AG 378 AV | L8: COMBUSTIBLE | M8: 0
A9: 46082 | B9: FA | C9: 92-5858 | D9: AF 728 AT | F9: 163010.51 | G9: =+G8+E9-F9 -> 2774828.6 | H9: 82.957 | I9: COMBUSTIBLE | K9: AG 337 MY | L9: COMBUSTIBLE | M9: =SUM(H15) -> 70.7399
A10: 46082 | B10: FA | C10: 92-5864 | D10: KJR 926 | F10: 45000.47 | G10: =+G9+E10-F10 -> 2729828.1 | H10: 22.901 | I10: COMBUSTIBLE | K10: AG 962 EW | L10: COMBUSTIBLE | M10: 0
A11: 46082 | B11: FA | C11: 60-2112 | D11: HLW 156 | F11: 45000.47 | G11: =+G10+E11-F11 -> 2684827.6 | H11: 22.901 | I11: COMBUSTIBLE | K11: AE 919 JA | L11: COMBUSTIBLE | M11: =SUM(H14) -> 55.472
A12: 46082 | B12: FA | C12: 96-1392 | D12: LVX 455 | F12: 45000.47 | G12: =+G11+E12-F12 -> 2639827.2 | H12: 22.901 | I12: COMBUSTIBLE | K12: AA 183 PK | L12: COMBUSTIBLE | M12: =SUM(H26+H30+H41+H43+H47+H48) -> 117.235
A13: 46082 | B13: FA | C13: 92-5880 | D13: LVX 455 | F13: 47317.2 | G13: =+G12+E13-F13 -> 2592510 | H13: 24.08 | I13: COMBUSTIBLE | K13: MOTO AMARILLA | L13: COMBUSTIBLE | M13: 0
A14: 46082 | B14: FA | C14: 96-1397 | D14: AE 919 JA | F14: 109002.48 | G14: =+G13+E14-F14 -> 2483507.5 | H14: 55.472 | I14: COMBUSTIBLE | K14: MOTO GRIS | L14: COMBUSTIBLE | M14: 0
A15: 46082 | B15: FA | C15: 92-5884 | D15: AG 337 MY | F15: 139004 | G15: =+G14+E15-F15 -> 2344503.5 | H15: 70.7399 | I15: COMBUSTIBLE | K15: KEX 251 | L15: COMBUSTIBLE | M15: 0
A16: 46082 | B16: FA | C16: 94-0729 | D16: HKQ 258 | F16: 666007.28 | G16: =+G15+E16-F16 -> 1678496.2 | H16: 338.935 | I16: COMBUSTIBLE | K16: AF 728 AT | L16: COMBUSTIBLE | M16: =SUM(H9+H22+H29+H44) -> 264.4586
A17: 46082 | B17: FA | C17: 94-0730 | D17: AG 768 OI | F17: 750011.03 | G17: =+G16+E17-F17 -> 928485.19 | H17: 381.685 | I17: COMBUSTIBLE | K17: PFG 964 | L17: COMBUSTIBLE | M17: 0
A18: 46083 | B18: FA | C18: 94-0736 | D18: FTL 303 | F18: 673197.18 | G18: =+G17+E18-F18 -> 255288.01 | H18: 362.714 | I18: COMBUSTIBLE | K18: LVX 455 | L18: COMBUSTIBLE | M18: =SUM(H12+H13) -> 46.981
A19: 46083 | B19: FA | C19: 98-1068 | D19: AG 958 JV | F19: 325687.06 | G19: =+G18+E19-F19 -> -70399.05 | H19: 165.072 | I19: COMBUSTIBLE | K19: AG 958 JV | L19: COMBUSTIBLE | M19: =SUM(H19+H23+H39+H40) -> 379.043
A20: 46083 | B20: FA | C20: 94-0742 | D20: AG 958 JV | F20: 24400 | G20: =+G19+E20-F20 -> -94799.05 | H20: * | I20: 4 HIELOS | K20: AG 768 OI | L20: COMBUSTIBLE | M20: =SUM(H17+H25+H37+H45) -> 1431.758
A21: 46083 | B21: RE | C21: 50-0145 | D21: TRANSF | E21: 1500000 | G21: =+G20+E21-F21 -> 1405200.9 | I21: PAGO - SALDO A FAVOR | K21: KJR 926 | L21: COMBUSTIBLE | M21: =SUM(H10+H24+H38+H49) -> 90.258
A22: 46083 | B22: FA | C22: 96-1452 | D22: AF 728 AT | F22: 114003 | G22: =+G21+E22-F22 -> 1291197.9 | H22: 57.7816 | I22: COMBUSTIBLE | K22: HLW 156 | L22: COMBUSTIBLE | M22: =SUM(H11+H50) -> 45.156
A23: 46083 | B23: FA | C23: 94-0746 | D23: AG 958 JV | F23: 73734.96 | G23: =+G22+E23-F23 -> 1217463 | H23: 37.372 | I23: COMBUSTIBLE | K23: WNO 918 | L23: COMBUSTIBLE | M23: =SUM(H33) -> 138.602
A24: 46084 | B24: FA | C24: 96-1489 | D24: KJR 926 | F24: 44999.59 | G24: =+G23+E24-F24 -> 1172463.4 | H24: 22.647 | I24: COMBUSTIBLE | K24: HKQ 258 | L24: COMBUSTIBLE | M24: =SUM(H16+H28) -> 660.047
A25: 46084 | B25: FA | C25: 94-0758 | D25: AG 768 OI | F25: 1190373.9 | G25: =+G24+E25-F25 -> -17910.55 | H25: 599.081 | I25: COMBUSTIBLE | K25: FTL 303 | L25: COMBUSTIBLE | M25: =SUM(H18+H34) -> 630.5236
A26: 46084 | B26: FA | C26: 96-1495 | D26: AA 183 PK | F26: 44999.59 | G26: =+G25+E26-F26 -> -62910.14 | H26: 22.647 | I26: COMBUSTIBLE | K26: AUTOELEVADOR | L26: COMBUSTIBLE | M26: =SUM(H31+H46) -> 55.427
A27: 46084 | B27: FA | C27: 60-2230 | D27: OXJ 846 | F27: 44999.16 | G27: =+G26+E27-F27 -> -107909.3 | H27: 26.377 | I27: ENJOY | K27: OXJ 846 | L27: ENJOY | M27: =SUM(H27) -> 26.377
A28: 46084 | B28: FA | C28: 94-0775 | D28: HKQ 258 | F28: 638049.54 | G28: =+G27+E28-F28 -> -745958.84 | H28: 321.112 | I28: COMBUSTIBLE | K28: HIELO | L28: 3KG Y 12KG | M28: 4 BOLSAS
A29: 46084 | B29: FA | C29: 92-6007 | D29: AF 728 AT | F29: 119895.58 | G29: =+G28+E29-F29 -> -865854.42 | H29: 60.34 | I29: COMBUSTIBLE | K29: LITROS SEMANAL | M29: =SUM(M9:M27) -> 4012.0781
A30: 46085 | B30: FA | C30: 92-6020 | D30: AA 183 PK | F30: 45000.6 | G30: =+G29+E30-F30 -> -910855.02 | H30: 22.433 | I30: COMBUSTIBLE
A31: 46085 | B31: FA | C31: 60-2244 | D31: MULITA | F31: 68821.35 | G31: =+G30+E31-F31 -> -979676.37 | H31: 36.862 | I31: COMBUSTIBLE
A32: 46085 | B32: RE | C32: 50-0148 | D32: TRANSF | E32: 900000 | G32: =+G31+E32-F32 -> -79676.37 | I32: PAGO - SALDO PENDIENTE
A33: 46085 | B33: FA | C33: 94-0783 | D33: WNO 918 | F33: 258769.93 | G33: =+G32+E33-F33 -> -338446.3 | H33: 138.602 | I33: COMBUSTIBLE
A34: 46085 | B34: FA | C34: 94-0784 | D34: FTL 303 | F34: 500000.54 | G34: =+G33+E34-F34 -> -838446.84 | H34: 267.8096 | I34: COMBUSTIBLE
A35: 46085 | B35: RE | C35: 98-0001 | D35: LINK MP | F35: 16443.9 | G35: =+G34+E35-F35 -> -854890.74 | I35: CARGO DE MERCADO PAGO
A36: 46085 | B36: FA | C36: 50-0149 | D36: TRANSF | E36: 2000000 | G36: =+G35+E36-F36 -> 1145109.3 | I36: PAGO - SALDO A FAVOR
A37: 46086 | B37: FA | C37: 98-1093 | D37: AG 768 OI | F37: 830036.76 | G37: =+G36+E37-F37 -> 315072.5 | H37: 414.19 | I37: COMBUSTIBLE
A38: 46086 | B38: FA | C38: 96-1592 | D38: KJR 926 | F38: 44999.82 | G38: =+G37+E38-F38 -> 270072.68 | H38: 22.455 | I38: COMBUSTIBLE
A39: 46086 | B39: FA | C39: 98-1097 | D39: AG 958 JV | F39: 316605.95 | G39: =+G38+E39-F39 -> -46533.27 | H39: 157.987 | I39: COMBUSTIBLE
A40: 46086 | B40: FA | C40: 98-1098 | D40: AG 958 JV | F40: 37298.45 | G40: =+G39+E40-F40 -> -83831.72 | H40: 18.612 | I40: COMBUSTIBLE
A41: 46086 | B41: FA | C41: 92-6088 | D41: AA 183 PK | F41: 44999.82 | G41: =+G40+E41-F41 -> -128831.54 | H41: 22.455 | I41: COMBUSTIBLE
A42: 46086 | B42: RE | C42: 50-0150 | D42: TRANSF | E42: 1000000 | G42: =+G41+E42-F42 -> 871168.46 | I42: PAGO - SALDO A FAVOR
A43: 46086 | B43: FA | C43: 96-1631 | D43: AA 183 PK | F43: 44999.82 | G43: =+G42+E43-F43 -> 826168.64 | H43: 22.455 | I43: COMBUSTIBLE
A44: 46086 | B44: FA | C44: 60-2321 | D44: AF 728 AT | F44: 127013.52 | G44: =+G43+E44-F44 -> 699155.12 | H44: 63.38 | I44: COMBUSTIBLE
...

Sheet ABRIL.2026
A5: CTA.CTE ABRIL - 2026 - CARGAS | K5: SEMANA DEL 1/4 AL 4/4
A6: CARGAS COMBUSTIBLE YPF | K6: RESUMEN CONSUMO
A7: FECHA | B7: FACTURA | C7: N° FA/COMP | D7: VEHICULO | E7: PAGOS | F7: CONSUMOS | G7: SALDO | H7: LITROS | I7: OBSEVACIONES | K7: RESUMEN | L7: CONSUMO | M7: LTS
D8: SALDO ANTERIOR | G8: =SUM(E8:F8) -> 0 | K8: AG 337 MY | L8: COMBUSTIBLE
G9: =+G8+E9-F9 -> 0 | K9: AG 962 EW | L9: COMBUSTIBLE
G10: =+G9+E10-F10 -> 0 | K10: AE 919 JA | L10: COMBUSTIBLE
G11: =+G10+E11-F11 -> 0 | K11: AA 183 PK | L11: COMBUSTIBLE
G12: =+G11+E12-F12 -> 0 | K12: MOTO AMARILLA | L12: COMBUSTIBLE
G13: =+G12+E13-F13 -> 0 | K13: KEX 251 | L13: COMBUSTIBLE | M13: =SUM(H9) -> 0
G14: =+G13+E14-F14 -> 0 | K14: AF 728 AT | L14: COMBUSTIBLE | M14: =SUM(H6) -> 0
G15: =+G14+E15-F15 -> 0 | K15: PFG 964 | L15: COMBUSTIBLE
G16: =+G15+E16-F16 -> 0 | K16: LVX 455 | L16: COMBUSTIBLE
G17: =+G16+E17-F17 -> 0 | K17: AG 958 JV | L17: COMBUSTIBLE | M17: =SUM(H8) -> 0
G18: =+G17+E18-F18 -> 0 | K18: AG 768 OI | L18: COMBUSTIBLE
G19: =+G18+E19-F19 -> 0 | K19: KJR 926 | L19: COMBUSTIBLE
G20: =+G19+E20-F20 -> 0 | K20: HLW 156 | L20: COMBUSTIBLE
G21: =+G20+E21-F21 -> 0 | K21: WNO 918 | L21: COMBUSTIBLE
G22: =+G21+E22-F22 -> 0 | K22: HKQ 258 | L22: COMBUSTIBLE | M22: =SUM(H10) -> 0
G23: =+G22+E23-F23 -> 0 | K23: FTL 303 | L23: COMBUSTIBLE
G24: =+G23+E24-F24 -> 0 | K24: AUTOELEVADOR-1 | L24: COMBUSTIBLE | M24: =SUM(H11) -> 0
G25: =+G24+E25-F25 -> 0 | K25: BIDON -(COMPRESOR/HIDROLAV)
G26: =+G25+E26-F26 -> 0 | K26: HIELO | L26: HIELO 3 Y 12 KG | M26: -
G27: =+G26+E27-F27 -> 0
G28: =+G27+E28-F28 -> 0
G29: =+G28+E29-F29 -> 0
G30: =+G29+E30-F30 -> 0
G31: =+G30+E31-F31 -> 0
G32: =+G31+E32-F32 -> 0
G33: =+G32+E33-F33 -> 0
G34: =+G33+E34-F34 -> 0
G35: =+G34+E35-F35 -> 0
G36: =+G35+E36-F36 -> 0
G37: =+G36+E37-F37 -> 0
G38: =+G37+E38-F38 -> 0
G39: =+G38+E39-F39 -> 0
C40: SALDO ANTERIOR | F40: 471748.76 | G40: =+G39+E40-F40 -> -471748.76 | K40: AG 378 AV | L40: COMBUSTIBLE | M40: 0
A41: 46113 | B41: FA | C41: 92-7449 | D41: PFG 964 | F41: 45000.11 | G41: =+G40+E41-F41 -> -516748.87 | H41: 19.198 | I41: COMBUSTIBLE | K41: AG 337 MY | L41: COMBUSTIBLE | M41: 0
A42: 46113 | B42: FA | C42: 96-3011 | D42: AG 962 EW | F42: 128005.84 | G42: =+G41+E42-F42 -> -644754.71 | H42: 54.61 | I42: COMBUSTIBLE | K42: AG 962 EW | L42: COMBUSTIBLE | M42: =SUM(H42) -> 54.61
A43: 46113 | B43: RE | C43: 50-0194 | D43: TRANSF | E43: 2000000 | G43: =+G42+E43-F43 -> 1355245.3 | I43: PAGO - SALDO A FAVOR | K43: AE 919 JA | L43: COMBUSTIBLE | M43: =SUM(H50+H56+H68) -> 57.594
A44: 46113 | B44: FA | C44: 96-3027 | D44: MOTO AMARILLA | F44: 20181.74 | G44: =+G43+E44-F44 -> 1335063.6 | H44: 9.207 | I44: COMBUSTIBLE | K44: AA 183 PK | L44: COMBUSTIBLE | M44: =SUM(H47+H53) -> 38.4
...

Sheet MAYO.2026
A5: CTA.CTE MAYO - 2026 - CARGAS | K5: SEMANA DEL 1/5 AL 9/5
A6: CARGAS COMBUSTIBLE YPF | K6: RESUMEN CONSUMO
A7: FECHA | B7: FACTURA | C7: N° FA/COMP | D7: VEHICULO | E7: PAGOS | F7: CONSUMOS | G7: SALDO | H7: LITROS | I7: OBSEVACIONES | K7: RESUMEN | L7: CONSUMO | M7: LTS
A8: 46142 | C8: SALDO ANTERIOR | E8: 148710.66 | G8: =+E8-F8 -> 148710.66 | K8: AG 378 AV | L8: COMBUSTIBLE | M8: 0
A9: 46143 | B9: FA | C9: 96-4382 | D9: KEX 251 | F9: 60000.03 | G9: =+G8+E9-F9 -> 88710.63 | H9: 25.652 | I9: COMBUSTIBLE | K9: AG 337 MY | L9: COMBUSTIBLE | M9: 0
A10: 46143 | B10: FA | C10: 60-4644 | D10: LVX 455 | F10: 60000.03 | G10: =+G9+E10-F10 -> 28710.6 | H10: 25.652 | I10: COMBUSTIBLE | K10: AG 962 EW | L10: COMBUSTIBLE | M10: 0
A11: 46143 | B11: FA | C11: 60-4645 | D11: AF 728 AT | F11: 152725.01 | G11: =+G10+E11-F11 -> -124014.41 | H11: 65.295 | I11: COMBUSTIBLE | K11: AE 919 JA | L11: COMBUSTIBLE | M11: =SUM(H12+H18+H20+H31+H49+H50+H55) -> 196.283
A12: 46143 | B12: FA | C12: 60-4647 | D12: AE 919 JA | F12: 60000.03 | G12: =+G11+E12-F12 -> -184014.44 | H12: 25.652 | I12: COMBUSTIBLE | K12: AA 183 PK | L12: COMBUSTIBLE | M12: 0
A13: 46143 | B13: FA | C13: 60-4648 | D13: MULITA | F13: 90004.72 | G13: =+G12+E13-F13 -> -274019.16 | H13: 38.48 | I13: COMBUSTIBLE | K13: MOTO AMARILLA | L13: COMBUSTIBLE | M13: 0
A14: 46143 | B14: FA | C14: 92-8996 | D14: PFG 964 | F14: 60000.03 | G14: =+G13+E14-F14 -> -334019.19 | H14: 25.652 | I14: COMBUSTIBLE | K14: MOTO GRIS | L14: COMBUSTIBLE | M14: =SUM(H24) -> 11.677
A15: 46143 | B15: FA | C15: 96-4389 | D15: KJR 926 | F15: 60000.03 | G15: =+G14+E15-F15 -> -394019.22 | H15: 25.652 | I15: COMBUSTIBLE | K15: KEX 251 | L15: COMBUSTIBLE | M15: =SUM(H9+H21+H29+H44+H54+H60) -> 163.924
A16: 46144 | B16: FA | C16: 94-1988 | D16: AG 768 OI | F16: 805362.52 | G16: =+G15+E16-F16 -> -1199381.7 | H16: 343.423 | I16: COMBUSTIBLE | K16: AF 728 AT | L16: COMBUSTIBLE | M16: =SUM(H11) -> 65.295
A17: 46145 | B17: FA | C17: 92-9037 | D17: HLW 156 | F17: 59999.37 | G17: =+G16+E17-F17 -> -1259381.1 | H17: 25.597 | I17: COMBUSTIBLE | K17: PFG 964 | L17: COMBUSTIBLE | M17: =SUM(H14+H26+H45) -> 76.847
A18: 46145 | B18: FA | C18: 96-4414 | D18: AE 919 JA | F18: 40000.36 | G18: =+G17+E18-F18 -> -1299381.5 | H18: 17.065 | I18: COMBUSTIBLE | K18: LVX 455 | L18: COMBUSTIBLE | M18: =SUM(H10+H25+H30+H37+H47+H57+H67) -> 179.139
A19: 46146 | B19: RE | C19: 50-0241 | D19: TRANSF | E19: 1000000 | G19: =+G18+E19-F19 -> -299381.47 | I19: PAGO - SALDO PENDIENTE | K19: AG 958 JV | L19: COMBUSTIBLE | M19: =SUM(H33+H59) -> 260.322
A20: 46146 | B20: FA | C20: 96-4475 | D20: AE 919 JA | F20: 99999.9 | G20: =+G19+E20-F20 -> -399381.37 | H20: 42.735 | I20: COMBUSTIBLE | K20: AG 768 OI | L20: COMBUSTIBLE | M20: =SUM(H16+H42) -> 471.628
A21: 46146 | B21: FA | C21: 96-4479 | D21: KEX 251 | F21: 60000 | G21: =+G20+E21-F21 -> -459381.37 | H21: 25.641 | I21: COMBUSTIBLE | K21: KJR 926 | L21: COMBUSTIBLE | M21: =SUM(H15+H32+H34+H56+H64) -> 127.944
A22: 46146 | B22: RE | C22: 50-0242 | D22: TRANSF | E22: 1500000 | G22: =+G21+E22-F22 -> 1040618.6 | I22: PAGO - SALDO A FAVOR | K22: HLW 156 | L22: COMBUSTIBLE | M22: =SUM(H17+H28+H35+H66) -> 102.335
A23: 46146 | B23: FA | C23: 60-4808 | D23: MULITA | F23: 140400 | G23: =+G22+E23-F23 -> 900218.63 | H23: 60 | I23: COMBUSTIBLE | K23: WNO 918 | L23: COMBUSTIBLE | M23: =SUM(H61) -> 130.065
A24: 46146 | B24: FA | C24: 92-9096 | D24: MOTO GRIS | F24: 25595.98 | G24: =+G23+E24-F24 -> 874622.65 | H24: 11.677 | I24: COMBUSTIBLE | K24: HKQ 258 | L24: COMBUSTIBLE | M24: =SUM(H40) -> 186.49
A25: 46146 | B25: FA | C25: 92-9109 | D25: LVX 455 | F25: 59999.94 | G25: =+G24+E25-F25 -> 814622.71 | H25: 25.641 | I25: COMBUSTIBLE | K25: FTL 303 | L25: COMBUSTIBLE | M25: =SUM(H27+H46+H62) -> 467.729
A26: 46146 | B26: FA | C26: 92-9110 | D26: PFG 964 | F26: 59999.94 | G26: =+G25+E26-F26 -> 754622.77 | H26: 25.641 | I26: COMBUSTIBLE | K26: AUTOELEVADOR | L26: COMBUSTIBLE | M26: =SUM(H13+H23+H36+H41+H43+H48+H52+H58+H65) -> 275.228
A27: 46147 | B27: FA | C27: 94-2048 | D27: FTL 303 | F27: 299998.98 | G27: =+G26+E27-F27 -> 454623.79 | H27: 134.831 | I27: COMBUSTIBLE | K27: LITROS SEMANAL | M27: =SUM(M8:M26) -> 2714.906
A28: 46147 | B28: FA | C28: 92-9120 | D28: HLW 156 | F28: 59999.94 | G28: =+G27+E28-F28 -> 394623.85 | H28: 25.641 | I28: COMBUSTIBLE
A29: 46147 | B29: FA | C29: 96-4518 | D29: KEX 251 | F29: 59999.94 | G29: =+G28+E29-F29 -> 334623.91 | H29: 25.641 | I29: COMBUSTIBLE
A30: 46147 | B30: FA | C30: 96-4519 | D30: LVX 455 | F30: 59999.94 | G30: =+G29+E30-F30 -> 274623.97 | H30: 25.641 | I30: COMBUSTIBLE
A31: 46147 | B31: FA | C31: 96-4533 | D31: AE 919 JA | F31: 59999.94 | G31: =+G30+E31-F31 -> 214624.03 | H31: 25.641 | I31: COMBUSTIBLE
A32: 46147 | B32: FA | C32: 96-4535 | D32: KJR 926 | F32: 59999.94 | G32: =+G31+E32-F32 -> 154624.09 | H32: 25.641 | I32: COMBUSTIBLE
A33: 46147 | B33: FA | C33: 94-2068 | D33: AG 958 JV | F33: 299999.7 | G33: =+G32+E33-F33 -> -145375.61 | H33: 128.205 | I33: COMBUSTIBLE
A34: 46148 | B34: FA | C34: 96-4569 | D34: KJR 926 | F34: 59999.94 | G34: =+G33+E34-F34 -> -205375.55 | H34: 25.641 | I34: COMBUSTIBLE
A35: 46148 | B35: FA | C35: 60-4860 | D35: HLW 156 | F35: 59999.94 | G35: =+G34+E35-F35 -> -265375.49 | H35: 25.641 | I35: COMBUSTIBLE
A36: 46148 | B36: FA | C36: 96-4573 | D36: MULITA | F36: 40001.83 | G36: =+G35+E36-F36 -> -305377.32 | H36: 17.93 | I36: COMBUSTIBLE
A37: 46148 | B37: FA | C37: 96-4574 | D37: LVX 455 | F37: 59999.94 | G37: =+G36+E37-F37 -> -365377.26 | H37: 25.641 | I37: COMBUSTIBLE
A38: 46148 | B38: RE | C38: 50-0248 | D38: TRANSF MP | E38: 600000 | G38: =+G37+E38-F38 -> 234622.74 | I38: PAGO - SALDO A FAVOR
A39: 46148 | B39: RE | C39: 50-0248 | D39: TRANSF BCO | E39: 400000 | G39: =+G38+E39-F39 -> 634622.74 | I39: PAGO - SALDO A FAVOR
A40: 46148 | B40: FA | C40: 98-1634 | D40: HKQ 258 | F40: 416059.19 | G40: =G39-F40 -> 218563.55 | H40: 186.49 | I40: COMBUSTIBLE
A41: 46148 | B41: FA | C41: 98-1635 | D41: MULITA | F41: 40068.76 | G41: =+G40+E41-F41 -> 178494.79 | H41: 17.96 | I41: COMBUSTIBLE
A42: 46148 | B42: FA | C42: 98-1638 | D42: AG 768 OI | F42: 299999.7 | G42: =+G41+E42-F42 -> -121504.91 | H42: 128.205 | I42: COMBUSTIBLE
A43: 46148 | B43: FA | C43: 60-4881 | D43: MULITA | F43: 85028.58 | G43: =+G42+E43-F43 -> -206533.49 | H43: 36.337 | I43: COMBUSTIBLE
A44: 46148 | B44: FA | C44: 60-4894 | D44: KEX 251 | F44: 45000.54 | G44: =+G43+E44-F44 -> -251534.03 | H44: 19.231 | I44: COMBUSTIBLE
...

Sheet JUNIO.2026
A5: CTA.CTE JUNIO - 2026 - CARGAS | K5: SEMANA DEL 1/6 AL 6/6
A6: CARGAS COMBUSTIBLE YPF | K6: RESUMEN CONSUMO
A7: FECHA | B7: TIPO | C7: N° FA/COMP | D7: VEHICULO | E7: PAGOS | F7: CONSUMOS | G7: SALDO | H7: LITROS | I7: OBSEVACIONES | K7: RESUMEN | L7: CONSUMO | M7: LTS
A8: 46173 | C8: SALDO ANTERIOR | E8: 294999.3 | G8: =+E8-F8 -> 294999.3 | K8: AG 378 AV | L8: COMBUSTIBLE | M8: 0
A9: 46174 | B9: FA | C9: 98-1867 | D9: FTL 303 | F9: 542358.78 | G9: =+G8+E9-F9 -> -247359.48 | H9: 239.452 | I9: COMBUSTIBLE | K9: AG 337 MY | L9: COMBUSTIBLE | M9: =SUM(H28) -> 72.332
A10: 46174 | B10: FA | C10: 96-5801 | D10: KEX 251 | F10: 60000.95 | G10: =+G9+E10-F10 -> -307360.43 | H10: 25.105 | I10: COMBUSTIBLE | K10: AG 962 EW | L10: COMBUSTIBLE | M10: 0
A11: 46174 | B11: FA | C11: 92-0451 | D11: PFG 964 | F11: 60000.95 | G11: =+G10+E11-F11 -> -367361.38 | H11: 25.105 | I11: COMBUSTIBLE | K11: AE 919 JA | L11: COMBUSTIBLE | M11: =SUM(H16+H19+H29+H43) -> 100.283
A12: 46174 | B12: FA | C12: 96-5804 | D12: KJR 926 | F12: 60000.95 | G12: =+G11+E12-F12 -> -427362.33 | H12: 25.105 | I12: COMBUSTIBLE | K12: AA 183 PK | L12: COMBUSTIBLE | M12: =SUM(H14+H24+H32+H46) -> 100.22
A13: 46174 | B13: FA | C13: 96-5805 | D13: MULITA | F13: 42842.48 | G13: =+G12+E13-F13 -> -470204.81 | H13: 18.915 | I13: COMBUSTIBLE | K13: MOTO AMARILLA | L13: COMBUSTIBLE | M13: 0
A14: 46174 | B14: FA | C14: 96-5806 | D14: AA 183 PK | F14: 60000.95 | G14: =+G13+E14-F14 -> -530205.76 | H14: 25.105 | I14: COMBUSTIBLE | K14: MOTO GRIS | L14: COMBUSTIBLE | M14: 0
A15: 46174 | B15: FA | C15: 96-5807 | D15: HLW 156 | F15: 60000.95 | G15: =+G14+E15-F15 -> -590206.71 | H15: 25.105 | I15: COMBUSTIBLE | K15: KEX 251 | L15: COMBUSTIBLE | M15: =SUM(H10+H22+H33) -> 75.21
A16: 46174 | B16: FA | C16: 96-5819 | D16: AE 919 JA | F16: 60000.95 | G16: =+G15+E16-F16 -> -650207.66 | H16: 25.105 | I16: COMBUSTIBLE | K16: AF 728 AT | L16: COMBUSTIBLE | M16: 0
A17: 46174 | B17: FA | C17: 92-0475 | D17: LVX 455 | F17: 64111.75 | G17: =+G16+E17-F17 -> -714319.41 | H17: 26.825 | I17: COMBUSTIBLE | K17: PFG 964 | L17: COMBUSTIBLE | M17: =SUM(H11) -> 25.105
A18: 46175 | B18: RE | C18: 50-0293 | D18: TRANSF | E18: 1000000 | G18: =+G17+E18-F18 -> 285680.59 | I18: PAGO - SALDO A FAVOR | K18: LVX 455 | L18: COMBUSTIBLE | M18: =SUM(H17+H35+H41+H44) -> 95.653
A19: 46175 | B19: FA | C19: 60-6002 | D19: AE 919 JA | F19: 59999.31 | G19: =+G18+E19-F19 -> 225681.28 | H19: 25.031 | I19: COMBUSTIBLE | K19: AG 958 JV | L19: COMBUSTIBLE | M19: =SUM(H21+H38) -> 271.022
A20: 46175 | B20: FA | C20: 96-5868 | D20: MULITA | F20: 77713.76 | G20: =+G19+E20-F20 -> 147967.52 | H20: 34.205 | I20: COMBUSTIBLE | K20: AG 768 OI | L20: COMBUSTIBLE | M20: =SUM(H26) -> 131.271
A21: 46175 | B21: FA | C21: 94-2729 | D21: AG 958 JV | F21: 308781.54 | G21: =+G20+E21-F21 -> -160814.02 | H21: 128.82 | I21: COMBUSTIBLE | K21: KJR 926 | L21: COMBUSTIBLE | M21: =SUM(H12+H30+H39) -> 75.252
A22: 46176 | B22: FA | C22: 92-0565 | D22: KEX 251 | F22: 60000.93 | G22: =+G21+E22-F22 -> -220814.95 | H22: 25.084 | I22: COMBUSTIBLE | K22: HLW 156 | L22: COMBUSTIBLE | M22: =SUM(H15+H37+H45) -> 75.136
A23: 46176 | B23: FA | C23: 96-5917 | D23: MULITA | F23: 42876.54 | G23: =+G22+E23-F23 -> -263691.49 | H23: 18.905 | I23: COMBUSTIBLE | K23: WNO 918 | L23: COMBUSTIBLE | M23: =SUM(H25) -> 159.457
A24: 46176 | B24: FA | C24: 96-5918 | D24: AA 183 PK | F24: 60000.93 | G24: =+G23+E24-F24 -> -323692.42 | H24: 25.084 | I24: COMBUSTIBLE | K24: HKQ 258 | L24: COMBUSTIBLE | M24: =SUM(H31) -> 208.507
A25: 46176 | B25: FA | C25: 98-1892 | D25: WNO 918 | F25: 361648.48 | G25: =+G24+E25-F25 -> -685340.9 | H25: 159.457 | I25: COMBUSTIBLE | K25: FTL 303 | L25: COMBUSTIBLE | M25: =SUM(H9) -> 239.452
A26: 46176 | B26: FA | C26: 94-2745 | D26: AG 768 OI | F26: 314000.23 | G26: =+G25+E26-F26 -> -999341.13 | H26: 131.271 | I26: COMBUSTIBLE | K26: AUTOELEVADOR | L26: COMBUSTIBLE | M26: =SUM(H13+H20+H23+H34+H36+H40) -> 166.304
A27: 46176 | B27: RE | C27: 50-0297 | D27: TRANSF | E27: 1500000 | G27: =+G26+E27-F27 -> 500658.87 | I27: PAGO - SALDO A FAVOR | K27: LITROS SEMANAL | M27: =SUM(M8:M26) -> 1795.204
A28: 46176 | B28: FA | C28: 92-0593 | D28: AG 337 MY | F28: 173018.14 | G28: =+G27+E28-F28 -> 327640.73 | H28: 72.332 | I28: COMBUSTIBLE
A29: 46176 | B29: FA | C29: 60-6083 | D29: AE 919 JA | F29: 60000.93 | G29: =+G28+E29-F29 -> 267639.8 | H29: 25.084 | I29: COMBUSTIBLE
A30: 46176 | B30: FA | C30: 92-0608 | D30: KJR 926 | F30: 60000.93 | G30: =+G29+E30-F30 -> 207638.87 | H30: 25.084 | I30: COMBUSTIBLE
A31: 46177 | B31: FA | C31: 94-2772 | D31: HKQ 258 | F31: 499999.79 | G31: =+G30+E31-F31 -> -292360.92 | H31: 208.507 | I31: COMBUSTIBLE
A32: 46177 | B32: FA | C32: 92-0622 | D32: AA 183 PK | F32: 60000.36 | G32: =+G31+E32-F32 -> -352361.28 | H32: 25.021 | I32: COMBUSTIBLE
A33: 46177 | B33: FA | C33: 92-0623 | D33: KEX 251 | F33: 60000.36 | G33: =+G32+E33-F33 -> -412361.64 | H33: 25.021 | I33: COMBUSTIBLE
A34: 46177 | B34: FA | C34: 92-0624 | D34: MULITA | F34: 85292.68 | G34: =+G33+E34-F34 -> -497654.32 | H34: 37.607 | I34: COMBUSTIBLE
A35: 46177 | B35: FA | C35: 98-1898 | D35: LVX 455 | F35: 60000.36 | G35: =+G34+E35-F35 -> -557654.68 | H35: 25.021 | I35: COMBUSTIBLE
A36: 46177 | B36: FA | C36: 98-1899 | D36: MULITA | F36: 40352.26 | G36: =+G35+E36-F36 -> -598006.94 | H36: 17.792 | I36: COMBUSTIBLE
A37: 46177 | B37: FA | C37: 96-5965 | D37: HLW 156 | F37: 60000.36 | G37: =+G36+E37-F37 -> -658007.3 | H37: 25.021 | I37: COMBUSTIBLE
A38: 46177 | B38: FA | C38: 94-2777 | D38: AG 958 JV | F38: 341000.4 | G38: =+G37+E38-F38 -> -999007.7 | H38: 142.202 | I38: COMBUSTIBLE
A39: 46178 | B39: FA | C39: 96-6035 | D39: KJR 926 | F39: 60000.82 | G39: =+G38+E39-F39 -> -1059008.5 | H39: 25.063 | I39: COMBUSTIBLE
... A41: 46178 | B41: FA | C41: 96-6037 | D41: LVX 455 | F41: 45000.02 | G41: =+G40+E41-F41 -> -1192032.9 | H41: 18.797 | I41: COMBUSTIBLE
A42: 46178 | B42: RE | C42: 50-0299 | D42: TRANSF | E42: 2000000 | G42: =+G41+E42-F42 -> 807967.14 | I42: PAGO - SALDO A FAVOR
A43: 46178 | B43: FA | C43: 60-6173 | D43: AE 919 JA | F43: 60000.82 | G43: =+G42+E43-F43 -> 747966.32 | H43: 25.063 | I43: COMBUSTIBLE
A44: 46179 | B44: FA | C44: 96-6097 | D44: LVX 455 | F44: 59998.99 | G44: =+G43+E44-F44 -> 687967.33 | H44: 25.01 | I44: COMBUSTIBLE
A45: 46179 | B45: FA | C45: 92-0745 | D45: HLW 156 | F45: 59998.99 | G45: =+G44+E45-F45 -> 627968.34 | H45: 25.01 | I45: COMBUSTIBLE
...

Sheet JULIO.2026
A5: CTA.CTE JULIO - 2026 - CARGAS | K5: SEMANA DEL 1/7 AL 4/7
A6: CARGAS COMBUSTIBLE YPF | K6: RESUMEN CONSUMO
A7: FECHA | B7: TIPO | C7: N° FA/COMP | D7: VEHICULO | E7: PAGOS | F7: CONSUMOS | G7: SALDO | H7: LITROS | I7: OBSEVACIONES | K7: RESUMEN | L7: CONSUMO | M7: LTS
A8: 46203 | C8: SALDO ANTERIOR | F8: 181680.85 | G8: =+E8-F8 -> -181680.85 | K8: AG 378 AV | L8: COMBUSTIBLE | M8: 0
A9: 46204 | B9: FA | C9: 94-3349 | D9: AG 958 JV | F9: 441269.4 | G9: =+G8+E9-F9 -> -622950.25 | H9: 183.48 | I9: COMBUSTIBLE | K9: AG 337 MY | L9: COMBUSTIBLE | M9: 0
A10: 46204 | B10: FA | C10: 92-1787 | D10: MULITA | F10: 86948.99 | G10: =+G9+E10-F10 -> -709899.24 | H10: 38.422 | I10: COMBUSTIBLE | K10: AG 962 EW | L10: COMBUSTIBLE | M10: =SUM(H11) -> 38.257
A11: 46204 | B11: FA | C11: 92-1790 | D11: AG 962 EW | F11: 92008.09 | G11: =+G10+E11-F11 -> -801907.33 | H11: 38.257 | I11: COMBUSTIBLE | K11: MOTO AMARILLA | L11: COMBUSTIBLE | M11: 0
A12: 46204 | B12: RE | C12: 50-0336 | D12: TRANSF | E12: 1000000 | G12: =+G11+E12-F12 -> 198092.67 | I12: PAGO - SALDO A FAVOR | K12: MOTO GRIS | L12: COMBUSTIBLE | M12: 0
A13: 46204 | B13: FA | C13: 96-7314 | D13: PFG 964 | F13: 59999.94 | G13: =+G12+E13-F13 -> 138092.73 | H13: 24.948 | I13: COMBUSTIBLE | K13: PFG 964 | L13: COMBUSTIBLE | M13: =SUM(H13+H16) -> 49.875
A14: 46205 | B14: FA | C14: 92-1830 | D14: HLW 156 | F14: 59999.36 | G14: =+G13+E14-F14 -> 78093.37 | H14: 24.896 | I14: COMBUSTIBLE | K14: LVX 455 | L14: COMBUSTIBLE | M14: =SUM(H18) -> 24.927
A15: 46206 | B15: FA | C15: 96-7369 | D15: PFG 964 | F15: 59999.29 | G15: =+G14+E15-F15 -> 18094.08 | H15: 24.927 | I15: COMBUSTIBLE | K15: AG 958 JV | L15: COMBUSTIBLE | M15: =SUM(H9) -> 183.48
A16: 46206 | B16: FA | C16: 96-7370 | D16: KJR 926 | F16: 59999.29 | G16: =+G15+E16-F16 -> -41905.21 | H16: 24.927 | I16: COMBUSTIBLE | K16: AG 768 OI | L16: COMBUSTIBLE | M16: 0
A17: 46206 | B17: FA | C17: 94-3419 | D17: WNO 918 | F17: 288843.82 | G17: =+G16+E17-F17 -> -330749.03 | H17: 127.807 | I17: COMBUSTIBLE | K17: KJR 926 | L17: COMBUSTIBLE | M17: =SUM(H16) -> 24.927
A18: 46206 | B18: FA | C18: 92-1933 | D18: LVX 455 | F18: 59999.29 | G18: =+G17+E18-F18 -> -390748.32 | H18: 24.927 | I18: COMBUSTIBLE | K18: HLW 156 | L18: COMBUSTIBLE | M18: =SUM(H14) -> 24.896
A19: TOTAL DE LITROS SEMANAL | H19: =SUM(H9:H18) -> 512.591 | K19: WNO 918 | L19: COMBUSTIBLE | M19: =SUM(H17) -> 127.807
A20: SEMANA DEL 1/7 AL 4/7 | K20: AUTOELEVADOR | L20: COMBUSTIBLE | M20: =SUM(H10) -> 38.422
A21: 46208 | B21: FA | C21: 92-2021 | D21: LVX 455 | F21: 60000.91 | G21: =+G18+E21-F21 -> -450749.23 | H21: 24.876 | I21: COMBUSTIBLE | K21: LITROS SEMANAL | M21: =SUM(M8:M20) -> 512.591
A22: 46209 | B22: FA | C22: 96-7493 | D22: HLW 156 | F22: 59999.36 | G22: =+G21+E22-F22 -> -510748.59 | H22: 24.896 | I22: COMBUSTIBLE
A23: 46209 | B23: FA | C23: 96-7494 | D23: KJR 926 | F23: 59999.36 | G23: =+G22+E23-F23 -> -570747.95 | H23: 24.896 | I23: COMBUSTIBLE | K23: SEMANA DEL 5/7 AL 11/7
A24: 46209 | B24: RE | C24: 50-0343 | D24: TRANSF | E24: 1000000 | G24: =+G23+E24-F24 -> 429252.05 | I24: PAGO - SALDO A FAVOR | K24: RESUMEN CONSUMO
A25: 46209 | B25: FA | C25: 92-2083 | D25: AG 378 AW | F25: 133000.67 | G25: =+G24+E25-F25 -> 296251.38 | H25: 55.187 | I25: COMBUSTIBLE | K25: RESUMEN | L25: CONSUMO | M25: LTS
A26: 46209 | B26: FA | C26: 92-2087 | D26: LVX 455 | F26: 59999.36 | G26: =+G25+E26-F26 -> 236252.02 | H26: 24.896 | I26: COMBUSTIBLE | K26: AG 378 AV | L26: COMBUSTIBLE | M26: 0
A27: 46211 | B27: FA | C27: 96-7585 | D27: MULITA | F27: 50000.27 | G27: =+G26+E27-F27 -> 186251.75 | H27: 20.747 | I27: COMBUSTIBLE | K27: AG 378 AW | L27: COMBUSTIBLE | M27: =SUM(H25) -> 55.187
A28: 46211 | B28: FA | C28: 82-2150 | D28: MULITA | F28: 89670.02 | G28: =+G27+E28-F28 -> 96581.73 | H28: 39.677 | I28: COMBUSTIBLE | K28: AG 337 MY | L28: COMBUSTIBLE | M28: =SUM(H30) -> 73.03
A29: 46211 | B29: FA | C29: 92-2172 | D29: LVX 455 | F29: 59999.36 | G29: =+G28+E29-F29 -> 36582.37 | H29: 24.896 | I29: COMBUSTIBLE | K29: AG 962 EW | L29: COMBUSTIBLE | M29: =SUM(H31) -> 51.76
A30: 46211 | B30: FA | C30: 82-2187 | D30: AG 337 MY | F30: 176002.3 | G30: =+G29+E30-F30 -> -139419.93 | H30: 73.03 | I30: COMBUSTIBLE | K30: MOTO AMARILLA | L30: COMBUSTIBLE | M30: 0
A31: 46212 | B31: FA | C31: 96-7640 | D31: AG 962 EW | F31: 125000.4 | G31: =+G30+E31-F31 -> -264420.33 | H31: 51.76 | I31: COMBUSTIBLE | K31: MOTO GRIS | L31: COMBUSTIBLE | M31: 0
A32: 46212 | B32: FA | C32: 60-7349 | D32: LVX 455 | F32: 60000.68 | G32: =+G31+E32-F32 -> -324421.01 | H32: 24.845 | I32: COMBUSTIBLE | K32: PFG 964 | L32: COMBUSTIBLE | M32: =SUM(H35) -> 24.876
A33: 46213 | B33: FA | C33: 96-7676 | D33: HLW 156 | F33: 60000.91 | G33: =+G32+E33-F33 -> -384421.92 | H33: 24.876 | I33: COMBUSTIBLE | K33: LVX 455 | L33: COMBUSTIBLE | M33: =SUM(H21+H26+H29+H32+H36) -> 124.389
A34: 46213 | B34: FA | C34: 92-2255 | D34: KJR 926 | F34: 65000.99 | G34: =+G33+E34-F34 -> -449422.91 | H34: 26.949 | I34: COMBUSTIBLE | K34: AG 958 JV | L34: COMBUSTIBLE | M34: 0
A35: 46213 | B35: FA | C35: 92-2278 | D35: PFG 964 | F35: 60000.91 | G35: =+G34+E35-F35 -> -509423.82 | H35: 24.876 | I35: COMBUSTIBLE | K35: AG 768 OI | L35: COMBUSTIBLE | M35: 0
A36: 46213 | B36: FA | C36: 92-2282 | D36: LVX 455 | F36: 60000.91 | G36: =+G35+E36-F36 -> -569424.73 | H36: 24.876 | I36: COMBUSTIBLE | K36: KJR 926 | L36: COMBUSTIBLE | M36: =SUM(H23+H34) -> 51.845
A37: TOTAL DE LITROS SEMANAL | H37: =SUM(H21:H36) -> 491.283 | K37: HLW 156 | L37: COMBUSTIBLE | M37: =SUM(H22+H33) -> 49.772
A38: SEMANA DEL 5/7 AL 11/7 | K38: WNO 918 | L38: COMBUSTIBLE | M38: 0
A39: 46216 | B39: FA | C39: 96-7846 | D39: LVX 455 | F39: 59999.36 | G39: =+G36+E39-F39 -> -629424.09 | H39: 24.896 | I39: COMBUSTIBLE | K39: AUTOELEVADOR | L39: COMBUSTIBLE | M39: =SUM(H27+H28) -> 60.424
A40: 46217 | B40: FA | C40: 98-2171 | D40: AG 768 OI | F40: 499999.75 | G40: =+G39+E40-F40 -> -1129423.8 | H40: 207.125 | I40: COMBUSTIBLE | K40: LITROS SEMANAL | M40: =SUM(M26:M39) -> 491.283
A41: 46217 | B41: RE | C41: 50-0352 | D41: TRANSF | E41: 1000000 | G41: =+G40+E41-F41 -> -129423.84 | I41: PAGO - SALDO PENDIENTE
A42: 46217 | B42: FA | C42: 96-7888 | D42: KJR 926 | F42: 59999.97 | G42: =+G41+E42-F42 -> -189423.81 | H42: 24.855 | I42: COMBUSTIBLE | K42: SEMANA DEL 12/7 AL 18/7
A43: 46217 | B43: FA | C43: 96-7889 | D43: HLW 156 | F43: 59999.97 | G43: =+G42+E43-F43 -> -249423.78 | H43: 24.855 | I43: COMBUSTIBLE | K43: RESUMEN CONSUMO
A44: 46217 | B44: FA | C44: 92-2437 | D44: MOTO GRIS | F44: 29513.84 | G44: =+G43+E44-F44 -> -278937.62 | H44: 13.065 | I44: COMBUSTIBLE | K44: RESUMEN | L44: CONSUMO | M44: LTS
...

Sheet AGOSTO.2026
A5: CTA.CTE AGOSTO - 2026 - CARGAS | K5: SEMANA DEL 1/8 AL 8/8
A6: CARGAS COMBUSTIBLE YPF | K6: RESUMEN CONSUMO
A7: FECHA | B7: TIPO | C7: N° FA/COMP | D7: VEHICULO | E7: PAGOS | F7: CONSUMOS | G7: SALDO | H7: LITROS | I7: OBSEVACIONES | K7: RESUMEN | L7: CONSUMO | M7: LTS
A8: 46233 | C8: SALDO ANTERIOR | E8: 880915.48 | G8: =+E8-F8 -> 880915.48 | K8: AG 378 AV | L8: COMBUSTIBLE | M8: =SUM(H13) -> 48.965
A9: 46237 | B9: FA | C9: 60-8302 | D9: KJR 926 | F9: 59999.36 | G9: =+G8+E9-F9 -> 820916.12 | H9: 24.896 | I9: COMBUSTIBLE | K9: AG 337 MY | L9: COMBUSTIBLE | M9: =SUM(H26) -> 70.965
A10: 46237 | B10: FA | C10: 92-3356 | D10: HLW 156 | F10: 59999.36 | G10: =+G9+E10-F10 -> 760916.76 | H10: 24.896 | I10: COMBUSTIBLE | K10: AG 962 EW | L10: COMBUSTIBLE | M10: 0
A11: 46237 | B11: FA | C11: 92-3357 | D11: MULITA | F11: 42986.57 | G11: =+G10+E11-F11 -> 717930.19 | H11: 18.987 | I11: COMBUSTIBLE | K11: MOTO AMARILLA | L11: COMBUSTIBLE | M11: 0
A12: 46237 | B12: FA | C12: 96-8798 | D12: LVX 455 | F12: 59999.36 | G12: =+G11+E12-F12 -> 657930.83 | H12: 24.896 | I12: COMBUSTIBLE | K12: MOTO GRIS | L12: COMBUSTIBLE | M12: 0
A13: 46238 | B13: FA | C13: 60-8364 | D13: AG 378 AV | F13: 118005.89 | G13: =+G12+E13-F13 -> 539924.94 | H13: 48.965 | I13: COMBUSTIBLE | K13: AF 728 AT | L13: COMBUSTIBLE | M13: =SUM(H23) -> 57.097
A14: 46238 | B14: FA | C14: 92-3417 | D14: AG 378 AV | F14: 118005.65 | G14: =+G13+E14-F14 -> 421919.29 | K14: PFG 964 | L14: COMBUSTIBLE | M14: 0
A15: 46238 | B15: NC | C15: 100-0010 | D15: NOTA DE CREDITO | E15: 118005.66 | G15: =+G14+E15-F15 -> 539924.95 | I15: DEVOLUCIÓN DE PAGO DE COMBUSTIBLE AG 378 AV (92-3417) | K15: LVX 455 | L15: COMBUSTIBLE | M15: =SUM(H12+H17+H30) -> 74.483
A16: 46238 | B16: FA | C16: 92-3439 | D16: KJR 926 | F16: 59999.36 | G16: =+G15+E16-F16 -> 479925.59 | H16: 24.896 | I16: COMBUSTIBLE | K16: AG 958 JV | L16: COMBUSTIBLE | M16: 0
A17: 46239 | B17: FA | C17: 60-8441 | D17: LVX 455 | F17: 59999.36 | G17: =+G16+E17-F17 -> 419926.23 | H17: 24.896 | I17: COMBUSTIBLE | K17: AG 768 OI | L17: COMBUSTIBLE | M17: =SUM(H25) -> 781.103
A18: 46239 | B18: FA | C18: 60-8451 | D18: KJR 926 | F18: 59999.36 | G18: =+G17+E18-F18 -> 359926.87 | H18: 24.896 | I18: COMBUSTIBLE | K18: KJR 926 | L18: COMBUSTIBLE | M18: =SUM(H9+H16+H18+H21+H27+H31) -> 149.027
A19: 46240 | B19: FA | C19: 96-8926 | D19: MULITA | F19: 136155.88 | G19: =+G18+E19-F19 -> 223770.99 | H19: 60.007 | I19: COMBUSTIBLE | K19: HLW 156 | L19: COMBUSTIBLE | M19: =SUM(H10+H20+H29) -> 74.544
A20: 46240 | B20: FA | C20: 60-8483 | D20: HLW 156 | F20: 59999.61 | G20: =+G19+E20-F20 -> 163771.38 | H20: 24.824 | I20: COMBUSTIBLE | K20: WNO 918 | L20: COMBUSTIBLE | M20: =SUM(H28) -> 43.917
A21: 46240 | B21: FA | C21: 92-3509 | D21: KJR 926 | F21: 59999.61 | G21: =+G20+E21-F21 -> 103771.77 | H21: 24.824 | I21: COMBUSTIBLE | K21: HKQ 258 | L21: COMBUSTIBLE | M21: =SUM(H24) -> 340.66
A22: 46240 | B22: RE | C22: 50-0398 | D22: TRANSF | E22: 2000000 | G22: =+G21+E22-F22 -> 2103771.8 | I22: PAGO - SALDO A FAVOR | K22: AUTOELEVADOR | L22: COMBUSTIBLE | M22: =SUM(H11+H19) -> 78.994
A23: 46240 | B23: FA | C23: 92-3515 | D23: AF 728 AT | F23: 138003.45 | G23: =+G22+E23-F23 -> 1965768.3 | H23: 57.097 | I23: COMBUSTIBLE | K23: LITROS SEMANAL | M23: =SUM(M8:M22) -> 1719.755
A24: 46240 | B24: FA | C24: 94-4286 | D24: HKQ 258 | F24: 823375.22 | G24: =+G23+E24-F24 -> 1142393.1 | H24: 340.66 | I24: COMBUSTIBLE
A25: 46240 | B25: FA | C25: 94-4290 | D25: AG 768 OI | F25: 1887925.9 | G25: =+G24+E25-F25 -> -745532.85 | H25: 781.103 | I25: COMBUSTIBLE
A26: 46240 | B26: FA | C26: 92-3539 | D26: AG 337 MY | F26: 171522.41 | G26: =+G25+E26-F26 -> -917055.26 | H26: 70.965 | I26: COMBUSTIBLE
A27: 46241 | B27: FA | C27: 60-8512 | D27: KJR 926 | F27: 59999.61 | G27: =+G26+E27-F27 -> -977054.87 | H27: 24.824 | I27: COMBUSTIBLE
A28: 46241 | B28: FA | C28: 94-4301 | D28: WNO 918 | F28: 99999.01 | G28: =+G27+E28-F28 -> -1077053.9 | H28: 43.917 | I28: COMBUSTIBLE
A29: 46241 | B29: FA | C29: 96-9014 | D29: HLW 156 | F29: 59999.61 | G29: =+G28+E29-F29 -> -1137053.5 | H29: 24.824 | I29: COMBUSTIBLE
A30: 46242 | B30: FA | C30: 98-2362 | D30: LVX 455 | F30: 59999.13 | G30: =+G29+E30-F30 -> -1197052.6 | H30: 24.691 | I30: COMBUSTIBLE
A31: 46242 | B31: FA | C31: 96-9043 | D31: KJR 926 | F31: 59999.13 | G31: =+G30+E31-F31 -> -1257051.7 | H31: 24.691 | I31: COMBUSTIBLE
A32: 46242 | B32: RE | C32: 50-0401 | D32: TRANSF | E32: 3000000 | G32: =+G31+E32-F32 -> 1742948.3 | I32: PAGO - SALDO A FAVOR
A33: TOTAL DE LITROS SEMANAL | H33: =SUM(H9:H32) -> 1719.755
A34: SEMANA DEL 1/8 AL 8/8 | K34: SEMANA DEL 9/8 AL 15/8
A35: 46243 | B35: FA | C35: 96-9071 | D35: KJR 926 | F35: 59999.13 | G35: =+G32+E35-F35 -> 1682949.1 | H35: 24.691 | I35: COMBUSTIBLE | K35: RESUMEN CONSUMO
A36: 46243 | B36: FA | C36: 60-8595 | D36: MULITA | F36: 45664.57 | G36: =+G35+E36-F36 -> 1637284.6 | H36: 20.002 | I36: COMBUSTIBLE | K36: RESUMEN | L36: CONSUMO | M36: LTS
A37: 46243 | B37: FA | C37: 60-8596 | D37: HLW 156 | F37: 65000.07 | G37: =+G36+E37-F37 -> 1572284.5 | H37: 26.749 | I37: COMBUSTIBLE | K37: AG 378 AV | L37: COMBUSTIBLE | M37: 0
A38: 46244 | B38: FA | C38: 94-4356 | D38: WNO 918 | F38: 223065.08 | G38: =+G37+E38-F38 -> 1349219.4 | H38: 97.707 | I38: COMBUSTIBLE | K38: AG 337 MY | L38: COMBUSTIBLE | M38: 0
A39: 46244 | B39: FA | C39: 94-4357 | D39: AG 958 JV | F39: 367531.6 | G39: =+G38+E39-F39 -> 981687.8 | H39: 150.937 | I39: COMBUSTIBLE | K39: AG 962 EW | L39: COMBUSTIBLE | M39: =SUM(H40+H64) -> 81.712
A40: 46244 | B40: FA | C40: 96-9108 | D40: AG 962 EW | F40: 98999.8 | G40: =+G39+E40-F40 -> 882688 | H40: 40.657 | I40: COMBUSTIBLE | K40: MOTO AMARILLA | L40: COMBUSTIBLE | M40: 0
A41: 46244 | B41: FA | C41: 92-3684 | D41: PFG 964 | F41: 60000.84 | G41: =+G40+E41-F41 -> 822687.16 | H41: 24.641 | I41: COMBUSTIBLE | K41: MOTO GRIS | L41: COMBUSTIBLE | M41: 0
A42: 46244 | B42: FA | C42: 94-4367 | D42: HKQ 258 | F42: 724120.3 | G42: =+G41+E42-F42 -> 98566.86 | H42: 297.38 | I42: COMBUSTIBLE | K42: AF 728 AT | L42: COMBUSTIBLE | M42: 0
A43: 46244 | B43: FA | C43: 92-3691 | D43: MULITA | F43: 90000.43 | G43: =+G42+E43-F43 -> 8566.43 | H43: 39.422 | I43: COMBUSTIBLE | K43: PFG 964 | L43: COMBUSTIBLE | M43: =SUM(H41+H51+H56+H59+H68) -> 123.113
A44: 46245 | B44: FA | C44: 96-9143 | D44: KJR 926 | F44: 64999.35 | G44: =+G43+E44-F44 -> -56432.92 | H44: 26.65 | I44: COMBUSTIBLE | K44: KEX 251 | L44: COMBUSTIBLE | M44: =SUM(H55+H66+H70) -> 73.903
...

Sheet SEPTIMBRE.2026
A5: CTA.CTE - 2026 - CARGAS | K5: SEMANA DEL / AL /
A6: CARGAS COMBUSTIBLE YPF | K6: RESUMEN CONSUMO
A7: FECHA | B7: TIPO | C7: N° FA/COMP | D7: VEHICULO | E7: PAGOS | F7: CONSUMOS | G7: SALDO | H7: LITROS | I7: OBSEVACIONES | K7: RESUMEN | L7: CONSUMO | M7: LTS
A8: 46203 | C8: SALDO ANTERIOR | G8: =+E8-F8 -> 0 | K8: AG 378 AV | L8: COMBUSTIBLE | M8: 0
K9: AG 337 MY | L9: COMBUSTIBLE | M9: 0
K10: AG 962 EW | L10: COMBUSTIBLE | M10: 0
K11: AE 919 JA | L11: COMBUSTIBLE | M11: =SUM(H12+H18+H23+H36+H37+H49) -> 0
K12: AA 183 PK | L12: COMBUSTIBLE | M12: =SUM(H16+H33+H41+H53) -> 0
K13: MOTO AMARILLA | L13: COMBUSTIBLE | M13: 0
K14: MOTO GRIS | L14: COMBUSTIBLE | M14: =SUM(H46) -> 0
K15: KEX 251 | L15: COMBUSTIBLE | M15: 0
K16: AF 728 AT | L16: COMBUSTIBLE | M16: =SUM(H13+H39+H56) -> 0
K17: PFG 964 | L17: COMBUSTIBLE | M17: =SUM(H17+H34+H48+H55) -> 0
K18: LVX 455 | L18: COMBUSTIBLE | M18: =SUM(H10+H24+H45+H50+H51) -> 0
K19: AG 958 JV | L19: COMBUSTIBLE | M19: =SUM(H8+H42) -> 0
K20: AG 768 OI | L20: COMBUSTIBLE | M20: =SUM(H15) -> 0
K21: KJR 926 | L21: COMBUSTIBLE | M21: =SUM(H14+H31+H54) -> 0
K22: HLW 156 | L22: COMBUSTIBLE | M22: =SUM(H26+H40+H52) -> 0
K23: WNO 918 | L23: COMBUSTIBLE | M23: =SUM(H19+H29) -> 0
K24: HKQ 258 | L24: COMBUSTIBLE | M24: =SUM(H6+H44) -> 0
K25: FTL 303 | L25: COMBUSTIBLE | M25: =SUM(H28) -> 0
K26: AUTOELEVADOR | L26: COMBUSTIBLE | M26: =SUM(H11+H20+H27+H32+H35) -> 0
K27: LITROS SEMANAL | M27: =SUM(M7:M26) -> 0
A112: TOTAL | E112: =SUM(E8:E111) -> 0 | F112: =SUM(F8:F111) -> 0 | G112: =+G111 -> 0 | H112: =SUM(H9:H111) -> 0

Sheet OCTUBRE.2026
A5: CTA.CTE - 2026 - CARGAS | K5: SEMANA DEL / AL /
A6: CARGAS COMBUSTIBLE YPF | K6: RESUMEN CONSUMO
A7: FECHA | B7: TIPO | C7: N° FA/COMP | D7: VEHICULO | E7: PAGOS | F7: CONSUMOS | G7: SALDO | H7: LITROS | I7: OBSEVACIONES | K7: RESUMEN | L7: CONSUMO | M7: LTS
A8: 46203 | C8: SALDO ANTERIOR | G8: =+E8-F8 -> 0 | K8: AG 378 AV | L8: COMBUSTIBLE | M8: 0
K9: AG 337 MY | L9: COMBUSTIBLE | M9: 0
K10: AG 962 EW | L10: COMBUSTIBLE | M10: 0
K11: AE 919 JA | L11: COMBUSTIBLE | M11: =SUM(H12+H18+H23+H36+H37+H49) -> 0
K12: AA 183 PK | L12: COMBUSTIBLE | M12: =SUM(H16+H33+H41+H53) -> 0
K13: MOTO AMARILLA | L13: COMBUSTIBLE | M13: 0
K14: MOTO GRIS | L14: COMBUSTIBLE | M14: =SUM(H46) -> 0
K15: KEX 251 | L15: COMBUSTIBLE | M15: 0
K16: AF 728 AT | L16: COMBUSTIBLE | M16: =SUM(H13+H39+H56) -> 0
K17: PFG 964 | L17: COMBUSTIBLE | M17: =SUM(H17+H34+H48+H55) -> 0
K18: LVX 455 | L18: COMBUSTIBLE | M18: =SUM(H10+H24+H45+H50+H51) -> 0
K19: AG 958 JV | L19: COMBUSTIBLE | M19: =SUM(H8+H42) -> 0
K20: AG 768 OI | L20: COMBUSTIBLE | M20: =SUM(H15) -> 0
K21: KJR 926 | L21: COMBUSTIBLE | M21: =SUM(H14+H31+H54) -> 0
K22: HLW 156 | L22: COMBUSTIBLE | M22: =SUM(H26+H40+H52) -> 0
K23: WNO 918 | L23: COMBUSTIBLE | M23: =SUM(H19+H29) -> 0
K24: HKQ 258 | L24: COMBUSTIBLE | M24: =SUM(H6+H44) -> 0
K25: FTL 303 | L25: COMBUSTIBLE | M25: =SUM(H28) -> 0
K26: AUTOELEVADOR | L26: COMBUSTIBLE | M26: =SUM(H11+H20+H27+H32+H35) -> 0
K27: LITROS SEMANAL | M27: =SUM(M7:M26) -> 0
A112: TOTAL | E112: =SUM(E8:E111) -> 0 | F112: =SUM(F8:F111) -> 0 | G112: =+G111 -> 0 | H112: =SUM(H9:H111) -> 0

Sheet NOVIEMBRE.2026
A5: CTA.CTE - 2026 - CARGAS | K5: SEMANA DEL / AL /
A6: CARGAS COMBUSTIBLE YPF | K6: RESUMEN CONSUMO
A7: FECHA | B7: TIPO | C7: N° FA/COMP | D7: VEHICULO | E7: PAGOS | F7: CONSUMOS | G7: SALDO | H7: LITROS | I7: OBSEVACIONES | K7: RESUMEN | L7: CONSUMO | M7: LTS
A8: 46203 | C8: SALDO ANTERIOR | G8: =+E8-F8 -> 0 | K8: AG 378 AV | L8: COMBUSTIBLE | M8: 0
K9: AG 337 MY | L9: COMBUSTIBLE | M9: 0
K10: AG 962 EW | L10: COMBUSTIBLE | M10: 0
K11: AE 919 JA | L11: COMBUSTIBLE | M11: =SUM(H12+H18+H23+H36+H37+H49) -> 0
K12: AA 183 PK | L12: COMBUSTIBLE | M12: =SUM(H16+H33+H41+H53) -> 0
K13: MOTO AMARILLA | L13: COMBUSTIBLE | M13: 0
K14: MOTO GRIS | L14: COMBUSTIBLE | M14: =SUM(H46) -> 0
K15: KEX 251 | L15: COMBUSTIBLE | M15: 0
K16: AF 728 AT | L16: COMBUSTIBLE | M16: =SUM(H13+H39+H56) -> 0
K17: PFG 964 | L17: COMBUSTIBLE | M17: =SUM(H17+H34+H48+H55) -> 0
K18: LVX 455 | L18: COMBUSTIBLE | M18: =SUM(H10+H24+H45+H50+H51) -> 0
K19: AG 958 JV | L19: COMBUSTIBLE | M19: =SUM(H8+H42) -> 0
K20: AG 768 OI | L20: COMBUSTIBLE | M20: =SUM(H15) -> 0
K21: KJR 926 | L21: COMBUSTIBLE | M21: =SUM(H14+H31+H54) -> 0
K22: HLW 156 | L22: COMBUSTIBLE | M22: =SUM(H26+H40+H52) -> 0
K23: WNO 918 | L23: COMBUSTIBLE | M23: =SUM(H19+H29) -> 0
K24: HKQ 258 | L24: COMBUSTIBLE | M24: =SUM(H6+H44) -> 0
K25: FTL 303 | L25: COMBUSTIBLE | M25: =SUM(H28) -> 0
K26: AUTOELEVADOR | L26: COMBUSTIBLE | M26: =SUM(H11+H20+H27+H32+H35) -> 0
K27: LITROS SEMANAL | M27: =SUM(M7:M26) -> 0
A112: TOTAL | E112: =SUM(E8:E111) -> 0 | F112: =SUM(F8:F111) -> 0 | G112: =+G111 -> 0 | H112: =SUM(H9:H111) -> 0

Sheet DICIEMBRE.2026
A5: CTA.CTE - 2026 - CARGAS | K5: SEMANA DEL / AL /
A6: CARGAS COMBUSTIBLE YPF | K6: RESUMEN CONSUMO
A7: FECHA | B7: TIPO | C7: N° FA/COMP | D7: VEHICULO | E7: PAGOS | F7: CONSUMOS | G7: SALDO | H7: LITROS | I7: OBSEVACIONES | K7: RESUMEN | L7: CONSUMO | M7: LTS
A8: 46203 | C8: SALDO ANTERIOR | G8: =+E8-F8 -> 0 | K8: AG 378 AV | L8: COMBUSTIBLE | M8: 0
K9: AG 337 MY | L9: COMBUSTIBLE | M9: 0
K10: AG 962 EW | L10: COMBUSTIBLE | M10: 0
K11: AE 919 JA | L11: COMBUSTIBLE | M11: =SUM(H12+H18+H23+H36+H37+H49) -> 0
K12: AA 183 PK | L12: COMBUSTIBLE | M12: =SUM(H16+H33+H41+H53) -> 0
K13: MOTO AMARILLA | L13: COMBUSTIBLE | M13: 0
K14: MOTO GRIS | L14: COMBUSTIBLE | M14: =SUM(H46) -> 0
K15: KEX 251 | L15: COMBUSTIBLE | M15: 0
K16: AF 728 AT | L16: COMBUSTIBLE | M16: =SUM(H13+H39+H56) -> 0
K17: PFG 964 | L17: COMBUSTIBLE | M17: =SUM(H17+H34+H48+H55) -> 0
K18: LVX 455 | L18: COMBUSTIBLE | M18: =SUM(H10+H24+H45+H50+H51) -> 0
K19: AG 958 JV | L19: COMBUSTIBLE | M19: =SUM(H8+H42) -> 0
K20: AG 768 OI | L20: COMBUSTIBLE | M20: =SUM(H15) -> 0
K21: KJR 926 | L21: COMBUSTIBLE | M21: =SUM(H14+H31+H54) -> 0
K22: HLW 156 | L22: COMBUSTIBLE | M22: =SUM(H26+H40+H52) -> 0
K23: WNO 918 | L23: COMBUSTIBLE | M23: =SUM(H19+H29) -> 0
K24: HKQ 258 | L24: COMBUSTIBLE | M24: =SUM(H6+H44) -> 0
K25: FTL 303 | L25: COMBUSTIBLE | M25: =SUM(H28) -> 0
K26: AUTOELEVADOR | L26: COMBUSTIBLE | M26: =SUM(H11+H20+H27+H32+H35) -> 0
K27: LITROS SEMANAL | M27: =SUM(M7:M26) -> 0
A112: TOTAL | E112: =SUM(E8:E111) -> 0 | F112: =SUM(F8:F111) -> 0 | G112: =+G111 -> 0 | H112: =SUM(#REF!+#REF!+#REF!+#REF!) -> #REF!

Sheet TRANSF.EFECT DE COMBUSTIBLE 
A2: PAGOS MENSUAL 2026
A3: MES | B3: OBSERVACION | C3: MONTO EN PESOS | D3: PORCENTAJE
A4: ENERO | B4: PAGOS MENSUALES TRANS/EFECT | C4: =SUM(ENERO.2026!E198) -> 14275896 | D4: =C4/$C$16 -> 0.093163197
A5: FEBRERO | B5: PAGOS MENSUALES TRANS/EFECT | C5: =SUM(FEBRERO.2026!E247) -> 23928881 | D5: =C5/$C$16 -> 0.15615769
A6: MARZO | B6: PAGOS MENSUALES TRANS/EFECT | C6: =SUM(MARZO.2026!E213) -> 27277839 | D6: =C6/$C$16 -> 0.17801269
A7: ABRIL | B7: PAGOS MENSUALES TRANS/EFECT | C7: =SUM(ABRIL.2026!E249) -> 22000000 | D7: =C7/$C$16 -> 0.14356999
A8: MAYO | B8: PAGOS MENSUALES TRANS/EFECT | C8: =SUM(MAYO.2026!E205) -> 23048711 | D8: =C8/$C$16 -> 0.15041378
A9: JUNIO | B9: PAGOS MENSUALES TRANS/EFECT | C9: =SUM(JUNIO.2026!E118) -> 9294999.3 | D9: =C9/$C$16 -> 0.060658316
A10: JULIO | B10: PAGOS MENSUALES TRANS/EFECT | C10: =SUM(JULIO.2026!E130) -> 17810119 | D10: =C10/$C$16 -> 0.11622721
A11: AGOSTO | B11: PAGOS MENSUALES TRANS/EFECT | C11: =SUM(AGOSTO.2026!E142) -> 15598921 | D11: =C11/$C$16 -> 0.10179713
A12: SEPTIEMBRE | B12: PAGOS MENSUALES TRANS/EFECT | D12: =C12/$C$16 -> 0
A13: OCTUBRE | B13: PAGOS MENSUALES TRANS/EFECT | D13: =C13/$C$16 -> 0
A14: NOVIEMBRE | B14: PAGOS MENSUALES TRANS/EFECT | D14: =C14/$C$16 -> 0
A15: DICIEMBRE | B15: PAGOS MENSUALES TRANS/EFECT | D15: =C15/$C$16 -> 0
A16: TOTAL ANUAL | C16: =SUM(C4:C15) -> 1.5323537e+08

Sheet CONSUMO DE COMBUSTIBLE EN PESOS
A2: CONSUMO MENSUAL 2026
A3: MES | B3: OBSERVACION | C3: MONTO EN PESOS | D3: PORCENTAJE
A4: ENERO | B4: COMBUSTIBLE CONSUMIDO EN PESOS | C4: =SUM(ENERO.2026!F198) -> 14847294 | D4: =C4/$C$16 -> 0.09762217
A5: FEBRERO | B5: COMBUSTIBLE CONSUMIDO EN PESOS | C5: =SUM(FEBRERO.2026!F247) -> 20991042 | D5: =C5/$C$16 -> 0.13801781
A6: MARZO | B6: COMBUSTIBLE CONSUMIDO EN PESOS | C6: =SUM(MARZO.2026!F213) -> 27749588 | D6: =C6/$C$16 -> 0.18245581
A7: ABRIL | B7: COMBUSTIBLE CONSUMIDO EN PESOS | C7: =SUM(ABRIL.2026!F249) -> 21851289 | D7: =C7/$C$16 -> 0.14367401
A8: MAYO | B8: COMBUSTIBLE CONSUMIDO EN PESOS | C8: =SUM(MAYO.2026!F205) -> 22753711 | D8: =C8/$C$16 -> 0.14960751
A9: JUNIO | B9: COMBUSTIBLE CONSUMIDO EN PESOS | C9: =SUM(JUNIO.2026!F118) -> 9476680.1 | D9: =C9/$C$16 -> 0.062309947
A10: JULIO | B10: COMBUSTIBLE CONSUMIDO EN PESOS | C10: =SUM(JULIO.2026!E130+JULIO.2026!G151) -> 18559835 | D10: =C10/$C$16 -> 0.12203244
A11: AGOSTO | B11: COMBUSTIBLE CONSUMIDO EN PESOS | C11: =SUM(AGOSTO.2026!F142) -> 15859924 | D11: =C11/$C$16 -> 0.10428029
A12: SEPTIEMBRE | B12: COMBUSTIBLE CONSUMIDO EN PESOS | D12: =C12/$C$16 -> 0
A13: OCTUBRE | B13: COMBUSTIBLE CONSUMIDO EN PESOS | D13: =C13/$C$16 -> 0
A14: NOVIEMBRE | B14: COMBUSTIBLE CONSUMIDO EN PESOS | D14: =C14/$C$16 -> 0
A15: DICIEMBRE | B15: COMBUSTIBLE CONSUMIDO EN PESOS | D15: =C15/$C$16 -> 0
A16: TOTAL ANUAL | C16: =SUM(C4:C15) -> 1.5208936e+08

Sheet CONSUMO DE LITROS
A2: LITROS MENSUAL 2026
A3: MES | B3: OBSERVACION | C3: MONTO EN LITROS (LTS) | D3: PORCENTAJE
A4: ENERO | B4: LITROS DE COMBUSTIBLE | C4: =SUM(ENERO.2026!H198) -> 7615.8795 | D4: =C4/$C$16 -> 0.11208527
A5: FEBRERO | B5: LITROS DE COMBUSTIBLE | C5: =SUM(FEBRERO.2026!H247) -> 10735.878 | D5: =C5/$C$16 -> 0.15800325
A6: MARZO | B6: LITROS DE COMBUSTIBLE | C6: =SUM(MARZO.2026!H213) -> 13158.28 | D6: =C6/$C$16 -> 0.19365449
A7: ABRIL | B7: LITROS DE COMBUSTIBLE | C7: =SUM(ABRIL.2026!H249) -> 9192.9291 | D7: =C7/$C$16 -> 0.13529519
A8: MAYO | B8: LITROS DE COMBUSTIBLE | C8: =SUM(MAYO.2026!H205) -> 9700.754 | D8: =C8/$C$16 -> 0.14276901
A9: JUNIO | B9: LITROS DE COMBUSTIBLE | C9: =SUM(JUNIO.2026!H118) -> 4009.9589 | D9: =C9/$C$16 -> 0.059015811
A10: JULIO | B10: LITROS DE COMBUSTIBLE | C10: =SUM(JULIO.2026!H130+JULIO.2026!H151) -> 7045.5677 | D10: =C10/$C$16 -> 0.10369181
A11: AGOSTO | B11: LITROS DE COMBUSTIBLE | C11: =SUM(AGOSTO.2026!H142) -> 6487.9499 | D11: =C11/$C$16 -> 0.095485175
A12: SEPTIEMBRE | B12: LITROS DE COMBUSTIBLE | D12: =C12/$C$16 -> 0
A13: OCTUBRE | B13: LITROS DE COMBUSTIBLE | D13: =C13/$C$16 -> 0
A14: NOVIEMBRE | B14: LITROS DE COMBUSTIBLE | D14: =C14/$C$16 -> 0
A15: DICIEMBRE | B15: LITROS DE COMBUSTIBLE | D15: =C15/$C$16 -> 0
A16: TOTAL ANUAL DE LTS | C16: =SUM(C4:C15) -> 67947.196

Sheet CARGAS AUTORIZADAS
A4: FLOTA VEHICULOS CARGAS AUTORIZADAS-2026
B5: TIPO DE VEHICULO | C5: DOMINIO | D5: MODELO | E5: 46126
A6: 1 | B6: CAMIONETA | C6: AG 337 MY | D6: FORD RANGER-2024 | E6: SIN LIMITE DE CARGA
A7: 2 | B7: CAMIONETA | C7: AG 378 AV | D7: TOYOTA SW4 | E7: SIN LIMITE DE CARGA
A8: 3 | B8: CAMIONETA | C8: AG 378 AW | D8: FORD RANGER-2024 | E8: SIN LIMITE DE CARGA
A9: 4 | B9: CAMIONETA | C9: AG 962 EW | D9: NISSAN FRONTIER | E9: SIN LIMITE DE CARGA
A10: 5 | B10: CAMIONETA | C10: PFG 964 | D10: FORD RANGER-2015 | E10: 60000
A11: 6 | B11: CAMIONETA | C11: AA 183 PK | D11: TOYOTA HILUX-2016 | E11: 60000
A12: 7 | B12: CAMIONETA | C12: LVX 455 | D12: TOYOTA HILUX-2012 | E12: 60000
A13: 8 | B13: CAMIONETA | C13: KJR 926 | D13: FORD RANGER-2011 | E13: 60000
A14: 9 | B14: CAMIONETA | C14: KEX 251 | D14: FORD RANGER-2011 | E14: 60000
A15: 10 | B15: CAMIONETA | C15: AE 919 JA | D15: TOYOTA HILUX-2021 | E15: 60000
A16: 11 | B16: CAMIONETA | C16: HLW 156 | D16: FORD RANGER- 2008 | E16: 60000
A17: 12 | B17: AUTOELEVADORES | C17: DOS57 | D17: AZUL/ROJO/4X4 | E17: SIN LIMITE DE CARGA
A18: 13 | B18: CAMION | C18: WNO 918 | D18: MERCEDES BENZ-1968 | E18: SIN LIMITE DE CARGA
A19: 14 | B19: CAMION | C19: HKQ 258 | D19: VOLKWAGEN-2008 | E19: SIN LIMITE DE CARGA
A20: 15 | B20: CAMION | C20: FTL 303 | D20: VOLVO-2006 | E20: SIN LIMITE DE CARGA
A21: 16 | B21: CAMION | C21: AG 768 OI | D21: MERCEDES -2024 | E21: SIN LIMITE DE CARGA
A22: 17 | B22: CAMION-PLANCHA | C22: AG 958 JV | D22: MERCEDES -2025 | E22: SIN LIMITE DE CARGA
A23: 18 | B23: MINIBUS | C23: AF 728 AT | D23: SPRINTER | E23: SIN LIMITE DE CARGA
A24: 19 | B24: MOTOCICLETA | C24: A26 2CPD | D24: CF 700 | E24: SIN LIMITE DE CARGA
