Workbook

Sheet INFORME GENERAL
A1: INFORME DE GASTO NAVE 15 | G1: AÑO
G2: 2022 al 2025
A3: RUBROS FIJOS | D3: GASTO | E3: DOS57 (50%) | F3: JIMENEZ (50%) | G3: OBSERVACION
A4: ALQUILER - PERIODO 12/2022 al 05/2023 (INCLUSIVE) | D4: 565000 | E4: =D4*50% -> 282500 | F4: =+D4*50% -> 282500 | G4: DICHO COSTO ES MENSUAL
A5: ALQUILER - PERIODO 06/2023 al 11/2023 (INCLUSIVE) | D5: 762750 | E5: =D5*50% -> 381375 | F5: =+D5*50% -> 381375 | G5: DICHO COSTO ES MENSUAL
A6: ALQUILER - PERIODO 12/2023 al 05/2024 (INCLUSIVE) | D6: =+D5*35%+D5 -> 1029712.5 | E6: =D6*50% -> 514856.25 | F6: =+D6*50% -> 514856.25 | G6: DICHO COSTO ES MENSUAL CON 35% SEMESTRAL
A7: ALQUILER - PERIODO 06/2024 al 11/2024 (INCLUSIVE) | D7: 0.35 | G7: DICHO COSTO ES MENSUAL CON 35% SEMESTRAL
A8: ALQUILER - PERIODO 12/2024 al 05/2025 (INCLUSIVE) | D8: 0.35 | G8: DICHO COSTO ES MENSUAL CON 35% SEMESTRAL
A9: ALQUILER - PERIODO 06/2025 al 11/2025 (INCLUSIVE) | D9: 0.35 | G9: DICHO COSTO ES MENSUAL CON 35% SEMESTRAL
A10: TOTAL | D10: =SUM(D4:D9) -> 2357463.6 | E10: =SUM(E4:E9) -> 1178731.2 | F10: =SUM(F4:F9) -> 1178731.2
A12: RUBROS VARIABLES | D12: GASTO | E12: DOS57 (50%) | F12: JIMENEZ (50%) | G12: OBSERVACION
A13: COMISION INMOBILIARIA - 4% VALOR CONTRATO | D13: =+'[1]INFORME GENERAL'!D13 -> 1958148 | E13: =+D13*50% -> 979074 | F13: =+D13*50% -> 979074 | G13: Se lleva adelante en 2 cuotas 50% Febrero 2023 y Marzo 2023
A14: TIMBRADO | D14: 108240 | E14: =+D14*50% -> 54120 | F14: =+D14*50% -> 54120 | G14: Se lleva adelante timbrado sobre contrato blanco
A15: TOTAL | D15: =SUM(D13:D14) -> 2066388 | E15: =SUM(E13:E14) -> 1033194 | F15: =SUM(F13:F14) -> 1033194
A17: EXTRAS DE OBRA | D17: GASTO | E17: DOS57 (50%) | F17: JIMENEZ (50%) | G17: OBSERVACION
A18: CAMARAS (12 + DVR) | D18: 450000 | E18: =+D18*50% -> 225000 | F18: =+D18*50% -> 225000 | G18: DICHO COSTO ESTA SUJETO A APROBACION DE AMBAS PARTES EN EL CASO DE APROBAR SE ABONARA CON CHEQUE 30/60/90 A PARTIR DEL 01/03/2023
A19: SEPARACION 50% GALPON DURLOCK | D19: 472300 | E19: =+D19*50% -> 236150 | F19: =+D19*50% -> 236150 | G19: DICHA OBRA SE LLEVO ADELANTE PARA LA DIVISION INTERNA DE GALPONES, DICHA OBRA SE ABONO CON CHEQUES ABRIL/MAYO/ JUNIO 2023
A20: RAMPA ACCESO + PORTON | D20: 521620 | E20: =+D20*50% -> 260810 | F20: =+D20*50% -> 260810 | G20: DICHA OBRA SE LLEVA ADELANTE PORQUE EL LADO DE DOS57 NO POSEIA NI RAMPA NI PORTON,DICHA OBRA SE ABONO CON CHEQUES ABRIL/MAYO/ JUNIO 2023
A21: TOTAL | D21: =SUM(D18:D20) -> 1443920 | E21: =SUM(E18:E20) -> 721960 | F21: =SUM(F18:F20) -> 721960

Sheet DICIEMBRE 2022
A1: RENDICION DE GASTOS NAVE 15 | H1: MES: | I1: AÑO
H2: DICIEMBRE | I2: 2022
A3: RUBROS FIJOS | D3: GASTO | E3: DOS57 (50%) | F3: JIMENEZ (50%) | G3: OBSERVACION
A4: ALQUILER | D4: 565000 | E4: =D4*50% -> 282500 | F4: =+D4*50% -> 282500
E5: =D5*25% -> 0 | F5: =+D5*50% -> 0
A6: TOTAL | D6: =SUM(D4:D5) -> 565000 | E6: =SUM(E4:E5) -> 282500 | F6: =SUM(F4:F5) -> 282500
A8: RUBROS VARIABLES | D8: GASTO | E8: DOS57 (50%) | F8: JIMENEZ (50%) | G8: OBSERVACION
A9: EXPENSAS | D9: 73929 | E9: =+D9*50% -> 36964.5 | F9: =+D9*50% -> 36964.5
A10: IMPUESTOS DGR | D10: 234 | E10: =+D10*50% -> 117 | F10: =+D10*50% -> 117
A11: EPEC | D11: 0 | E11: =+D11*50% -> 0 | F11: =+D11*50% -> 0
A12: TOTAL | D12: =SUM(D9:D11) -> 74163 | E12: =SUM(E9:E11) -> 37081.5 | F12: =SUM(F9:F11) -> 37081.5
A14: EXTRAS | D14: GASTO | E14: DOS57 (50%) | F14: JIMENEZ (50%) | G14: OBSERVACION
A15: INTERNET - WIFI | D15: 0 | E15: =+D15*50% -> 0 | F15: =+D15*50% -> 0 | G15: SIN INSTALACION APROX MENSUAL $ 8.000, SE REQUIERE DE DICHO SERVICIO PARA FUNCIONAMIENTO DE CAMARAS
A16: MANTENIMIENTO JARDINEROS | D16: 0 | E16: =+D16*50% -> 0 | F16: =+D16*50% -> 0 | G16: APROX MENSUAL $ 5.000
A17: AREA PROTEGIDA | D17: 0 | E17: =+D17*50% -> 0 | F17: =+D17*50% -> 0 | G17: SIN COBERTURA APROX MENSUAL $6.000
D18: 0 | E18: =+D18*50% -> 0 | F18: =+D18*50% -> 0
A19: TOTAL | D19: =SUM(D15) -> 0 | E19: =SUM(E15:E18) -> 0 | F19: =SUM(F15:F18) -> 0
A21: GASTO POR EMPRESA (TEORIA) | C21: =+H2 -> DICIEMBRE | D21: Porcentaje
A22: DOS57 | C22: =+E19+E12+E6 -> 319581.5 | D22: 0.5
A23: JIMENEZ | C23: =+F19+F12+F6 -> 319581.5 | D23: 0.5
A24: TOTALES | C24: =SUM(C22:C23) -> 639163 | D24: =SUM(D22:D23) -> 1
A26: GASTO POR EMPRESA (PRACTICA) | C26: Alquiler | D26: Porcentaje | E26: Rubros Variables | F26: Porcentaje | G26: Extras | H26: Porcentaje | I26: Total Aportes
A27: DOS57 | C27: =+D4 -> 565000 | D27: 1 | E27: =+D12 -> 74163 | F27: 1 | G27: 0 | H27: 0 | I27: =+C27+E27+G27 -> 639163
A28: JIMENEZ | C28: 0 | D28: 0 | E28: 0 | F28: 0 | G28: 0 | H28: 0 | I28: =+C28+E28+G28 -> 0

Sheet ENERO 2023
A1: RENDICION DE GASTOS NAVE 15 | H1: MES: | I1: AÑO
H2: ENERO | I2: 2023
A3: RUBROS FIJOS | D3: GASTO | E3: DOS57 (50%) | F3: JIMENEZ (50%) | G3: OBSERVACION
A4: ALQUILER | D4: 565000 | E4: =D4*50% -> 282500 | F4: =+D4*50% -> 282500
E5: =D5*25% -> 0 | F5: =+D5*50% -> 0
A6: TOTAL | D6: =SUM(D4:D5) -> 565000 | E6: =SUM(E4:E5) -> 282500 | F6: =SUM(F4:F5) -> 282500
A8: RUBROS VARIABLES | D8: GASTO | E8: DOS57 (50%) | F8: JIMENEZ (50%) | G8: OBSERVACION
A9: EXPENSAS | D9: 83649 | E9: =+D9*50% -> 41824.5 | F9: =+D9*50% -> 41824.5
A10: IMPUESTOS DGR | D10: 259 | E10: =+D10*50% -> 129.5 | F10: =+D10*50% -> 129.5
A11: EPEC | D11: 6885 | E11: =+D11*50% -> 3442.5 | F11: =+D11*50% -> 3442.5
A12: TOTAL | D12: =SUM(D9:D11) -> 90793 | E12: =SUM(E9:E11) -> 45396.5 | F12: =SUM(F9:F11) -> 45396.5
A14: EXTRAS | D14: GASTO | E14: DOS57 (50%) | F14: JIMENEZ (50%) | G14: OBSERVACION
A15: INTERNET - WIFI | D15: 0 | E15: =+D15*50% -> 0 | F15: =+D15*50% -> 0 | G15: SIN INSTALACION APROX MENSUAL $ 8.000, SE REQUIERE DE DICHO SERVICIO PARA FUNCIONAMIENTO DE CAMARAS
A16: MANTENIMIENTO JARDINEROS | D16: 0 | E16: =+D16*50% -> 0 | F16: =+D16*50% -> 0 | G16: APROX MENSUAL $ 5.000
A17: AREA PROTEGIDA | D17: 0 | E17: =+D17*50% -> 0 | F17: =+D17*50% -> 0 | G17: SIN COBERTURA APROX MENSUAL $6.000
A18: TOTAL | D18: =SUM(D15) -> 0 | E18: =SUM(E15:E17) -> 0 | F18: =SUM(F15:F17) -> 0
A20: GASTO POR EMPRESA | C20: =+H2 -> ENERO | D20: Porcentaje
A21: DOS57 | C21: =+E18+E12+E6 -> 327896.5 | D21: 0.5
A22: JIMENEZ | C22: =+F18+F12+F6 -> 327896.5 | D22: 0.5
A23: TOTALES | C23: =SUM(C21:C22) -> 655793 | D23: =SUM(D21:D22) -> 1
A25: GASTO POR EMPRESA (PRACTICA) | C25: Alquiler | D25: Porcentaje | E25: Rubros Variables | F25: Porcentaje | G25: Extras | H25: Porcentaje | I25: Total Aportes
A26: DOS57 | C26: =+D4 -> 565000 | D26: 1 | E26: =+D12 -> 90793 | F26: 1 | G26: 0 | H26: 0 | I26: =+C26+E26+G26 -> 655793
A27: JIMENEZ | C27: 0 | D27: 0 | E27: 0 | F27: 0 | G27: 0 | H27: 0 | I27: =+C27+E27+G27 -> 0

Sheet FEBRERO 2023
A1: RENDICION DE GASTOS NAVE 15 | H1: MES: | I1: AÑO
H2: FEBRERO | I2: 2023
A3: RUBROS FIJOS | D3: GASTO | E3: DOS57 (50%) | F3: JIMENEZ (50%) | G3: OBSERVACION
A4: ALQUILER | D4: 565000 | E4: =D4*50% -> 282500 | F4: =+D4*50% -> 282500
E5: =D5*25% -> 0 | F5: =+D5*50% -> 0
A6: TOTAL | D6: =SUM(D4:D5) -> 565000 | E6: =SUM(E4:E5) -> 282500 | F6: =SUM(F4:F5) -> 282500
A8: RUBROS VARIABLES | D8: GASTO | E8: DOS57 (50%) | F8: JIMENEZ (50%) | G8: OBSERVACION
A9: EXPENSAS | D9: 91824 | E9: =+D9*50% -> 45912 | F9: =+D9*50% -> 45912
A10: IMPUESTOS DGR | D10: 0 | E10: =+D10*50% -> 0 | F10: =+D10*50% -> 0
A11: EPEC | D11: 365 | E11: =+D11*50% -> 182.5 | F11: =+D11*50% -> 182.5 | G11: LIQUIDACION ABRIL 2023
A12: TOTAL | D12: =SUM(D9:D11) -> 92189 | E12: =SUM(E9:E11) -> 46094.5 | F12: =SUM(F9:F11) -> 46094.5
A14: EXTRAS | D14: GASTO | E14: DOS57 (50%) | F14: JIMENEZ (50%) | G14: OBSERVACION
A15: INTERNET - WIFI | D15: 0 | E15: =+D15*50% -> 0 | F15: =+D15*50% -> 0 | G15: SIN INSTALACION APROX MENSUAL $ 8.000, SE REQUIERE DE DICHO SERVICIO PARA FUNCIONAMIENTO DE CAMARAS
A16: MANTENIMIENTO JARDINEROS | D16: 0 | E16: =+D16*50% -> 0 | F16: =+D16*50% -> 0 | G16: APROX MENSUAL $ 5.000
A17: AREA PROTEGIDA | D17: 0 | E17: =+D17*50% -> 0 | F17: =+D17*50% -> 0 | G17: SIN COBERTURA APROX MENSUAL $6.000
A18: TOTAL | D18: =SUM(D15) -> 0 | E18: =SUM(E15:E17) -> 0 | F18: =SUM(F15:F17) -> 0
A20: GASTO POR EMPRESA | C20: =+H2 -> FEBRERO | D20: Porcentaje
A21: DOS57 | C21: =+E18+E12+E6 -> 328594.5 | D21: 0.5
A22: JIMENEZ | C22: =+F18+F12+F6 -> 328594.5 | D22: 0.5
A23: TOTALES | C23: =SUM(C21:C22) -> 657189 | D23: =SUM(D21:D22) -> 1
A25: GASTO POR EMPRESA (PRACTICA) | C25: Alquiler | D25: Porcentaje | E25: Rubros Variables | F25: Porcentaje | G25: Extras | H25: Porcentaje | I25: Extraordinario | J25: Porcentaje | K25: Total Aportes
A26: DOS57 | C26: =+D6 -> 565000 | D26: 1 | E26: =+D12 -> 92189 | F26: 1 | G26: 0 | H26: 0 | I26: 979074 | J26: 1 | K26: =+C26+E26+G26+I26 -> 1636263
A27: JIMENEZ | C27: 0 | D27: 0 | E27: 0 | F27: 0 | G27: 0 | H27: 0 | I27: 0 | J27: 0 | K27: =+C27+E27+G27+I27 -> 0

Sheet MARZO 2023
A1: RENDICION DE GASTOS NAVE 15 | H1: MES: | I1: AÑO
H2: MARZO | I2: 2023
A3: RUBROS FIJOS | D3: GASTO | E3: DOS57 (50%) | F3: JIMENEZ (50%) | G3: OBSERVACION
A4: ALQUILER | D4: 565000 | E4: =D4*50% -> 282500 | F4: =+D4*50% -> 282500
E5: =D5*25% -> 0 | F5: =+D5*50% -> 0
A6: TOTAL | D6: =SUM(D4:D5) -> 565000 | E6: =SUM(E4:E5) -> 282500 | F6: =SUM(F4:F5) -> 282500
A8: RUBROS VARIABLES | D8: GASTO | E8: DOS57 (50%) | F8: JIMENEZ (50%) | G8: OBSERVACION
A9: EXPENSAS | D9: 98410 | E9: =+D9*50% -> 49205 | F9: =+D9*50% -> 49205
A10: IMPUESTOS DGR | D10: 0 | E10: =+D10*50% -> 0 | F10: =+D10*50% -> 0
A11: EPEC | D11: 5331 | E11: =+D11*50% -> 2665.5 | F11: =+D11*50% -> 2665.5 | G11: EN LA LIQUIDACION DE MAYO 2023
A12: TOTAL | D12: =SUM(D9:D11) -> 103741 | E12: =SUM(E9:E11) -> 51870.5 | F12: =SUM(F9:F11) -> 51870.5
A14: EXTRAS | D14: GASTO | E14: DOS57 (50%) | F14: JIMENEZ (50%) | G14: OBSERVACION
A15: INTERNET - WIFI | D15: 0 | E15: =+D15*50% -> 0 | F15: =+D15*50% -> 0 | G15: SIN INSTALACION APROX MENSUAL $ 8.000, SE REQUIERE DE DICHO SERVICIO PARA FUNCIONAMIENTO DE CAMARAS
A16: MANTENIMIENTO JARDINEROS | D16: 0 | E16: =+D16*50% -> 0 | F16: =+D16*50% -> 0 | G16: APROX MENSUAL $ 5.000
A17: AREA PROTEGIDA | D17: 0 | E17: =+D17*50% -> 0 | F17: =+D17*50% -> 0 | G17: SIN COBERTURA APROX MENSUAL $6.000
A18: TOTAL | D18: =SUM(D15) -> 0 | E18: =SUM(E15:E17) -> 0 | F18: =SUM(F15:F17) -> 0
A20: GASTO POR EMPRESA | C20: =+H2 -> MARZO | D20: Porcentaje
A21: DOS57 | C21: =+E18+E12+E6 -> 334370.5 | D21: 0.5
A22: JIMENEZ | C22: =+F18+F12+F6 -> 334370.5 | D22: 0.5
A23: TOTALES | C23: =SUM(C21:C22) -> 668741 | D23: =SUM(D21:D22) -> 1
A25: GASTO POR EMPRESA (PRACTICA) | C25: Alquiler | D25: Porcentaje | E25: Rubros Variables | F25: Porcentaje | G25: Extras | H25: Porcentaje | I25: Extraordinario | J25: Porcentaje | K25: Total Aportes
A26: DOS57 | C26: 0 | D26: 0 | E26: =+D12 -> 103741 | F26: 1 | G26: 0 | H26: 0 | I26: 0 | J26: 0 | K26: =+C26+E26+G26+I26 -> 103741
A27: JIMENEZ | C27: 565000 | D27: 1 | E27: 0 | F27: 0 | G27: 0 | H27: 0 | I27: 979074 | J27: 1 | K27: =+C27+E27+G27+I27 -> 1544074

Sheet ABRIL 2023
A1: RENDICION DE GASTOS NAVE 15 | H1: MES: | I1: AÑO
H2: ABRIL | I2: 2023
A3: RUBROS FIJOS | D3: GASTO | E3: DOS57 (50%) | F3: JIMENEZ (50%) | G3: OBSERVACION
A4: ALQUILER | D4: 565000 | E4: =D4*50% -> 282500 | F4: =+D4*50% -> 282500
E5: =D5*25% -> 0 | F5: =+D5*50% -> 0
A6: TOTAL | D6: =SUM(D4:D5) -> 565000 | E6: =SUM(E4:E5) -> 282500 | F6: =SUM(F4:F5) -> 282500
A8: RUBROS VARIABLES | D8: GASTO | E8: DOS57 (50%) | F8: JIMENEZ (50%) | G8: OBSERVACION
A9: EXPENSAS | D9: 109765 | E9: =+D9*50% -> 54882.5 | F9: =+D9*50% -> 54882.5
A10: IMPUESTOS DGR | D10: 0 | E10: =+D10*50% -> 0 | F10: =+D10*50% -> 0
A11: EPEC | D11: 251 | E11: =+D11*50% -> 125.5 | F11: =+D11*50% -> 125.5 | G11: EN LA LIQUIDACION DEJUNIO/JULIO 2023
A12: TOTAL | D12: =+D9+D10+D11 -> 110016 | E12: =SUM(E9:E11) -> 55008 | F12: =SUM(F9:F11) -> 55008
A14: EXTRAS | D14: GASTO | E14: DOS57 (50%) | F14: JIMENEZ (50%) | G14: OBSERVACION
A15: INTERNET - WIFI | D15: 26214.1 | E15: =+D15*50% -> 13107.05 | F15: =+D15*50% -> 13107.05 | G15: INSTALACION DE SERVICIO + ROUTER
A16: MANTENIMIENTO JARDINEROS | D16: 0 | E16: =+D16*50% -> 0 | F16: =+D16*50% -> 0 | G16: APROX MENSUAL $ 5.000
A17: AREA PROTEGIDA | D17: 0 | E17: =+D17*50% -> 0 | F17: =+D17*50% -> 0 | G17: SIN COBERTURA APROX MENSUAL $6.000
A18: TOTAL | D18: =SUM(D15) -> 26214.1 | E18: =SUM(E15:E17) -> 13107.05 | F18: =SUM(F15:F17) -> 13107.05
A20: GASTO POR EMPRESA | C20: =+H2 -> ABRIL | D20: Porcentaje
A21: DOS57 | C21: =+E18+E12+E6 -> 350615.05 | D21: 0.5
A22: JIMENEZ | C22: =+F18+F12+F6 -> 350615.05 | D22: 0.5
A23: TOTALES | C23: =SUM(C21:C22) -> 701230.1 | D23: =SUM(D21:D22) -> 1
A25: GASTO POR EMPRESA (PRACTICA) | C25: Alquiler | D25: Porcentaje | E25: Rubros Variables | F25: Porcentaje | G25: Extras | H25: Porcentaje | I25: Total Aportes
A26: DOS57 | C26: 0 | D26: 0 | E26: =+D12 -> 110016 | F26: 1 | G26: =+D18 -> 26214.1 | H26: 1 | I26: =+C26+E26+G26 -> 136230.1
A27: JIMENEZ | C27: =+D6 -> 565000 | D27: 1 | E27: 0 | F27: 0 | G27: 0 | H27: 0 | I27: =+C27+E27+G27 -> 565000

Sheet MAYO 2023
A1: RENDICION DE GASTOS NAVE 15 | H1: MES: | I1: AÑO
H2: MAYO | I2: 2023
A3: RUBROS FIJOS | D3: GASTO | E3: DOS57 (50%) | F3: JIMENEZ (50%) | G3: OBSERVACION
A4: ALQUILER | D4: 565000 | E4: =D4*50% -> 282500 | F4: =+D4*50% -> 282500
E5: =D5*25% -> 0 | F5: =+D5*50% -> 0
A6: TOTAL | D6: =SUM(D4:D5) -> 565000 | E6: =SUM(E4:E5) -> 282500 | F6: =SUM(F4:F5) -> 282500
A8: RUBROS VARIABLES | D8: GASTO | E8: DOS57 (50%) | F8: JIMENEZ (50%) | G8: OBSERVACION
A9: EXPENSAS | D9: 134746 | E9: =+D9*50% -> 67373 | F9: =+D9*50% -> 67373
A10: IMPUESTOS DGR | D10: 0 | E10: =+D10*50% -> 0 | F10: =+D10*50% -> 0
A11: EPEC | D11: 355 | E11: =+D11*50% -> 177.5 | F11: =+D11*50% -> 177.5 | G11: EN LA LIQUIDACION DEJUNIO/JULIO 2023
A12: TOTAL | D12: =SUM(D9:D11) -> 135101 | E12: =SUM(E9:E11) -> 67550.5 | F12: =SUM(F9:F11) -> 67550.5
A14: EXTRAS | D14: GASTO | E14: DOS57 (50%) | F14: JIMENEZ (50%) | G14: OBSERVACION
A15: INTERNET - WIFI | D15: 5727.95 | E15: =+D15*50% -> 2863.975 | F15: =+D15*50% -> 2863.975 | G15: ABONO MENSUAL
A16: MANTENIMIENTO JARDINEROS | D16: 0 | E16: =+D16*50% -> 0 | F16: =+D16*50% -> 0 | G16: APROX MENSUAL $ 5.000
A17: AREA PROTEGIDA | D17: 0 | E17: =+D17*50% -> 0 | F17: =+D17*50% -> 0 | G17: SIN COBERTURA APROX MENSUAL $6.000
A18: TOTAL | D18: =SUM(D15) -> 5727.95 | E18: =SUM(E15:E17) -> 2863.975 | F18: =SUM(F15:F17) -> 2863.975
A20: GASTO POR EMPRESA | C20: =+H2 -> MAYO | D20: Porcentaje
A21: DOS57 | C21: =+E18+E12+E6 -> 352914.47 | D21: 0.5
A22: JIMENEZ | C22: =+F18+F12+F6 -> 352914.47 | D22: 0.5
A23: TOTALES | C23: =SUM(C21:C22) -> 705828.95 | D23: =SUM(D21:D22) -> 1
A25: GASTO POR EMPRESA (PRACTICA) | C25: Alquiler | D25: Porcentaje | E25: Rubros Variables | F25: Porcentaje | G25: Extras | H25: Porcentaje | I25: Total Aportes
A26: DOS57 | C26: 0 | D26: 0 | E26: =+D12 -> 135101 | F26: 1 | G26: =+D18 -> 5727.95 | H26: 1 | I26: =+C26+E26+G26 -> 140828.95
A27: JIMENEZ | C27: =+D6 -> 565000 | D27: 1 | E27: 0 | F27: 0 | G27: 0 | H27: 0 | I27: =+C27+E27+G27 -> 565000

Sheet JUNIO 2023
A1: RENDICION DE GASTOS NAVE 15 | H1: MES: | I1: AÑO
H2: JUNIO | I2: 2023
A3: RUBROS FIJOS | D3: GASTO | E3: DOS57 (50%) | F3: JIMENEZ (50%) | G3: OBSERVACION
A4: ALQUILER | D4: 762750 | E4: =D4*50% -> 381375 | F4: =+D4*50% -> 381375
E5: =D5*25% -> 0 | F5: =+D5*50% -> 0
A6: TOTAL | D6: =SUM(D4:D5) -> 762750 | E6: =SUM(E4:E5) -> 381375 | F6: =SUM(F4:F5) -> 381375
A8: RUBROS VARIABLES | D8: GASTO | E8: DOS57 (50%) | F8: JIMENEZ (50%) | G8: OBSERVACION
A9: EXPENSAS | D9: 157427 | E9: =+D9*50% -> 78713.5 | F9: =+D9*50% -> 78713.5
A10: IMPUESTOS DGR | D10: 0 | E10: =+D10*50% -> 0 | F10: =+D10*50% -> 0
A11: EPEC | D11: 246 | E11: =+D11*50% -> 123 | F11: =+D11*50% -> 123 | G11: EN LA LIQUIDACION AGOSTO 2023
A12: TOTAL | D12: =SUM(D9:D11) -> 157673 | E12: =SUM(E9:E11) -> 78836.5 | F12: =SUM(F9:F11) -> 78836.5
A14: EXTRAS | D14: GASTO | E14: DOS57 (50%) | F14: JIMENEZ (50%) | G14: OBSERVACION
A15: INTERNET - WIFI | D15: 5985.71 | E15: =+D15*50% -> 2992.855 | F15: =+D15*50% -> 2992.855 | G15: ABONO MENSUAL
A16: MANTENIMIENTO JARDINEROS | D16: 0 | E16: =+D16*50% -> 0 | F16: =+D16*50% -> 0 | G16: APROX MENSUAL $ 5.000
A17: AREA PROTEGIDA | D17: 0 | E17: =+D17*50% -> 0 | F17: =+D17*50% -> 0 | G17: SIN COBERTURA APROX MENSUAL $6.000
A18: TOTAL | D18: =SUM(D15) -> 5985.71 | E18: =SUM(E15:E17) -> 2992.855 | F18: =SUM(F15:F17) -> 2992.855
A20: GASTO POR EMPRESA | C20: =+H2 -> JUNIO | D20: Porcentaje
A21: DOS57 | C21: =+E18+E12+E6 -> 463204.35 | D21: 0.5
A22: JIMENEZ | C22: =+F18+F12+F6 -> 463204.35 | D22: 0.5
A23: TOTALES | C23: =SUM(C21:C22) -> 926408.71 | D23: =SUM(D21:D22) -> 1
A25: GASTO POR EMPRESA (PRACTICA) | C25: Alquiler | D25: Porcentaje | E25: Rubros Variables | F25: Porcentaje | G25: Extras | H25: Porcentaje | I25: Total Aportes
A26: DOS57 | C26: 762750 | D26: 0 | E26: =+D12 -> 157673 | F26: 1 | G26: =+D18 -> 5985.71 | H26: 1 | I26: =+C26+E26+G26 -> 926408.71
A27: JIMENEZ | C27: 0 | D27: 0 | E27: 0 | F27: 0 | G27: 0 | H27: 0 | I27: =+C27+E27+G27 -> 0

Sheet JULIO 2023 
A1: RENDICION DE GASTOS NAVE 15 | H1: MES: | I1: AÑO
H2: JULIO | I2: 2023
A3: RUBROS FIJOS | D3: GASTO | E3: DOS57 (50%) | F3: JIMENEZ (50%) | G3: OBSERVACION
A4: ALQUILER | D4: 762750 | E4: =D4*50% -> 381375 | F4: =+D4*50% -> 381375
E5: =D5*25% -> 0 | F5: =+D5*50% -> 0
A6: TOTAL | D6: =SUM(D4:D5) -> 762750 | E6: =SUM(E4:E5) -> 381375 | F6: =SUM(F4:F5) -> 381375
A8: RUBROS VARIABLES | D8: GASTO | E8: DOS57 (50%) | F8: JIMENEZ (50%) | G8: OBSERVACION
A9: EXPENSAS | D9: 178078 | E9: =+D9*50% -> 89039 | F9: =+D9*50% -> 89039
A10: IMPUESTOS DGR | D10: 0 | E10: =+D10*50% -> 0 | F10: =+D10*50% -> 0
A11: EPEC | D11: 104 | E11: =+D11*50% -> 52 | F11: =+D11*50% -> 52
A12: TOTAL | D12: =SUM(D9:D11) -> 178182 | E12: =SUM(E9:E11) -> 89091 | F12: =SUM(F9:F11) -> 89091
A14: EXTRAS | D14: GASTO | E14: DOS57 (50%) | F14: JIMENEZ (50%) | G14: OBSERVACION
A15: INTERNET - WIFI | D15: =6255.07+437.75 -> 6692.82 | E15: =+D15*50% -> 3346.41 | F15: =+D15*50% -> 3346.41 | G15: ABONO MENSUAL
A16: MANTENIMIENTO JARDINEROS | D16: 0 | E16: =+D16*50% -> 0 | F16: =+D16*50% -> 0 | G16: APROX MENSUAL $ 5.000
A17: AREA PROTEGIDA | D17: 0 | E17: =+D17*50% -> 0 | F17: =+D17*50% -> 0 | G17: SIN COBERTURA APROX MENSUAL $6.000
A18: TOTAL | D18: =SUM(D15) -> 6692.82 | E18: =SUM(E15:E17) -> 3346.41 | F18: =SUM(F15:F17) -> 3346.41
A20: GASTO POR EMPRESA | C20: =+H2 -> JULIO | D20: Porcentaje
A21: DOS57 | C21: =+E18+E12+E6 -> 473812.41 | D21: 0.5
A22: JIMENEZ | C22: =+F18+F12+F6 -> 473812.41 | D22: 0.5
A23: TOTALES | C23: =SUM(C21:C22) -> 947624.82 | D23: =SUM(D21:D22) -> 1
A25: GASTO POR EMPRESA (PRACTICA) | C25: Alquiler | D25: Porcentaje | E25: Rubros Variables | F25: Porcentaje | G25: Extras | H25: Porcentaje | I25: Total Aportes
A26: DOS57 | C26: 762750 | D26: 1 | E26: =+D12 -> 178182 | F26: 1 | G26: =+D18 -> 6692.82 | H26: 1 | I26: =+C26+E26+G26 -> 947624.82
A27: JIMENEZ | C27: 0 | D27: 0 | E27: 0 | F27: 0 | G27: 0 | H27: 0 | I27: =+C27+E27+G27 -> 0

Sheet AGOSTO 2023
A1: RENDICION DE GASTOS NAVE 15 | H1: MES: | I1: AÑO
H2: AGOSTO | I2: 2023
A3: RUBROS FIJOS | D3: GASTO | E3: DOS57 (50%) | F3: JIMENEZ (50%) | G3: OBSERVACION
A4: ALQUILER | D4: 762750 | E4: =D4*50% -> 381375 | F4: =+D4*50% -> 381375
D5: 0 | E5: =D5*25% -> 0 | F5: =+D5*50% -> 0
A6: TOTAL | D6: =SUM(D4:D5) -> 762750 | E6: =SUM(E4:E5) -> 381375 | F6: =SUM(F4:F5) -> 381375
A8: RUBROS VARIABLES | D8: GASTO | E8: DOS57 (50%) | F8: JIMENEZ (50%) | G8: OBSERVACION
A9: EXPENSAS | D9: 192231 | E9: =+D9*50% -> 96115.5 | F9: =+D9*50% -> 96115.5
A10: IMPUESTOS DGR | D10: 0 | E10: =+D10*50% -> 0 | F10: =+D10*50% -> 0
A11: EPEC | D11: 584 | E11: =+D11*50% -> 292 | F11: =+D11*50% -> 292
A12: TOTAL | D12: =SUM(D9:D11) -> 192815 | E12: =SUM(E9:E11) -> 96407.5 | F12: =SUM(F9:F11) -> 96407.5
A14: EXTRAS | D14: GASTO | E14: DOS57 (50%) | F14: JIMENEZ (50%) | G14: OBSERVACION
A15: INTERNET - WIFI | D15: =11095.04+493.53 -> 11588.57 | E15: =+D15*50% -> 5794.285 | F15: =+D15*50% -> 5794.285 | G15: ABONO MENSUAL
A16: MANTENIMIENTO JARDINEROS | D16: 0 | E16: =+D16*50% -> 0 | F16: =+D16*50% -> 0 | G16: APROX MENSUAL $ 5.000
A17: AREA PROTEGIDA | D17: 0 | E17: =+D17*50% -> 0 | F17: =+D17*50% -> 0 | G17: SIN COBERTURA APROX MENSUAL $6.000
A18: TOTAL | D18: =SUM(D15) -> 11588.57 | E18: =SUM(E15:E17) -> 5794.285 | F18: =SUM(F15:F17) -> 5794.285
A20: GASTO POR EMPRESA | C20: =+H2 -> AGOSTO | D20: Porcentaje
A21: DOS57 | C21: =+E18+E12+E6 -> 483576.79 | D21: 0.5
A22: JIMENEZ | C22: =+F18+F12+F6 -> 483576.79 | D22: 0.5
A23: TOTALES | C23: =SUM(C21:C22) -> 967153.57 | D23: =SUM(D21:D22) -> 1
A25: GASTO POR EMPRESA (PRACTICA) | C25: Alquiler | D25: Porcentaje | E25: Rubros Variables | F25: Porcentaje | G25: Extras | H25: Porcentaje | I25: Total Aportes
A26: DOS57 | C26: 762750 | D26: 1 | E26: =+D12 -> 192815 | F26: 1 | G26: =+D18 -> 11588.57 | H26: 1 | I26: =+C26+E26+G26 -> 967153.57
A27: JIMENEZ | C27: 0 | D27: 0 | E27: 0 | F27: 0 | G27: 0 | H27: 0 | I27: =+C27+E27+G27 -> 0

Sheet SEPTIEMBRE 2023 
A1: RENDICION DE GASTOS NAVE 15 | H1: MES: | I1: AÑO
H2: SEPTIEMBRE | I2: 2023
A3: RUBROS FIJOS | D3: GASTO | E3: DOS57 (50%) | F3: JIMENEZ (50%) | G3: OBSERVACION
A4: ALQUILER | D4: 759750 | E4: =D4*50% -> 379875 | F4: =+D4*50% -> 379875
E5: =D5*25% -> 0 | F5: =+D5*50% -> 0
A6: TOTAL | D6: =SUM(D4:D5) -> 759750 | E6: =SUM(E4:E5) -> 379875 | F6: =SUM(F4:F5) -> 379875
A8: RUBROS VARIABLES | D8: GASTO | E8: DOS57 (50%) | F8: JIMENEZ (50%) | G8: OBSERVACION
A9: EXPENSAS | D9: 211133 | E9: =+D9*50% -> 105566.5 | F9: =+D9*50% -> 105566.5
A10: IMPUESTOS DGR | D10: 0 | E10: =+D10*50% -> 0 | F10: =+D10*50% -> 0
A11: EPEC | D11: 3377 | E11: =+D11*50% -> 1688.5 | F11: =+D11*50% -> 1688.5
A12: TOTAL | D12: =SUM(D9:D11) -> 214510 | E12: =SUM(E9:E11) -> 107255 | F12: =SUM(F9:F11) -> 107255
A14: EXTRAS | D14: GASTO | E14: DOS57 (50%) | F14: JIMENEZ (50%) | G14: OBSERVACION
A15: INTERNET - WIFI | D15: 12446.04 | E15: =+D15*50% -> 6223.02 | F15: =+D15*50% -> 6223.02 | G15: ABONO MENSUAL
A16: MANTENIMIENTO JARDINEROS | D16: 0 | E16: =+D16*50% -> 0 | F16: =+D16*50% -> 0 | G16: APROX MENSUAL $ 5.000
A17: AREA PROTEGIDA | D17: 0 | E17: =+D17*50% -> 0 | F17: =+D17*50% -> 0 | G17: SIN COBERTURA APROX MENSUAL $6.000
A18: TOTAL | D18: =SUM(D15) -> 12446.04 | E18: =SUM(E15:E17) -> 6223.02 | F18: =SUM(F15:F17) -> 6223.02
A20: GASTO POR EMPRESA | C20: =+H2 -> SEPTIEMBRE | D20: Porcentaje
A21: DOS57 | C21: =+E18+E12+E6 -> 493353.02 | D21: 0.5
A22: JIMENEZ | C22: =+F18+F12+F6 -> 493353.02 | D22: 0.5
A23: TOTALES | C23: =SUM(C21:C22) -> 986706.04 | D23: =SUM(D21:D22) -> 1
A25: GASTO POR EMPRESA (PRACTICA) | C25: Alquiler | D25: Porcentaje | E25: Rubros Variables | F25: Porcentaje | G25: Extras | H25: Porcentaje | I25: Total Aportes
A26: DOS57 | C26: 0 | D26: 0 | E26: =+D12 -> 214510 | F26: 1 | G26: =+D18 -> 12446.04 | H26: 1 | I26: =+C26+E26+G26 -> 226956.04
A27: JIMENEZ | C27: 759750 | D27: 1 | E27: 0 | F27: 0 | G27: 0 | H27: 0 | I27: =+C27+E27+G27 -> 759750

Sheet OCTUBRE 2023
A1: RENDICION DE GASTOS NAVE 15 | H1: MES: | I1: AÑO
H2: OCTUBRE | I2: 2023
A3: RUBROS FIJOS | D3: GASTO | E3: DOS57 (50%) | F3: JIMENEZ (50%) | G3: OBSERVACION
A4: ALQUILER | D4: =+'SEPTIEMBRE 2023 '!D4 -> 759750 | E4: =D4*50% -> 379875 | F4: =+D4*50% -> 379875
E5: =D5*25% -> 0 | F5: =+D5*50% -> 0
A6: TOTAL | D6: =SUM(D4:D5) -> 759750 | E6: =SUM(E4:E5) -> 379875 | F6: =SUM(F4:F5) -> 379875
A8: RUBROS VARIABLES | D8: GASTO | E8: DOS57 (50%) | F8: JIMENEZ (50%) | G8: OBSERVACION
A9: EXPENSAS | D9: 226440 | E9: =+D9*50% -> 113220 | F9: =+D9*50% -> 113220
A10: IMPUESTOS DGR | D10: 0 | E10: =+D10*50% -> 0 | F10: =+D10*50% -> 0
A11: EPEC | D11: 6890 | E11: =+D11*50% -> 3445 | F11: =+D11*50% -> 3445
A12: TOTAL | D12: =SUM(D9:D11) -> 233330 | E12: =SUM(E9:E11) -> 116665 | F12: =SUM(F9:F11) -> 116665
A14: EXTRAS | D14: GASTO | E14: DOS57 (50%) | F14: JIMENEZ (50%) | G14: OBSERVACION
A15: INTERNET - WIFI | D15: 17149.76 | E15: =+D15*50% -> 8574.88 | F15: =+D15*50% -> 8574.88 | G15: ABONO MENSUAL
A16: MANTENIMIENTO JARDINEROS | D16: 0 | E16: =+D16*50% -> 0 | F16: =+D16*50% -> 0 | G16: APROX MENSUAL $ 5.000
A17: AREA PROTEGIDA | D17: 0 | E17: =+D17*50% -> 0 | F17: =+D17*50% -> 0 | G17: SIN COBERTURA APROX MENSUAL $6.000
A18: TOTAL | D18: =SUM(D15) -> 17149.76 | E18: =SUM(E15:E17) -> 8574.88 | F18: =SUM(F15:F17) -> 8574.88
A20: GASTO POR EMPRESA | C20: =+H2 -> OCTUBRE | D20: Porcentaje
A21: DOS57 | C21: =+E18+E12+E6 -> 505114.88 | D21: 0.5
A22: JIMENEZ | C22: =+F18+F12+F6 -> 505114.88 | D22: 0.5
A23: TOTALES | C23: =SUM(C21:C22) -> 1010229.8 | D23: =SUM(D21:D22) -> 1
A25: GASTO POR EMPRESA (PRACTICA) | C25: Alquiler | D25: Porcentaje | E25: Rubros Variables | F25: Porcentaje | G25: Extras | H25: Porcentaje | I25: Total Aportes
A26: DOS57 | C26: 0 | D26: 0 | E26: =+D12 -> 233330 | F26: 1 | G26: =+D18 -> 17149.76 | H26: 1 | I26: =+C26+E26+G26 -> 250479.76
A27: JIMENEZ | C27: 759750 | D27: 0 | E27: 0 | F27: 0 | G27: 0 | H27: 0 | I27: =+C27+E27+G27 -> 759750

Sheet NOVIEMBRE 2023
A1: RENDICION DE GASTOS NAVE 15 | H1: MES: | I1: AÑO
H2: NOVIEMBRE | I2: 2023
A3: RUBROS FIJOS | D3: GASTO | E3: DOS57 (50%) | F3: JIMENEZ (50%) | G3: OBSERVACION
A4: ALQUILER | D4: =+'OCTUBRE 2023'!D4 -> 759750 | E4: =D4*50% -> 379875 | F4: =+D4*50% -> 379875
E5: =D5*25% -> 0 | F5: =+D5*50% -> 0
A6: TOTAL | D6: =SUM(D4:D5) -> 759750 | E6: =SUM(E4:E5) -> 379875 | F6: =SUM(F4:F5) -> 379875
A8: RUBROS VARIABLES | D8: GASTO | E8: DOS57 (50%) | F8: JIMENEZ (50%) | G8: OBSERVACION
A9: EXPENSAS | D9: 260406 | E9: =+D9*50% -> 130203 | F9: =+D9*50% -> 130203
A10: IMPUESTOS DGR | D10: 0 | E10: =+D10*50% -> 0 | F10: =+D10*50% -> 0
A11: EPEC | D11: 1744 | E11: =+D11*50% -> 872 | F11: =+D11*50% -> 872
A12: TOTAL | D12: =SUM(D9:D11) -> 262150 | E12: =SUM(E9:E11) -> 131075 | F12: =SUM(F9:F11) -> 131075
A14: EXTRAS | D14: GASTO | E14: DOS57 (50%) | F14: JIMENEZ (50%) | G14: OBSERVACION
A15: INTERNET - WIFI | D15: 18305.67 | E15: =+D15*50% -> 9152.835 | F15: =+D15*50% -> 9152.835 | G15: ABONO MENSUAL
A16: MANTENIMIENTO JARDINEROS | D16: 0 | E16: =+D16*50% -> 0 | F16: =+D16*50% -> 0 | G16: APROX MENSUAL $ 5.000
A17: AREA PROTEGIDA | D17: 0 | E17: =+D17*50% -> 0 | F17: =+D17*50% -> 0 | G17: SIN COBERTURA APROX MENSUAL $6.000
A18: TOTAL | D18: =SUM(D15) -> 18305.67 | E18: =SUM(E15:E17) -> 9152.835 | F18: =SUM(F15:F17) -> 9152.835
A20: GASTO POR EMPRESA | C20: =+H2 -> NOVIEMBRE | D20: Porcentaje
A21: DOS57 | C21: =+E18+E12+E6 -> 520102.83 | D21: 0.5
A22: JIMENEZ | C22: =+F18+F12+F6 -> 520102.83 | D22: 0.5
A23: TOTALES | C23: =SUM(C21:C22) -> 1040205.7 | D23: =SUM(D21:D22) -> 1
A25: GASTO POR EMPRESA (PRACTICA) | C25: Alquiler | D25: Porcentaje | E25: Rubros Variables | F25: Porcentaje | G25: Extras | H25: Porcentaje | I25: Total Aportes
A26: DOS57 | C26: 0 | D26: 0 | E26: =+D12 -> 262150 | F26: 1 | G26: =+D18 -> 18305.67 | H26: 1 | I26: =+C26+E26+G26 -> 280455.67
A27: JIMENEZ | C27: 759750 | D27: 0 | E27: 0 | F27: 0 | G27: 0 | H27: 0 | I27: =+C27+E27+G27 -> 759750

Sheet DICIEMBRE 2023
A1: RENDICION DE GASTOS NAVE 15 | H1: MES: | I1: AÑO
H2: DICIEMBRE | I2: 2023
A3: RUBROS FIJOS | D3: GASTO | E3: DOS57 (50%) | F3: JIMENEZ (50%) | G3: OBSERVACION
A4: ALQUILER | D4: 1030000 | E4: =D4*50% -> 515000 | F4: =+D4*50% -> 515000
E5: =D5*25% -> 0 | F5: =+D5*50% -> 0
A6: TOTAL | D6: =SUM(D4:D5) -> 1030000 | E6: =SUM(E4:E5) -> 515000 | F6: =SUM(F4:F5) -> 515000
A8: RUBROS VARIABLES | D8: GASTO | E8: DOS57 (50%) | F8: JIMENEZ (50%) | G8: OBSERVACION
A9: EXPENSAS | D9: 314599 | E9: =+D9*50% -> 157299.5 | F9: =+D9*50% -> 157299.5
A10: IMPUESTOS DGR | D10: 0 | E10: =+D10*50% -> 0 | F10: =+D10*50% -> 0
A11: EPEC | D11: 10894 | E11: =+D11*50% -> 5447 | F11: =+D11*50% -> 5447
A12: TOTAL | D12: =SUM(D9:D11) -> 325493 | E12: =SUM(E9:E11) -> 162746.5 | F12: =SUM(F9:F11) -> 162746.5
A14: EXTRAS | D14: GASTO | E14: DOS57 (50%) | F14: JIMENEZ (50%) | G14: OBSERVACION
A15: INTERNET - WIFI | D15: 19263.9 | E15: =+D15*50% -> 9631.95 | F15: =+D15*50% -> 9631.95 | G15: ABONO MENSUAL
A16: MANTENIMIENTO JARDINEROS | D16: 0 | E16: =+D16*50% -> 0 | F16: =+D16*50% -> 0 | G16: APROX MENSUAL $ 5.000
A17: AREA PROTEGIDA | D17: 0 | E17: =+D17*50% -> 0 | F17: =+D17*50% -> 0 | G17: SIN COBERTURA APROX MENSUAL $6.000
A18: TOTAL | D18: =SUM(D15) -> 19263.9 | E18: =SUM(E15:E17) -> 9631.95 | F18: =SUM(F15:F17) -> 9631.95
A20: GASTO POR EMPRESA | C20: =+H2 -> DICIEMBRE | D20: Porcentaje
A21: DOS57 | C21: =+E18+E12+E6 -> 687378.45 | D21: 0.5
A22: JIMENEZ | C22: =+F18+F12+F6 -> 687378.45 | D22: 0.5
A23: TOTALES | C23: =SUM(C21:C22) -> 1374756.9 | D23: =SUM(D21:D22) -> 1
A25: GASTO POR EMPRESA (PRACTICA) | C25: Alquiler | D25: Porcentaje | E25: Rubros Variables | F25: Porcentaje | G25: Extras | H25: Porcentaje | I25: Total Aportes
A26: DOS57 | C26: 0 | D26: 0 | E26: =+D12 -> 325493 | F26: 1 | G26: =+D18 -> 19263.9 | H26: 1 | I26: =+C26+E26+G26 -> 344756.9
A27: JIMENEZ | C27: 1030000 | D27: 0 | E27: 0 | F27: 0 | G27: 0 | H27: 0 | I27: =+C27+E27+G27 -> 1030000

Sheet ENERO 2024
A1: RENDICION DE GASTOS NAVE 15 | H1: MES: | I1: AÑO
H2: ENERO | I2: 2024
A3: RUBROS FIJOS | D3: GASTO | E3: DOS57 (50%) | F3: JIMENEZ (50%) | G3: OBSERVACION
A4: ALQUILER | D4: 1030000 | E4: =D4*50% -> 515000 | F4: =+D4*50% -> 515000
A6: TOTAL | D6: =SUM(D4:D5) -> 1030000 | E6: =SUM(E4:E5) -> 515000 | F6: =SUM(F4:F5) -> 515000
A8: RUBROS VARIABLES | D8: GASTO | E8: DOS57 (50%) | F8: JIMENEZ (50%) | G8: OBSERVACION
A9: EXPENSAS | D9: 350099 | E9: =+D9*50% -> 175049.5 | F9: =+D9*50% -> 175049.5
A10: IMPUESTOS DGR | D10: 0 | E10: =+D10*50% -> 0 | F10: =+D10*50% -> 0
A11: EPEC | D11: 33111 | E11: =+D11*50% -> 16555.5 | F11: =+D11*50% -> 16555.5
A12: TOTAL | D12: =SUM(D9:D11) -> 383210 | E12: =SUM(E9:E11) -> 191605 | F12: =SUM(F9:F11) -> 191605
A14: EXTRAS | D14: GASTO | E14: DOS57 (50%) | F14: JIMENEZ (50%) | G14: OBSERVACION
A15: INTERNET - WIFI | D15: 18110.57 | E15: =+D15*50% -> 9055.285 | F15: =+D15*50% -> 9055.285 | G15: ABONO MENSUAL
A16: MANTENIMIENTO JARDINEROS | D16: 0 | E16: =+D16*50% -> 0 | F16: =+D16*50% -> 0 | G16: APROX MENSUAL $ 5.000
A17: AREA PROTEGIDA | D17: 0 | E17: =+D17*50% -> 0 | F17: =+D17*50% -> 0 | G17: SIN COBERTURA APROX MENSUAL $6.000
A18: TOTAL | D18: =SUM(D15) -> 18110.57 | E18: =SUM(E15:E17) -> 9055.285 | F18: =SUM(F15:F17) -> 9055.285
A20: GASTO POR EMPRESA | C20: =+H2 -> ENERO | D20: Porcentaje
A21: DOS57 | C21: =+E18+E12+E6 -> 715660.29 | D21: 0.5
A22: JIMENEZ | C22: =+F18+F12+F6 -> 715660.29 | D22: 0.5
A23: TOTALES | C23: =SUM(C21:C22) -> 1431320.6 | D23: =SUM(D21:D22) -> 1
A25: GASTO POR EMPRESA (PRACTICA) | C25: Alquiler | D25: Porcentaje | E25: Rubros Variables | F25: Porcentaje | G25: Extras | H25: Porcentaje | I25: Total Aportes
A26: DOS57 | C26: 0 | D26: 0 | E26: =+D12 -> 383210 | F26: 1 | G26: =+D18 -> 18110.57 | H26: 1 | I26: =+C26+E26+G26 -> 401320.57
A27: JIMENEZ | C27: 1030000 | D27: 0 | E27: 0 | F27: 0 | G27: 0 | H27: 0 | I27: =+C27+E27+G27 -> 1030000

Sheet FEBRERO 2024
A1: RENDICION DE GASTOS NAVE 15 | H1: MES: | I1: AÑO
H2: FEBRERO | I2: 2024
A3: RUBROS FIJOS | D3: GASTO | E3: DOS57 (50%) | F3: JIMENEZ (50%) | G3: OBSERVACION
A4: ALQUILER | D4: 1030000 | E4: =D4*50% -> 515000 | F4: =+D4*50% -> 515000
A6: TOTAL | D6: =SUM(D4:D5) -> 1030000 | E6: =SUM(E4:E5) -> 515000 | F6: =SUM(F4:F5) -> 515000
A8: RUBROS VARIABLES | D8: GASTO | E8: DOS57 (50%) | F8: JIMENEZ (50%) | G8: OBSERVACION
A9: EXPENSAS | D9: 420118 | E9: =+D9*50% -> 210059 | F9: =+D9*50% -> 210059
A10: IMPUESTOS DGR | D10: 0 | E10: =+D10*50% -> 0 | F10: =+D10*50% -> 0
A11: EPEC | D11: 36180 | E11: =+D11*50% -> 18090 | F11: =+D11*50% -> 18090
A12: TOTAL | D12: =SUM(D9:D11) -> 456298 | E12: =SUM(E9:E11) -> 228149 | F12: =SUM(F9:F11) -> 228149
A14: EXTRAS | D14: GASTO | E14: DOS57 (50%) | F14: JIMENEZ (50%) | G14: OBSERVACION
A15: INTERNET - WIFI | D15: 28695.32 | E15: =+D15*50% -> 14347.66 | F15: =+D15*50% -> 14347.66 | G15: ABONO MENSUAL
A16: MANTENIMIENTO JARDINEROS | D16: 0 | E16: =+D16*50% -> 0 | F16: =+D16*50% -> 0 | G16: APROX MENSUAL $ 5.000
A17: AREA PROTEGIDA | D17: 0 | E17: =+D17*50% -> 0 | F17: =+D17*50% -> 0 | G17: SIN COBERTURA APROX MENSUAL $6.000
A18: TOTAL | D18: =SUM(D15) -> 28695.32 | E18: =SUM(E15:E17) -> 14347.66 | F18: =SUM(F15:F17) -> 14347.66
A20: GASTO POR EMPRESA | C20: =+H2 -> FEBRERO | D20: Porcentaje
A21: DOS57 | C21: =+E18+E12+E6 -> 757496.66 | D21: 0.5
A22: JIMENEZ | C22: =+F18+F12+F6 -> 757496.66 | D22: 0.5
A23: TOTALES | C23: =SUM(C21:C22) -> 1514993.3 | D23: =SUM(D21:D22) -> 1
A25: GASTO POR EMPRESA (PRACTICA) | C25: Alquiler | D25: Porcentaje | E25: Rubros Variables | F25: Porcentaje | G25: Extras | H25: Porcentaje | I25: Total Aportes
A26: DOS57 | C26: 0 | D26: 0 | E26: =+D12 -> 456298 | F26: 1 | G26: =+D18 -> 28695.32 | H26: 1 | I26: =+C26+E26+G26 -> 484993.32
A27: JIMENEZ | C27: 1030000 | D27: 1 | E27: 0 | F27: 0 | G27: 0 | H27: 0 | I27: =+C27+E27+G27 -> 1030000

Sheet MARZO 2024
A1: RENDICION DE GASTOS NAVE 15 | H1: MES: | I1: AÑO
H2: MARZO | I2: 2024
A3: RUBROS FIJOS | D3: GASTO | E3: DOS57 (50%) | F3: JIMENEZ (50%) | G3: OBSERVACION
A4: ALQUILER | D4: 1030000 | E4: =D4*50% -> 515000 | F4: =+D4*50% -> 515000
A6: TOTAL | D6: =SUM(D4:D5) -> 1030000 | E6: =SUM(E4:E5) -> 515000 | F6: =SUM(F4:F5) -> 515000
A8: RUBROS VARIABLES | D8: GASTO | E8: DOS57 (50%) | F8: JIMENEZ (50%) | G8: OBSERVACION
A9: EXPENSAS | D9: 527406 | E9: =+D9*50% -> 263703 | F9: =+D9*50% -> 263703
A10: IMPUESTOS DGR | D10: 0 | E10: =+D10*50% -> 0 | F10: =+D10*50% -> 0
A11: EPEC | D11: 17751 | E11: =+D11*50% -> 8875.5 | F11: =+D11*50% -> 8875.5
A12: TOTAL | D12: =SUM(D9:D11) -> 545157 | E12: =SUM(E9:E11) -> 272578.5 | F12: =SUM(F9:F11) -> 272578.5
A14: EXTRAS | D14: GASTO | E14: DOS57 (50%) | F14: JIMENEZ (50%) | G14: OBSERVACION
A15: INTERNET - WIFI | D15: 35416.18 | E15: =+D15*50% -> 17708.09 | F15: =+D15*50% -> 17708.09 | G15: ABONO MENSUAL
A16: MANTENIMIENTO JARDINEROS | D16: 0 | E16: =+D16*50% -> 0 | F16: =+D16*50% -> 0 | G16: APROX MENSUAL $ 5.000
A17: AREA PROTEGIDA | D17: 0 | E17: =+D17*50% -> 0 | F17: =+D17*50% -> 0 | G17: SIN COBERTURA APROX MENSUAL $6.000
A18: TOTAL | D18: =SUM(D15) -> 35416.18 | E18: =SUM(E15:E17) -> 17708.09 | F18: =SUM(F15:F17) -> 17708.09
A20: GASTO POR EMPRESA | C20: =+H2 -> MARZO | D20: Porcentaje
A21: DOS57 | C21: =+E18+E12+E6 -> 805286.59 | D21: 0.5
A22: JIMENEZ | C22: =+F18+F12+F6 -> 805286.59 | D22: 0.5
A23: TOTALES | C23: =SUM(C21:C22) -> 1610573.2 | D23: =SUM(D21:D22) -> 1
A25: GASTO POR EMPRESA (PRACTICA) | C25: Alquiler | D25: Porcentaje | E25: Rubros Variables | F25: Porcentaje | G25: Extras | H25: Porcentaje | I25: Total Aportes
A26: DOS57 | C26: 0 | D26: 0 | E26: =+D12 -> 545157 | F26: 1 | G26: =+D18 -> 35416.18 | H26: 1 | I26: =+C26+E26+G26 -> 580573.18
A27: JIMENEZ | C27: 1030000 | D27: 1 | E27: 0 | F27: 0 | G27: 0 | H27: 0 | I27: =+C27+E27+G27 -> 1030000

Sheet ABRIL 2024
A1: RENDICION DE GASTOS NAVE 15 | H1: MES: | I1: AÑO
H2: ABRIL | I2: 2024
A3: RUBROS FIJOS | D3: GASTO | E3: DOS57 (50%) | F3: JIMENEZ (50%) | G3: OBSERVACION
A4: ALQUILER | D4: 1505350 | E4: =D4*50% -> 752675 | F4: =+D4*50% -> 752675
A6: TOTAL | D6: =SUM(D4:D5) -> 1505350 | E6: =SUM(E4:E5) -> 752675 | F6: =SUM(F4:F5) -> 752675
A8: RUBROS VARIABLES | D8: GASTO | E8: DOS57 (50%) | F8: JIMENEZ (50%) | G8: OBSERVACION
A9: EXPENSAS | D9: 560911 | E9: =+D9*50% -> 280455.5 | F9: =+D9*50% -> 280455.5
A10: IMPUESTOS DGR | D10: 0 | E10: =+D10*50% -> 0 | F10: =+D10*50% -> 0
A11: EPEC | D11: 11019 | E11: =+D11*50% -> 5509.5 | F11: =+D11*50% -> 5509.5
A12: TOTAL | D12: =SUM(D9:D11) -> 571930 | E12: =SUM(E9:E11) -> 285965 | F12: =SUM(F9:F11) -> 285965
A14: EXTRAS | D14: GASTO | E14: DOS57 (50%) | F14: JIMENEZ (50%) | G14: OBSERVACION
A15: INTERNET - WIFI | D15: 38375.3 | E15: =+D15*50% -> 19187.65 | F15: =+D15*50% -> 19187.65 | G15: ABONO MENSUAL
A16: MANTENIMIENTO JARDINEROS | D16: 0 | E16: =+D16*50% -> 0 | F16: =+D16*50% -> 0 | G16: APROX MENSUAL $ 5.000
A17: AREA PROTEGIDA | D17: 0 | E17: =+D17*50% -> 0 | F17: =+D17*50% -> 0 | G17: SIN COBERTURA APROX MENSUAL $6.000
A18: TOTAL | D18: =SUM(D15) -> 38375.3 | E18: =SUM(E15:E17) -> 19187.65 | F18: =SUM(F15:F17) -> 19187.65
A20: GASTO POR EMPRESA | C20: =+H2 -> ABRIL | D20: Porcentaje
A21: DOS57 | C21: =+E18+E12+E6 -> 1057827.6 | D21: 0.5
A22: JIMENEZ | C22: =+F18+F12+F6 -> 1057827.6 | D22: 0.5
A23: TOTALES | C23: =SUM(C21:C22) -> 2115655.3 | D23: =SUM(D21:D22) -> 1
A25: GASTO POR EMPRESA (PRACTICA) | C25: Alquiler | D25: Porcentaje | E25: Rubros Variables | F25: Porcentaje | G25: Extras | H25: Porcentaje | I25: Total Aportes
A26: DOS57 | C26: =+D4 -> 1505350 | D26: 1 | E26: =+D12 -> 571930 | F26: 1 | G26: =+D18 -> 38375.3 | H26: 1 | I26: =+C26+E26+G26 -> 2115655.3
A27: JIMENEZ | C27: 0 | D27: 0 | E27: 0 | F27: 0 | G27: 0 | H27: 0 | I27: =+C27+E27+G27 -> 0

Sheet MAYO 2024
A1: RENDICION DE GASTOS NAVE 15 | H1: MES: | I1: AÑO
H2: MAYO | I2: 2024
A3: RUBROS FIJOS | D3: GASTO | E3: DOS57 (50%) | F3: JIMENEZ (50%) | G3: OBSERVACION
A4: ALQUILER | D4: 1888950 | E4: =D4*50% -> 944475 | F4: =+D4*50% -> 944475
A6: TOTAL | D6: =SUM(D4:D5) -> 1888950 | E6: =SUM(E4:E5) -> 944475 | F6: =SUM(F4:F5) -> 944475
A8: RUBROS VARIABLES | D8: GASTO | E8: DOS57 (50%) | F8: JIMENEZ (50%) | G8: OBSERVACION
A9: EXPENSAS | D9: 654240 | E9: =+D9*50% -> 327120 | F9: =+D9*50% -> 327120
A10: IMPUESTOS DGR | D10: 0 | E10: =+D10*50% -> 0 | F10: =+D10*50% -> 0
A11: EPEC | D11: 99 | E11: =+D11*50% -> 49.5 | F11: =+D11*50% -> 49.5
A12: TOTAL | D12: =SUM(D9:D11) -> 654339 | E12: =SUM(E9:E11) -> 327169.5 | F12: =SUM(F9:F11) -> 327169.5
A14: EXTRAS | D14: GASTO | E14: DOS57 (50%) | F14: JIMENEZ (50%) | G14: OBSERVACION
A15: INTERNET - WIFI | D15: 34869.28 | E15: =+D15*50% -> 17434.64 | F15: =+D15*50% -> 17434.64 | G15: ABONO MENSUAL
A16: MANTENIMIENTO JARDINEROS | D16: 0 | E16: =+D16*50% -> 0 | F16: =+D16*50% -> 0 | G16: APROX MENSUAL $ 5.000
A17: AREA PROTEGIDA | D17: 0 | E17: =+D17*50% -> 0 | F17: =+D17*50% -> 0 | G17: SIN COBERTURA APROX MENSUAL $6.000
A18: TOTAL | D18: =SUM(D15) -> 34869.28 | E18: =SUM(E15:E17) -> 17434.64 | F18: =SUM(F15:F17) -> 17434.64
A20: GASTO POR EMPRESA | C20: =+H2 -> MAYO | D20: Porcentaje
A21: DOS57 | C21: =+E18+E12+E6 -> 1289079.1 | D21: 0.5
A22: JIMENEZ | C22: =+F18+F12+F6 -> 1289079.1 | D22: 0.5
A23: TOTALES | C23: =SUM(C21:C22) -> 2578158.3 | D23: =SUM(D21:D22) -> 1
A25: GASTO POR EMPRESA (PRACTICA) | C25: Alquiler | D25: Porcentaje | E25: Rubros Variables | F25: Porcentaje | G25: Extras | H25: Porcentaje | I25: Total Aportes
A26: DOS57 | C26: =+D4 -> 1888950 | D26: 1 | E26: =+D12 -> 654339 | F26: 1 | G26: =+D18 -> 34869.28 | H26: 1 | I26: =+C26+E26+G26 -> 2578158.3
A27: JIMENEZ | C27: 0 | D27: 0 | E27: 0 | F27: 0 | G27: 0 | H27: 0 | I27: =+C27+E27+G27 -> 0

Sheet JUNIO 2024
A1: RENDICION DE GASTOS NAVE 15 | H1: MES: | I1: AÑO
H2: JUNIO | I2: 2024
A3: RUBROS FIJOS | D3: GASTO | E3: DOS57 (50%) | F3: JIMENEZ (50%) | G3: OBSERVACION
A4: ALQUILER | D4: 2062125 | E4: =D4*50% -> 1031062.5 | F4: =+D4*50% -> 1031062.5
A6: TOTAL | D6: =SUM(D4:D5) -> 2062125 | E6: =SUM(E4:E5) -> 1031062.5 | F6: =SUM(F4:F5) -> 1031062.5
A8: RUBROS VARIABLES | D8: GASTO | E8: DOS57 (50%) | F8: JIMENEZ (50%) | G8: OBSERVACION
A9: EXPENSAS | D9: 801147 | E9: =+D9*50% -> 400573.5 | F9: =+D9*50% -> 400573.5
A10: IMPUESTOS DGR | D10: 0 | E10: =+D10*50% -> 0 | F10: =+D10*50% -> 0
A11: EPEC | D11: 403 | E11: =+D11*50% -> 201.5 | F11: =+D11*50% -> 201.5
A12: TOTAL | D12: =SUM(D9:D11) -> 801550 | E12: =SUM(E9:E11) -> 400775 | F12: =SUM(F9:F11) -> 400775
A14: EXTRAS | D14: GASTO | E14: DOS57 (50%) | F14: JIMENEZ (50%) | G14: OBSERVACION
A15: INTERNET - WIFI | D15: 34226 | E15: =+D15*50% -> 17113 | F15: =+D15*50% -> 17113 | G15: ABONO MENSUAL
A16: MANTENIMIENTO JARDINEROS | D16: 0 | E16: =+D16*50% -> 0 | F16: =+D16*50% -> 0 | G16: APROX MENSUAL $ 5.000
A17: AREA PROTEGIDA | D17: 0 | E17: =+D17*50% -> 0 | F17: =+D17*50% -> 0 | G17: SIN COBERTURA APROX MENSUAL $6.000
A18: TOTAL | D18: =SUM(D15) -> 34226 | E18: =SUM(E15:E17) -> 17113 | F18: =SUM(F15:F17) -> 17113
A20: GASTO POR EMPRESA | C20: =+H2 -> JUNIO | D20: Porcentaje
A21: DOS57 | C21: =+E18+E12+E6 -> 1448950.5 | D21: 0.5
A22: JIMENEZ | C22: =+F18+F12+F6 -> 1448950.5 | D22: 0.5
A23: TOTALES | C23: =SUM(C21:C22) -> 2897901 | D23: =SUM(D21:D22) -> 1
A25: GASTO POR EMPRESA (PRACTICA) | C25: Alquiler | D25: Porcentaje | E25: Rubros Variables | F25: Porcentaje | G25: Extras | H25: Porcentaje | I25: Total Aportes
A26: DOS57 | C26: 0 | D26: 0 | E26: =+D12 -> 801550 | F26: 1 | G26: =+D18 -> 34226 | H26: 1 | I26: =+C26+E26+G26 -> 835776
A27: JIMENEZ | C27: =+D4 -> 2062125 | D27: 1 | E27: 0 | F27: 0 | G27: 0 | H27: 0 | I27: =+C27+E27+G27 -> 2062125

Sheet JULIO 2024
A1: RENDICION DE GASTOS NAVE 15 | H1: MES: | I1: AÑO
H2: JULIO | I2: 2024
A3: RUBROS FIJOS | D3: GASTO | E3: DOS57 (50%) | F3: JIMENEZ (50%) | G3: OBSERVACION
A4: ALQUILER | D4: 2247600 | E4: =D4*50% -> 1123800 | F4: =+D4*50% -> 1123800
A6: TOTAL | D6: =SUM(D4:D5) -> 2247600 | E6: =SUM(E4:E5) -> 1123800 | F6: =SUM(F4:F5) -> 1123800
A8: RUBROS VARIABLES | D8: GASTO | E8: DOS57 (50%) | F8: JIMENEZ (50%) | G8: OBSERVACION
A9: EXPENSAS | D9: 798074 | E9: =+D9*50% -> 399037 | F9: =+D9*50% -> 399037
A10: IMPUESTOS DGR | D10: 0 | E10: =+D10*50% -> 0 | F10: =+D10*50% -> 0
A11: EPEC | D11: 3017 | E11: =+D11*50% -> 1508.5 | F11: =+D11*50% -> 1508.5
A12: TOTAL | D12: =SUM(D9:D11) -> 801091 | E12: =SUM(E9:E11) -> 400545.5 | F12: =SUM(F9:F11) -> 400545.5
A14: EXTRAS | D14: GASTO | E14: DOS57 (50%) | F14: JIMENEZ (50%) | G14: OBSERVACION
A15: INTERNET - WIFI | D15: 49291.08 | E15: =+D15*50% -> 24645.54 | F15: =+D15*50% -> 24645.54 | G15: ABONO MENSUAL
A16: MANTENIMIENTO JARDINEROS | D16: 0 | E16: =+D16*50% -> 0 | F16: =+D16*50% -> 0 | G16: APROX MENSUAL $ 5.000
A17: AREA PROTEGIDA | D17: 0 | E17: =+D17*50% -> 0 | F17: =+D17*50% -> 0 | G17: SIN COBERTURA APROX MENSUAL $6.000
A18: TOTAL | D18: =SUM(D15) -> 49291.08 | E18: =SUM(E15:E17) -> 24645.54 | F18: =SUM(F15:F17) -> 24645.54
A20: GASTO POR EMPRESA | C20: =+H2 -> JULIO | D20: Porcentaje
A21: DOS57 | C21: =+E18+E12+E6 -> 1548991 | D21: 0.5
A22: JIMENEZ | C22: =+F18+F12+F6 -> 1548991 | D22: 0.5
A23: TOTALES | C23: =SUM(C21:C22) -> 3097982.1 | D23: =SUM(D21:D22) -> 1
A25: GASTO POR EMPRESA (PRACTICA) | C25: Alquiler | D25: Porcentaje | E25: Rubros Variables | F25: Porcentaje | G25: Extras | H25: Porcentaje | I25: Total Aportes
A26: DOS57 | C26: 0 | D26: 0 | E26: =+D12 -> 801091 | F26: 1 | G26: =+D18 -> 49291.08 | H26: 1 | I26: =+C26+E26+G26 -> 850382.08
A27: JIMENEZ | C27: =+D4 -> 2247600 | D27: 1 | E27: 0 | F27: 0 | G27: 0 | H27: 0 | I27: =+C27+E27+G27 -> 2247600

Sheet AGOSTO 2024
A1: RENDICION DE GASTOS NAVE 15 | H1: MES: | I1: AÑO
H2: AGOSTO | I2: 2024
A3: RUBROS FIJOS | D3: GASTO | E3: DOS57 (50%) | F3: JIMENEZ (50%) | G3: OBSERVACION
A4: ALQUILER | D4: 2436525 | E4: =D4*50% -> 1218262.5 | F4: =+D4*50% -> 1218262.5
A6: TOTAL | D6: =SUM(D4:D5) -> 2436525 | E6: =SUM(E4:E5) -> 1218262.5 | F6: =SUM(F4:F5) -> 1218262.5
A8: RUBROS VARIABLES | D8: GASTO | E8: DOS57 (50%) | F8: JIMENEZ (50%) | G8: OBSERVACION
A9: EXPENSAS | D9: 849814 | E9: =+D9*50% -> 424907 | F9: =+D9*50% -> 424907
A10: IMPUESTOS DGR | D10: 0 | E10: =+D10*50% -> 0 | F10: =+D10*50% -> 0
A11: EPEC | D11: 3470 | E11: =+D11*50% -> 1735 | F11: =+D11*50% -> 1735
A12: TOTAL | D12: =SUM(D9:D11) -> 853284 | E12: =SUM(E9:E11) -> 426642 | F12: =SUM(F9:F11) -> 426642
A14: EXTRAS | D14: GASTO | E14: DOS57 (50%) | F14: JIMENEZ (50%) | G14: OBSERVACION
A15: INTERNET - WIFI | D15: 54767.83 | E15: =+D15*50% -> 27383.915 | F15: =+D15*50% -> 27383.915 | G15: ABONO MENSUAL
A16: MANTENIMIENTO JARDINEROS | D16: 0 | E16: =+D16*50% -> 0 | F16: =+D16*50% -> 0 | G16: APROX MENSUAL $ 5.000
A17: AREA PROTEGIDA | D17: 0 | E17: =+D17*50% -> 0 | F17: =+D17*50% -> 0 | G17: SIN COBERTURA APROX MENSUAL $6.000
A18: TOTAL | D18: =SUM(D15) -> 54767.83 | E18: =SUM(E15:E17) -> 27383.915 | F18: =SUM(F15:F17) -> 27383.915
A20: GASTO POR EMPRESA | C20: =+H2 -> AGOSTO | D20: Porcentaje
A21: DOS57 | C21: =+E18+E12+E6 -> 1672288.4 | D21: 0.5
A22: JIMENEZ | C22: =+F18+F12+F6 -> 1672288.4 | D22: 0.5
A23: TOTALES | C23: =SUM(C21:C22) -> 3344576.8 | D23: =SUM(D21:D22) -> 1
A25: GASTO POR EMPRESA (PRACTICA) | C25: Alquiler | D25: Porcentaje | E25: Rubros Variables | F25: Porcentaje | G25: Extras | H25: Porcentaje | I25: Total Aportes
A26: DOS57 | C26: =+D4 -> 2436525 | D26: 1 | E26: =+D12 -> 853284 | F26: 1 | G26: =+D18 -> 54767.83 | H26: 1 | I26: =+C26+E26+G26 -> 3344576.8
A27: JIMENEZ | C27: 0 | D27: 0 | E27: 0 | F27: 0 | G27: 0 | H27: 0 | I27: =+C27+E27+G27 -> 0

Sheet SEPTIEMBRE 2024
A1: RENDICION DE GASTOS NAVE 15 | H1: MES: | I1: AÑO
H2: SEPTIEMBRE | I2: 2024
A3: RUBROS FIJOS | D3: GASTO | E3: DOS57 (50%) | F3: JIMENEZ (50%) | G3: OBSERVACION
A4: ALQUILER | D4: 2491350 | E4: =D4*50% -> 1245675 | F4: =+D4*50% -> 1245675
A6: TOTAL | D6: =SUM(D4:D5) -> 2491350 | E6: =SUM(E4:E5) -> 1245675 | F6: =SUM(F4:F5) -> 1245675
A8: RUBROS VARIABLES | D8: GASTO | E8: DOS57 (50%) | F8: JIMENEZ (50%) | G8: OBSERVACION
A9: EXPENSAS | D9: 756030 | E9: =+D9*50% -> 378015 | F9: =+D9*50% -> 378015
A10: IMPUESTOS DGR | D10: 0 | E10: =+D10*50% -> 0 | F10: =+D10*50% -> 0
A11: EPEC | D11: 11055 | E11: =+D11*50% -> 5527.5 | F11: =+D11*50% -> 5527.5
A12: TOTAL | D12: =SUM(D9:D11) -> 767085 | E12: =SUM(E9:E11) -> 383542.5 | F12: =SUM(F9:F11) -> 383542.5
A14: EXTRAS | D14: GASTO | E14: DOS57 (50%) | F14: JIMENEZ (50%) | G14: OBSERVACION
A15: INTERNET - WIFI | D15: 57186.37 | E15: =+D15*50% -> 28593.185 | F15: =+D15*50% -> 28593.185 | G15: ABONO MENSUAL
A16: MANTENIMIENTO JARDINEROS | D16: 0 | E16: =+D16*50% -> 0 | F16: =+D16*50% -> 0 | G16: APROX MENSUAL $ 5.000
A17: AREA PROTEGIDA | D17: 0 | E17: =+D17*50% -> 0 | F17: =+D17*50% -> 0 | G17: SIN COBERTURA APROX MENSUAL $6.000
A18: TOTAL | D18: =SUM(D15) -> 57186.37 | E18: =SUM(E15:E17) -> 28593.185 | F18: =SUM(F15:F17) -> 28593.185
A20: GASTO POR EMPRESA | C20: =+H2 -> SEPTIEMBRE | D20: Porcentaje
A21: DOS57 | C21: =+E18+E12+E6 -> 1657810.7 | D21: 0.5
A22: JIMENEZ | C22: =+F18+F12+F6 -> 1657810.7 | D22: 0.5
A23: TOTALES | C23: =SUM(C21:C22) -> 3315621.4 | D23: =SUM(D21:D22) -> 1
A25: GASTO POR EMPRESA (PRACTICA) | C25: Alquiler | D25: Porcentaje | E25: Rubros Variables | F25: Porcentaje | G25: Extras | H25: Porcentaje | I25: Total Aportes
A26: DOS57 | C26: =+D4 -> 2491350 | D26: 1 | E26: =+D12 -> 767085 | F26: 1 | G26: =+D18 -> 57186.37 | H26: 1 | I26: =+C26+E26+G26 -> 3315621.4
A27: JIMENEZ | C27: 0 | D27: 0 | E27: 0 | F27: 0 | G27: 0 | H27: 0 | I27: =+C27+E27+G27 -> 0

Sheet OCTUBRE 2024
A1: RENDICION DE GASTOS NAVE 15 | H1: MES: | I1: AÑO
H2: OCTUBRE | I2: 2024
A3: RUBROS FIJOS | D3: GASTO | E3: DOS57 (50%) | F3: JIMENEZ (50%) | G3: OBSERVACION
A4: ALQUILER | D4: 2675700 | E4: =D4*50% -> 1337850 | F4: =+D4*50% -> 1337850
A6: TOTAL | D6: =SUM(D4:D5) -> 2675700 | E6: =SUM(E4:E5) -> 1337850 | F6: =SUM(F4:F5) -> 1337850
A8: RUBROS VARIABLES | D8: GASTO | E8: DOS57 (50%) | F8: JIMENEZ (50%) | G8: OBSERVACION
A9: EXPENSAS | D9: 799095 | E9: =+D9*50% -> 399547.5 | F9: =+D9*50% -> 399547.5
A10: IMPUESTOS DGR | D10: 0 | E10: =+D10*50% -> 0 | F10: =+D10*50% -> 0
A11: EPEC | D11: 1923 | E11: =+D11*50% -> 961.5 | F11: =+D11*50% -> 961.5
A12: TOTAL | D12: =SUM(D9:D11) -> 801018 | E12: =SUM(E9:E11) -> 400509 | F12: =SUM(F9:F11) -> 400509
A14: EXTRAS | D14: GASTO | E14: DOS57 (50%) | F14: JIMENEZ (50%) | G14: OBSERVACION
A15: INTERNET - WIFI | D15: 70453.16 | E15: =+D15*50% -> 35226.58 | F15: =+D15*50% -> 35226.58 | G15: ABONO MENSUAL
A16: MANTENIMIENTO JARDINEROS | D16: 0 | E16: =+D16*50% -> 0 | F16: =+D16*50% -> 0 | G16: APROX MENSUAL $ 5.000
A17: AREA PROTEGIDA | D17: 0 | E17: =+D17*50% -> 0 | F17: =+D17*50% -> 0 | G17: SIN COBERTURA APROX MENSUAL $6.000
A18: TOTAL | D18: =SUM(D15) -> 70453.16 | E18: =SUM(E15:E17) -> 35226.58 | F18: =SUM(F15:F17) -> 35226.58
A20: GASTO POR EMPRESA | C20: =+H2 -> OCTUBRE | D20: Porcentaje
A21: DOS57 | C21: =+E18+E12+E6 -> 1773585.6 | D21: 0.5
A22: JIMENEZ | C22: =+F18+F12+F6 -> 1773585.6 | D22: 0.5
A23: TOTALES | C23: =SUM(C21:C22) -> 3547171.2 | D23: =SUM(D21:D22) -> 1
A25: GASTO POR EMPRESA (PRACTICA) | C25: Alquiler | D25: Porcentaje | E25: Rubros Variables | F25: Porcentaje | G25: Extras | H25: Porcentaje | I25: Total Aportes
A26: DOS57 | C26: 0 | D26: 0 | E26: =+D12 -> 801018 | F26: 1 | G26: =+D18 -> 70453.16 | H26: 1 | I26: =+C26+E26+G26 -> 871471.16
A27: JIMENEZ | C27: =+D4 -> 2675700 | D27: 1 | E27: 0 | F27: 0 | G27: 0 | H27: 0 | I27: =+C27+E27+G27 -> 2675700

Sheet NOVIEMBRE 2024
A1: RENDICION DE GASTOS NAVE 15 | H1: MES: | I1: AÑO
H2: NOVIEMBRE | I2: 2024
A3: RUBROS FIJOS | D3: GASTO | E3: DOS57 (50%) | F3: JIMENEZ (50%) | G3: OBSERVACION
A4: ALQUILER | D4: 2887050 | E4: =D4*50% -> 1443525 | F4: =+D4*50% -> 1443525
A6: TOTAL | D6: =SUM(D4:D5) -> 2887050 | E6: =SUM(E4:E5) -> 1443525 | F6: =SUM(F4:F5) -> 1443525
A8: RUBROS VARIABLES | D8: GASTO | E8: DOS57 (50%) | F8: JIMENEZ (50%) | G8: OBSERVACION
A9: EXPENSAS | D9: 916790 | E9: =+D9*50% -> 458395 | F9: =+D9*50% -> 458395
A10: IMPUESTOS DGR | D10: 0 | E10: =+D10*50% -> 0 | F10: =+D10*50% -> 0
A11: EPEC | D11: 888 | E11: =+D11*50% -> 444 | F11: =+D11*50% -> 444
A12: TOTAL | D12: =SUM(D9:D11) -> 917678 | E12: =SUM(E9:E11) -> 458839 | F12: =SUM(F9:F11) -> 458839
A14: EXTRAS | D14: GASTO | E14: DOS57 (50%) | F14: JIMENEZ (50%) | G14: OBSERVACION
A15: INTERNET - WIFI | D15: 67756.69 | E15: =+D15*50% -> 33878.345 | F15: =+D15*50% -> 33878.345 | G15: ABONO MENSUAL
A16: MANTENIMIENTO JARDINEROS | D16: 0 | E16: =+D16*50% -> 0 | F16: =+D16*50% -> 0 | G16: APROX MENSUAL $ 5.000
A17: AREA PROTEGIDA | D17: 0 | E17: =+D17*50% -> 0 | F17: =+D17*50% -> 0 | G17: SIN COBERTURA APROX MENSUAL $6.000
A18: TOTAL | D18: =SUM(D15:D17) -> 67756.69 | E18: =SUM(E15:E17) -> 33878.345 | F18: =SUM(F15:F17) -> 33878.345
A20: GASTO POR EMPRESA | C20: =+H2 -> NOVIEMBRE | D20: Porcentaje
A21: DOS57 | C21: =+E18+E12+E6 -> 1936242.3 | D21: 0.5
A22: JIMENEZ | C22: =+F18+F12+F6 -> 1936242.3 | D22: 0.5
A23: TOTALES | C23: =SUM(C21:C22) -> 3872484.7 | D23: =SUM(D21:D22) -> 1
A25: GASTO POR EMPRESA (PRACTICA) | C25: Alquiler | D25: Porcentaje | E25: Rubros Variables | F25: Porcentaje | G25: Extras | H25: Porcentaje | I25: Total Aportes
A26: DOS57 | C26: 0 | D26: 0 | E26: =+D12 -> 917678 | F26: 1 | G26: =+D18 -> 67756.69 | H26: 1 | I26: =+C26+E26+G26 -> 985434.69
A27: JIMENEZ | C27: =+D4 -> 2887050 | D27: 1 | E27: 0 | F27: 0 | G27: 0 | H27: 0 | I27: =+C27+E27+G27 -> 2887050

Sheet DICIEMBRE 2024
A1: RENDICION DE GASTOS NAVE 15 | H1: MES: | I1: AÑO
H2: DICIEMBRE | I2: 2024
A3: RUBROS FIJOS | D3: GASTO | E3: DOS57 (50%) | F3: JIMENEZ (50%) | G3: OBSERVACION
A4: ALQUILER | D4: 3096000 | E4: =D4*50% -> 1548000 | F4: =+D4*50% -> 1548000
A6: TOTAL | D6: =SUM(D4:D5) -> 3096000 | E6: =SUM(E4:E5) -> 1548000 | F6: =SUM(F4:F5) -> 1548000
A8: RUBROS VARIABLES | D8: GASTO | E8: DOS57 (50%) | F8: JIMENEZ (50%) | G8: OBSERVACION
A9: EXPENSAS | D9: 828153 | E9: =+D9*50% -> 414076.5 | F9: =+D9*50% -> 414076.5
A10: IMPUESTOS DGR | D10: 0 | E10: =+D10*50% -> 0 | F10: =+D10*50% -> 0
A11: EPEC | D11: 2375 | E11: =+D11*50% -> 1187.5 | F11: =+D11*50% -> 1187.5
A12: TOTAL | D12: =SUM(D9:D11) -> 830528 | E12: =SUM(E9:E11) -> 415264 | F12: =SUM(F9:F11) -> 415264
A14: EXTRAS | D14: GASTO | E14: DOS57 (50%) | F14: JIMENEZ (50%) | G14: OBSERVACION
A15: INTERNET - WIFI | D15: 72445.64 | E15: =+D15*50% -> 36222.82 | F15: =+D15*50% -> 36222.82 | G15: ABONO MENSUAL
A16: MANTENIMIENTO JARDINEROS | D16: 50000 | E16: =+D16*50% -> 25000 | F16: =+D16*50% -> 25000 | G16: APROX MENSUAL $ 5.000
A17: AREA PROTEGIDA | D17: 0 | E17: =+D17*50% -> 0 | F17: =+D17*50% -> 0 | G17: SIN COBERTURA APROX MENSUAL $6.000
A18: TOTAL | D18: =SUM(D15:D17) -> 122445.64 | E18: =SUM(E15:E17) -> 61222.82 | F18: =SUM(F15:F17) -> 61222.82
A20: GASTO POR EMPRESA | C20: =+H2 -> DICIEMBRE | D20: Porcentaje
A21: DOS57 | C21: =+E18+E12+E6 -> 2024486.8 | D21: 0.5
A22: JIMENEZ | C22: =+F18+F12+F6 -> 2024486.8 | D22: 0.5
A23: TOTALES | C23: =SUM(C21:C22) -> 4048973.6 | D23: =SUM(D21:D22) -> 1
A25: GASTO POR EMPRESA (PRACTICA) | C25: Alquiler | D25: Porcentaje | E25: Rubros Variables | F25: Porcentaje | G25: Extras | H25: Porcentaje | I25: Total Aportes
A26: DOS57 | C26: 0 | D26: 0 | E26: =+D12 -> 830528 | F26: 1 | G26: =+D18 -> 122445.64 | H26: 1 | I26: =+C26+E26+G26 -> 952973.64
A27: JIMENEZ | C27: =+D4 -> 3096000 | D27: 1 | E27: 0 | F27: 0 | G27: 0 | H27: 0 | I27: =+C27+E27+G27 -> 3096000

Sheet ENERO 2025
A1: RENDICION DE GASTOS NAVE 15 | H1: MES: | I1: AÑO
H2: ENERO | I2: 2025
A3: RUBROS FIJOS | D3: GASTO | E3: DOS57 (50%) | F3: JIMENEZ (50%) | G3: OBSERVACION
A4: ALQUILER | D4: 3096000 | E4: =D4*50% -> 1548000 | F4: =+D4*50% -> 1548000
A6: TOTAL | D6: =SUM(D4:D5) -> 3096000 | E6: =SUM(E4:E5) -> 1548000 | F6: =SUM(F4:F5) -> 1548000
A8: RUBROS VARIABLES | D8: GASTO | E8: DOS57 (50%) | F8: JIMENEZ (50%) | G8: OBSERVACION
A9: EXPENSAS | D9: 864398 | E9: =+D9*50% -> 432199 | F9: =+D9*50% -> 432199
A10: IMPUESTOS DGR | D10: 0 | E10: =+D10*50% -> 0 | F10: =+D10*50% -> 0
A11: EPEC | D11: 9060 | E11: =+D11*50% -> 4530 | F11: =+D11*50% -> 4530
A12: TOTAL | D12: =SUM(D9:D11) -> 873458 | E12: =SUM(E9:E11) -> 436729 | F12: =SUM(F9:F11) -> 436729
A14: EXTRAS | D14: GASTO | E14: DOS57 (50%) | F14: JIMENEZ (50%) | G14: OBSERVACION
A15: INTERNET - WIFI | D15: 77553.55 | E15: =+D15*50% -> 38776.775 | F15: =+D15*50% -> 38776.775 | G15: ABONO MENSUAL
A16: MANTENIMIENTO JARDINEROS | D16: 0 | E16: =+D16*50% -> 0 | F16: =+D16*50% -> 0 | G16: APROX MENSUAL $ 5.000
A17: AREA PROTEGIDA | D17: 0 | E17: =+D17*50% -> 0 | F17: =+D17*50% -> 0 | G17: SIN COBERTURA APROX MENSUAL $6.000
A18: TOTAL | D18: =SUM(D15:D17) -> 77553.55 | E18: =SUM(E15:E17) -> 38776.775 | F18: =SUM(F15:F17) -> 38776.775
A20: GASTO POR EMPRESA | C20: =+H2 -> ENERO | D20: Porcentaje
A21: DOS57 | C21: =+E18+E12+E6 -> 2023505.8 | D21: 0.5
A22: JIMENEZ | C22: =+F18+F12+F6 -> 2023505.8 | D22: 0.5
A23: TOTALES | C23: =SUM(C21:C22) -> 4047011.5 | D23: =SUM(D21:D22) -> 1
A25: GASTO POR EMPRESA (PRACTICA) | C25: Alquiler | D25: Porcentaje | E25: Rubros Variables | F25: Porcentaje | G25: Extras | H25: Porcentaje | I25: Total Aportes
A26: DOS57 | C26: 0 | D26: 0 | E26: =+D12 -> 873458 | F26: 1 | G26: =+D18 -> 77553.55 | H26: 1 | I26: =+C26+E26+G26 -> 951011.55
A27: JIMENEZ | C27: =+D4 -> 3096000 | D27: 1 | E27: 0 | F27: 0 | G27: 0 | H27: 0 | I27: =+C27+E27+G27 -> 3096000

Sheet FEBRERO 2025
A1: RENDICION DE GASTOS NAVE 15 | H1: MES: | I1: AÑO
H2: FEBRERO | I2: 2025
A3: RUBROS FIJOS | D3: GASTO | E3: DOS57 (50%) | F3: JIMENEZ (50%) | G3: OBSERVACION
A4: ALQUILER | D4: 3981200 | E4: =D4*50% -> 1990600 | F4: =+D4*50% -> 1990600
A6: TOTAL | D6: =SUM(D4:D5) -> 3981200 | E6: =SUM(E4:E5) -> 1990600 | F6: =SUM(F4:F5) -> 1990600
A8: RUBROS VARIABLES | D8: GASTO | E8: DOS57 (50%) | F8: JIMENEZ (50%) | G8: OBSERVACION
A9: EXPENSAS | D9: 872375 | E9: =+D9*50% -> 436187.5 | F9: =+D9*50% -> 436187.5
A10: IMPUESTOS DGR | D10: 0 | E10: =+D10*50% -> 0 | F10: =+D10*50% -> 0
A11: EPEC | D11: 436 | E11: =+D11*50% -> 218 | F11: =+D11*50% -> 218
A12: TOTAL | D12: =SUM(D9:D11) -> 872811 | E12: =SUM(E9:E11) -> 436405.5 | F12: =SUM(F9:F11) -> 436405.5
A14: EXTRAS | D14: GASTO | E14: DOS57 (50%) | F14: JIMENEZ (50%) | G14: OBSERVACION
A15: INTERNET - WIFI | D15: 79881.88 | E15: =+D15*50% -> 39940.94 | F15: =+D15*50% -> 39940.94 | G15: ABONO MENSUAL
A16: MANTENIMIENTO JARDINEROS | D16: 62500 | E16: =+D16*50% -> 31250 | F16: =+D16*50% -> 31250 | G16: APROX MENSUAL $ 5.000
A17: AREA PROTEGIDA | D17: 0 | E17: =+D17*50% -> 0 | F17: =+D17*50% -> 0 | G17: SIN COBERTURA APROX MENSUAL $6.000
A18: TOTAL | D18: =SUM(D15:D17) -> 142381.88 | E18: =SUM(E15:E17) -> 71190.94 | F18: =SUM(F15:F17) -> 71190.94
A20: GASTO POR EMPRESA | C20: =+H2 -> FEBRERO | D20: Porcentaje
A21: DOS57 | C21: =+E18+E12+E6 -> 2498196.4 | D21: 0.5
A22: JIMENEZ | C22: =+F18+F12+F6 -> 2498196.4 | D22: 0.5
A23: TOTALES | C23: =SUM(C21:C22) -> 4996392.9 | D23: =SUM(D21:D22) -> 1
A25: GASTO POR EMPRESA (PRACTICA) | C25: Alquiler | D25: Porcentaje | E25: Rubros Variables | F25: Porcentaje | G25: Extras | H25: Porcentaje | I25: Total Aportes
A26: DOS57 | C26: 0 | D26: 0 | E26: =+D12 -> 872811 | F26: 1 | G26: =+D18 -> 142381.88 | H26: 1 | I26: =+C26+E26+G26 -> 1015192.9
A27: JIMENEZ | C27: =+D4 -> 3981200 | D27: 1 | E27: 0 | F27: 0 | G27: 0 | H27: 0 | I27: =+C27+E27+G27 -> 3981200

Sheet MARZO 2025
A1: RENDICION DE GASTOS NAVE 15 | H1: MES: | I1: AÑO
H2: MARZO | I2: 2025
A3: RUBROS FIJOS | D3: GASTO | E3: DOS57 (50%) | F3: JIMENEZ (50%) | G3: OBSERVACION
A4: ALQUILER | D4: 4446450 | E4: =D4*50% -> 2223225 | F4: =+D4*50% -> 2223225
A6: TOTAL | D6: =SUM(D4:D5) -> 4446450 | E6: =SUM(E4:E5) -> 2223225 | F6: =SUM(F4:F5) -> 2223225
A8: RUBROS VARIABLES | D8: GASTO | E8: DOS57 (50%) | F8: JIMENEZ (50%) | G8: OBSERVACION
A9: EXPENSAS | D9: 894912 | E9: =+D9*50% -> 447456 | F9: =+D9*50% -> 447456
A10: IMPUESTOS DGR | D10: 0 | E10: =+D10*50% -> 0 | F10: =+D10*50% -> 0
A11: EPEC | D11: 260 | E11: =+D11*50% -> 130 | F11: =+D11*50% -> 130
A12: TOTAL | D12: =SUM(D9:D11) -> 895172 | E12: =SUM(E9:E11) -> 447586 | F12: =SUM(F9:F11) -> 447586
A14: EXTRAS | D14: GASTO | E14: DOS57 (50%) | F14: JIMENEZ (50%) | G14: OBSERVACION
A15: INTERNET - WIFI | D15: 82291.5 | E15: =+D15*50% -> 41145.75 | F15: =+D15*50% -> 41145.75 | G15: ABONO MENSUAL
A16: MANTENIMIENTO JARDINEROS | D16: 0 | E16: =+D16*50% -> 0 | F16: =+D16*50% -> 0 | G16: APROX MENSUAL $ 5.000
A17: AREA PROTEGIDA | D17: 0 | E17: =+D17*50% -> 0 | F17: =+D17*50% -> 0 | G17: SIN COBERTURA APROX MENSUAL $6.000
A18: TOTAL | D18: =SUM(D15:D17) -> 82291.5 | E18: =SUM(E15:E17) -> 41145.75 | F18: =SUM(F15:F17) -> 41145.75
A20: GASTO POR EMPRESA | C20: =+H2 -> MARZO | D20: Porcentaje
A21: DOS57 | C21: =+E18+E12+E6 -> 2711956.8 | D21: 0.5
A22: JIMENEZ | C22: =+F18+F12+F6 -> 2711956.8 | D22: 0.5
A23: TOTALES | C23: =SUM(C21:C22) -> 5423913.5 | D23: =SUM(D21:D22) -> 1
A25: GASTO POR EMPRESA (PRACTICA) | C25: Alquiler | D25: Porcentaje | E25: Rubros Variables | F25: Porcentaje | G25: Extras | H25: Porcentaje | I25: Total Aportes
A26: DOS57 | C26: =+D4 -> 4446450 | D26: 1 | E26: =+D12 -> 895172 | F26: 1 | G26: =+D18 -> 82291.5 | H26: 1 | I26: =+C26+E26+G26 -> 5423913.5
A27: JIMENEZ | C27: 0 | D27: 0 | E27: 0 | F27: 0 | G27: 0 | H27: 0 | I27: =+C27+E27+G27 -> 0

Sheet ABRIL 2025
A1: RENDICION DE GASTOS NAVE 15 | H1: MES: | I1: AÑO
H2: ABRIL | I2: 2025
A3: RUBROS FIJOS | D3: GASTO | E3: DOS57 (50%) | F3: JIMENEZ (50%) | G3: OBSERVACION
A4: ALQUILER | D4: 4825700 | E4: =D4*50% -> 2412850 | F4: =+D4*50% -> 2412850
A6: TOTAL | D6: =SUM(D4:D5) -> 4825700 | E6: =SUM(E4:E5) -> 2412850 | F6: =SUM(F4:F5) -> 2412850
A8: RUBROS VARIABLES | D8: GASTO | E8: DOS57 (50%) | F8: JIMENEZ (50%) | G8: OBSERVACION
A9: EXPENSAS | D9: 938395 | E9: =+D9*50% -> 469197.5 | F9: =+D9*50% -> 469197.5
A10: IMPUESTOS DGR | D10: 0 | E10: =+D10*50% -> 0 | F10: =+D10*50% -> 0
A11: EPEC | D11: 783 | E11: =+D11*50% -> 391.5 | F11: =+D11*50% -> 391.5
A12: TOTAL | D12: =SUM(D9:D11) -> 939178 | E12: =SUM(E9:E11) -> 469589 | F12: =SUM(F9:F11) -> 469589
A14: EXTRAS | D14: GASTO | E14: DOS57 (50%) | F14: JIMENEZ (50%) | G14: OBSERVACION
A15: INTERNET - WIFI | D15: 92616.06 | E15: =+D15*50% -> 46308.03 | F15: =+D15*50% -> 46308.03 | G15: ABONO MENSUAL
A16: MANTENIMIENTO JARDINEROS | D16: 0 | E16: =+D16*50% -> 0 | F16: =+D16*50% -> 0 | G16: APROX MENSUAL $ 5.000
A17: AREA PROTEGIDA | D17: 0 | E17: =+D17*50% -> 0 | F17: =+D17*50% -> 0 | G17: SIN COBERTURA APROX MENSUAL $6.000
A18: TOTAL | D18: =SUM(D15:D17) -> 92616.06 | E18: =SUM(E15:E17) -> 46308.03 | F18: =SUM(F15:F17) -> 46308.03
A20: GASTO POR EMPRESA | C20: =+H2 -> ABRIL | D20: Porcentaje
A21: DOS57 | C21: =+E18+E12+E6 -> 2928747 | D21: 0.5
A22: JIMENEZ | C22: =+F18+F12+F6 -> 2928747 | D22: 0.5
A23: TOTALES | C23: =SUM(C21:C22) -> 5857494.1 | D23: =SUM(D21:D22) -> 1
A25: GASTO POR EMPRESA (PRACTICA) | C25: Alquiler | D25: Porcentaje | E25: Rubros Variables | F25: Porcentaje | G25: Extras | H25: Porcentaje | I25: Total Aportes
A26: DOS57 | C26: =+D4 -> 4825700 | D26: 1 | E26: =+D12 -> 939178 | F26: 1 | G26: =+D18 -> 92616.06 | H26: 1 | I26: =+C26+E26+G26 -> 5857494.1
