Workbook

Sheet ENERO
A1: RENDICION DE GASTOS COWORKING | H1: MES: | I1: AÑO
H2: ENERO | I2: 2026
A3: RUBROS | D3: GASTO | E3: GASTO | F3: GALARA (40%) | G3: JUAN PABLO (35%) | H3: ENJOY (25%) | I3: OBSERVACION
A4: ALQUILER | D4: Karina Vidal | E4: 1747135 | F4: =+E4*40% -> 698854 | G4: =+E4*35% -> 611497.25 | H4: =+E4*25% -> 436783.75 | I4: ** HASTA 31 de marzo 2026
A5: MUNICIPALIDAD | D5: 031402504400000 | E5: 47792 | F5: =+E5*40% -> 19116.8 | G5: =+E5*35% -> 16727.2 | H5: =+E5*25% -> 11948
A6: RENTAS | D6: 110116241561 | E6: 97190.2 | F6: =+E6*40% -> 38876.08 | G6: =+E6*35% -> 34016.57 | H6: =+E6*25% -> 24297.55
A7: AGUA | D7: 285408 | E7: 147679.48 | F7: =+E7*40% -> 59071.792 | G7: =+E7*35% -> 51687.818 | H7: =+E7*25% -> 36919.87
A8: ECOGAS | D8: 21858193 | E8: 47094.94 | F8: =+E8*40% -> 18837.976 | G8: =+E8*35% -> 16483.229 | H8: =+E8*25% -> 11773.735
A9: WIFI -CLARO | D9: 21316865904 | E9: 44525.18 | F9: =+E9*40% -> 17810.072 | G9: =+E9*35% -> 15583.813 | H9: =+E9*25% -> 11131.295
A10: COBERTURA DE ÁREA PROTEGIDA | D10: E407041 | E10: 60000 | F10: =+E10*40% -> 24000 | G10: =+E10*35% -> 21000 | H10: =+E10*25% -> 15000
A11: EPEC | D11: 1421037 / 0050866107 | E11: 327175.7 | F11: =+E11*40% -> 130870.28 | G11: =+E11*35% -> 114511.49 | H11: =+E11*25% -> 81793.925
A12: TOTAL | E12: =SUM(E4:E11) -> 2518592.5 | F12: =SUM(F4:F11) -> 1007437 | G12: =SUM(G4:G11) -> 881507.37 | H12: =SUM(H4:H11) -> 629648.12
A14: GASTO POR EMPRESA | C14: =+H2 -> ENERO | D14: Porcentaje
A15: GALARA | C15: =+F12 -> 1007437 | D15: 0.4
A16: JUAN PABLO | C16: =+G12 -> 881507.37 | D16: 0.35
A17: ENJOY | C17: =+H12 -> 629648.12 | D17: 0.25
A18: TOTALES | C18: =SUM(C15:C17) -> 2518592.5 | D18: =SUM(D15:D17) -> 1

Sheet FEBRERO
A1: RENDICION DE GASTOS COWORKING | H1: MES: | I1: AÑO
H2: FEBRERO | I2: 2026
A3: RUBROS | D3: GASTO | E3: GASTO | F3: GALARA (40%) | G3: JUAN PABLO (35%) | H3: ENJOY (25%) | I3: OBSERVACION
A4: ALQUILER | D4: Karina Vidal | E4: 1747135 | F4: =+E4*40% -> 698854 | G4: =+E4*35% -> 611497.25 | H4: =+E4*25% -> 436783.75 | I4: ** HASTA 31 de marzo 2026
A5: MUNICIPALIDAD | D5: 031402504400000 | E5: 47792 | F5: =+E5*40% -> 19116.8 | G5: =+E5*35% -> 16727.2 | H5: =+E5*25% -> 11948
A6: RENTAS | D6: 110116241561 | E6: 129761.75 | F6: =+E6*40% -> 51904.7 | G6: =+E6*35% -> 45416.612 | H6: =+E6*25% -> 32440.438
A7: AGUA | D7: 285408 | E7: 151324.39 | F7: =+E7*40% -> 60529.756 | G7: =+E7*35% -> 52963.537 | H7: =+E7*25% -> 37831.098
A8: ECOGAS | D8: 21858193 | E8: 47827.68 | F8: =+E8*40% -> 19131.072 | G8: =+E8*35% -> 16739.688 | H8: =+E8*25% -> 11956.92
A9: WIFI -CLARO | D9: 21316865904 | E9: 44525.18 | F9: =+E9*40% -> 17810.072 | G9: =+E9*35% -> 15583.813 | H9: =+E9*25% -> 11131.295
A10: COBERTURA DE ÁREA PROTEGIDA | D10: E407041 | E10: 60000 | F10: =+E10*40% -> 24000 | G10: =+E10*35% -> 21000 | H10: =+E10*25% -> 15000
A11: EPEC | D11: 1421037 / 0050866107 | E11: 357169.9 | F11: =+E11*40% -> 142867.96 | G11: =+E11*35% -> 125009.46 | H11: =+E11*25% -> 89292.475
A12: TOTAL | E12: =SUM(E4:E11) -> 2585535.9 | F12: =SUM(F4:F11) -> 1034214.4 | G12: =SUM(G4:G11) -> 904937.56 | H12: =SUM(H4:H11) -> 646383.98
A14: GASTO POR EMPRESA | C14: =+H2 -> FEBRERO | D14: Porcentaje
A15: GALARA | C15: =+F12 -> 1034214.4 | D15: 0.4
A16: JUAN PABLO | C16: =+G12 -> 904937.56 | D16: 0.35
A17: ENJOY | C17: =+H12 -> 646383.98 | D17: 0.25
A18: TOTALES | C18: =SUM(C15:C17) -> 2585535.9 | D18: =SUM(D15:D17) -> 1

Sheet MARZO
A1: RENDICION DE GASTOS COWORKING | H1: MES: | I1: AÑO
H2: MARZO | I2: 2026
A3: RUBROS | D3: GASTO | E3: GASTO | F3: GALARA (40%) | G3: JUAN PABLO (35%) | H3: ENJOY (25%) | I3: OBSERVACION
A4: ALQUILER | D4: Karina Vidal | E4: 1747135 | F4: =+E4*40% -> 698854 | G4: =+E4*35% -> 611497.25 | H4: =+E4*25% -> 436783.75 | I4: ** HASTA 31 de marzo 2026
A5: MUNICIPALIDAD | D5: 031402504400000 | E5: 47792 | F5: =+E5*40% -> 19116.8 | G5: =+E5*35% -> 16727.2 | H5: =+E5*25% -> 11948
A6: RENTAS | D6: 110116241561 | E6: 129761.75 | F6: =+E6*40% -> 51904.7 | G6: =+E6*35% -> 45416.612 | H6: =+E6*25% -> 32440.438
A7: AGUA | D7: 285408 | E7: 151324.39 | F7: =+E7*40% -> 60529.756 | G7: =+E7*35% -> 52963.537 | H7: =+E7*25% -> 37831.098
A8: ECOGAS | D8: 21858193 | E8: 47764.96 | F8: =+E8*40% -> 19105.984 | G8: =+E8*35% -> 16717.736 | H8: =+E8*25% -> 11941.24
A9: WIFI -CLARO | D9: 21316865904 | E9: 46071.95 | F9: =+E9*40% -> 18428.78 | G9: =+E9*35% -> 16125.182 | H9: =+E9*25% -> 11517.987
A10: COBERTURA DE ÁREA PROTEGIDA | D10: E407041 | E10: 70000 | F10: =+E10*40% -> 28000 | G10: =+E10*35% -> 24500 | H10: =+E10*25% -> 17500
A11: EPEC | D11: 1421037 / 0050866107 | E11: 362743.2 | F11: =+E11*40% -> 145097.28 | G11: =+E11*35% -> 126960.12 | H11: =+E11*25% -> 90685.8
A12: TOTAL | E12: =SUM(E4:E11) -> 2602593.3 | F12: =SUM(F4:F11) -> 1041037.3 | G12: =SUM(G4:G11) -> 910907.64 | H12: =SUM(H4:H11) -> 650648.31
A14: GASTO POR EMPRESA | C14: =+H2 -> MARZO | D14: Porcentaje
A15: GALARA | C15: =+F12 -> 1041037.3 | D15: 0.4
A16: JUAN PABLO | C16: =+G12 -> 910907.64 | D16: 0.35
A17: ENJOY | C17: =+H12 -> 650648.31 | D17: 0.25
A18: TOTALES | C18: =SUM(C15:C17) -> 2602593.3 | D18: =SUM(D15:D17) -> 1

Sheet ABRIL
A1: RENDICION DE GASTOS COWORKING | H1: MES: | I1: AÑO
H2: ABRIL | I2: 2026
A3: RUBROS | D3: GASTO | E3: GASTO | F3: GALARA (40%) | G3: JUAN PABLO (35%) | H3: ENJOY (25%) | I3: OBSERVACION
A4: ALQUILER | D4: Karina Vidal | E4: 1903178 | F4: =+E4*40% -> 761271.2 | G4: =+E4*35% -> 666112.3 | H4: =+E4*25% -> 475794.5 | I4: ** HASTA 30 de junio 2026
A5: MUNICIPALIDAD | D5: 031402504400000 | E5: 47792 | F5: =+E5*40% -> 19116.8 | G5: =+E5*35% -> 16727.2 | H5: =+E5*25% -> 11948
A6: RENTAS | D6: 110116241561 | E6: 129761.75 | F6: =+E6*40% -> 51904.7 | G6: =+E6*35% -> 45416.612 | H6: =+E6*25% -> 32440.438
A7: AGUA | D7: 285408 | E7: 151324.39 | F7: =+E7*40% -> 60529.756 | G7: =+E7*35% -> 52963.537 | H7: =+E7*25% -> 37831.098
A8: ECOGAS | D8: 21858193 | E8: 48884.58 | F8: =+E8*40% -> 19553.832 | G8: =+E8*35% -> 17109.603 | H8: =+E8*25% -> 12221.145
A9: WIFI -CLARO | D9: 21316865904 | E9: 48960.76 | F9: =+E9*40% -> 19584.304 | G9: =+E9*35% -> 17136.266 | H9: =+E9*25% -> 12240.19
A10: COBERTURA DE ÁREA PROTEGIDA | D10: E407041 | E10: 70000 | F10: =+E10*40% -> 28000 | G10: =+E10*35% -> 24500 | H10: =+E10*25% -> 17500
A11: EPEC | D11: 1421037 / 0050866107 | E11: 402442.6 | F11: =+E11*40% -> 160977.04 | G11: =+E11*35% -> 140854.91 | H11: =+E11*25% -> 100610.65
A12: TOTAL | E12: =SUM(E4:E11) -> 2802344.1 | F12: =SUM(F4:F11) -> 1120937.6 | G12: =SUM(G4:G11) -> 980820.43 | H12: =SUM(H4:H11) -> 700586.02
A14: GASTO POR EMPRESA | C14: =+H2 -> ABRIL | D14: Porcentaje
A15: GALARA | C15: =+F12 -> 1120937.6 | D15: 0.4
A16: JUAN PABLO | C16: =+G12 -> 980820.43 | D16: 0.35
A17: ENJOY | C17: =+H12 -> 700586.02 | D17: 0.25
A18: TOTALES | C18: =SUM(C15:C17) -> 2802344.1 | D18: =SUM(D15:D17) -> 1

Sheet MAYO
A1: RENDICION DE GASTOS COWORKING | H1: MES: | I1: AÑO
H2: MAYO | I2: 2026
A3: RUBROS | D3: GASTO | E3: GASTO | F3: GALARA (40%) | G3: JUAN PABLO (35%) | H3: ENJOY (25%) | I3: OBSERVACION
A4: ALQUILER | D4: Karina Vidal | E4: 1903178 | F4: =+E4*40% -> 761271.2 | G4: =+E4*35% -> 666112.3 | H4: =+E4*25% -> 475794.5 | I4: ** HASTA 30 de junio 2026
A5: MUNICIPALIDAD | D5: 031402504400000 | E5: 47792 | F5: =+E5*40% -> 19116.8 | G5: =+E5*35% -> 16727.2 | H5: =+E5*25% -> 11948
A6: RENTAS | D6: 110116241561 | E6: 129761.75 | F6: =+E6*40% -> 51904.7 | G6: =+E6*35% -> 45416.612 | H6: =+E6*25% -> 32440.438
A7: AGUA | D7: 285408 | E7: 162212.97 | F7: =+E7*40% -> 64885.188 | G7: =+E7*35% -> 56774.539 | H7: =+E7*25% -> 40553.243
A8: ECOGAS | D8: 21858193 | E8: 29702.17 | F8: =+E8*40% -> 11880.868 | G8: =+E8*35% -> 10395.759 | H8: =+E8*25% -> 7425.5425
A9: WIFI -CLARO | D9: 21316865904 | E9: 50417.63 | F9: =+E9*40% -> 20167.052 | G9: =+E9*35% -> 17646.17 | H9: =+E9*25% -> 12604.407
A10: COBERTURA DE ÁREA PROTEGIDA | D10: E407041 | E10: 70000 | F10: =+E10*40% -> 28000 | G10: =+E10*35% -> 24500 | H10: =+E10*25% -> 17500
A11: EPEC | D11: 1421037 / 0050866107 | E11: 408031.5 | F11: =+E11*40% -> 163212.6 | G11: =+E11*35% -> 142811.02 | H11: =+E11*25% -> 102007.88
A12: TOTAL | E12: =SUM(E4:E11) -> 2801096 | F12: =SUM(F4:F11) -> 1120438.4 | G12: =SUM(G4:G11) -> 980383.61 | H12: =SUM(H4:H11) -> 700274.01
A14: GASTO POR EMPRESA | C14: =+H2 -> MAYO | D14: Porcentaje
A15: GALARA | C15: =+F12 -> 1120438.4 | D15: 0.4
A16: JUAN PABLO | C16: =+G12 -> 980383.61 | D16: 0.35
A17: ENJOY | C17: =+H12 -> 700274.01 | D17: 0.25
A18: TOTALES | C18: =SUM(C15:C17) -> 2801096 | D18: =SUM(D15:D17) -> 1

Sheet JUNIO
A1: RENDICION DE GASTOS COWORKING | H1: MES: | I1: AÑO
H2: JUNIO | I2: 2026
A3: RUBROS | D3: GASTO | E3: GASTO | F3: GALARA (40%) | G3: JUAN PABLO (35%) | H3: ENJOY (25%) | I3: OBSERVACION
A4: ALQUILER | D4: Karina Vidal | E4: 1903178 | F4: =+E4*40% -> 761271.2 | G4: =+E4*35% -> 666112.3 | H4: =+E4*25% -> 475794.5 | I4: ** HASTA 30 de junio 2026
A5: MUNICIPALIDAD | D5: 031402504400000 | E5: 47792 | F5: =+E5*40% -> 19116.8 | G5: =+E5*35% -> 16727.2 | H5: =+E5*25% -> 11948
A6: RENTAS | D6: 110116241561 | E6: 90833.22 | F6: =+E6*40% -> 36333.288 | G6: =+E6*35% -> 31791.627 | H6: =+E6*25% -> 22708.305
A7: AGUA | D7: 285408 | E7: 163667.91 | F7: =+E7*40% -> 65467.164 | G7: =+E7*35% -> 57283.768 | H7: =+E7*25% -> 40916.978
A8: ECOGAS | D8: 21858193 | E8: 33889.61 | F8: =+E8*40% -> 13555.844 | G8: =+E8*35% -> 11861.363 | H8: =+E8*25% -> 8472.4025
A9: WIFI -CLARO | D9: 21316865904 | E9: 55000 | F9: =+E9*40% -> 22000 | G9: =+E9*35% -> 19250 | H9: =+E9*25% -> 13750
A10: COBERTURA DE ÁREA PROTEGIDA | D10: E407041 | E10: 70000 | F10: =+E10*40% -> 28000 | G10: =+E10*35% -> 24500 | H10: =+E10*25% -> 17500
A11: EPEC | D11: 1421037 / 0050866107 | E11: 450487.6 | F11: =+E11*40% -> 180195.04 | G11: =+E11*35% -> 157670.66 | H11: =+E11*25% -> 112621.9
A12: TOTAL | E12: =SUM(E4:E11) -> 2814848.3 | F12: =SUM(F4:F11) -> 1125939.3 | G12: =SUM(G4:G11) -> 985196.92 | H12: =SUM(H4:H11) -> 703712.08
A14: GASTO POR EMPRESA | C14: =+H2 -> JUNIO | D14: Porcentaje
A15: GALARA | C15: =+F12 -> 1125939.3 | D15: 0.4
A16: JUAN PABLO | C16: =+G12 -> 985196.92 | D16: 0.35
A17: ENJOY | C17: =+H12 -> 703712.08 | D17: 0.25
A18: TOTALES | C18: =SUM(C15:C17) -> 2814848.3 | D18: =SUM(D15:D17) -> 1

Sheet JULIO
A1: RENDICION DE GASTOS COWORKING | H1: MES: | I1: AÑO
H2: JULIO | I2: 2026
A3: RUBROS | D3: GASTO | E3: GASTO | F3: GALARA (40%) | G3: JUAN PABLO (35%) | H3: ENJOY (25%) | I3: OBSERVACION
A4: ALQUILER | D4: Karina Vidal | E4: 2036000 | F4: =+E4*40% -> 814400 | G4: =+E4*35% -> 712600 | H4: =+E4*25% -> 509000 | I4: ** HASTA 30 de septiembre 2026
A5: MUNICIPALIDAD | D5: 031402504400000 | E5: 54315 | F5: =+E5*40% -> 21726 | G5: =+E5*35% -> 19010.25 | H5: =+E5*25% -> 13578.75
A6: RENTAS | D6: 110116241561 | E6: 90833.22 | F6: =+E6*40% -> 36333.288 | G6: =+E6*35% -> 31791.627 | H6: =+E6*25% -> 22708.305
A7: AGUA | D7: 285408 | E7: 163667.91 | F7: =+E7*40% -> 65467.164 | G7: =+E7*35% -> 57283.768 | H7: =+E7*25% -> 40916.978
A8: ECOGAS | D8: 21858193 | E8: 50110.76 | F8: =+E8*40% -> 20044.304 | G8: =+E8*35% -> 17538.766 | H8: =+E8*25% -> 12527.69
A9: WIFI -CLARO | D9: 21316865904 | E9: 54192.23 | F9: =+E9*40% -> 21676.892 | G9: =+E9*35% -> 18967.281 | H9: =+E9*25% -> 13548.058
A10: COBERTURA DE ÁREA PROTEGIDA | D10: E407041 | E10: 72948.16 | F10: =+E10*40% -> 29179.264 | G10: =+E10*35% -> 25531.856 | H10: =+E10*25% -> 18237.04
A11: EPEC | D11: 1421037 / 0050866107 | E11: 319621 | F11: =+E11*40% -> 127848.4 | G11: =+E11*35% -> 111867.35 | H11: =+E11*25% -> 79905.25
A12: TOTAL | E12: =SUM(E4:E11) -> 2841688.3 | F12: =SUM(F4:F11) -> 1136675.3 | G12: =SUM(G4:G11) -> 994590.9 | H12: =SUM(H4:H11) -> 710422.07
A14: GASTO POR EMPRESA | C14: =+H2 -> JULIO | D14: Porcentaje
A15: GALARA | C15: =+F12 -> 1136675.3 | D15: 0.4
A16: JUAN PABLO | C16: =+G12 -> 994590.9 | D16: 0.35
A17: ENJOY | C17: =+H12 -> 710422.07 | D17: 0.25
A18: TOTALES | C18: =SUM(C15:C17) -> 2841688.3 | D18: =SUM(D15:D17) -> 1

Sheet AGOSTO
A1: RENDICION DE GASTOS COWORKING | H1: MES: | I1: AÑO
H2: AGOSTO | I2: 2026
A3: RUBROS | D3: GASTO | E3: GASTO | F3: GALARA (40%) | G3: JUAN PABLO (35%) | H3: ENJOY (25%) | I3: OBSERVACION
A4: ALQUILER | D4: Karina Vidal | E4: 2036000 | F4: =+E4*40% -> 814400 | G4: =+E4*35% -> 712600 | H4: =+E4*25% -> 509000 | I4: ** HASTA 30 de septiembre 2026
A5: MUNICIPALIDAD | D5: 031402504400000 | E5: 54315 | F5: =+E5*40% -> 21726 | G5: =+E5*35% -> 19010.25 | H5: =+E5*25% -> 13578.75
A6: RENTAS | D6: 110116241561 | E6: 90833.22 | F6: =+E6*40% -> 36333.288 | G6: =+E6*35% -> 31791.627 | H6: =+E6*25% -> 22708.305
A7: AGUA | D7: 285408 | E7: 176417.89 | F7: =+E7*40% -> 70567.156 | G7: =+E7*35% -> 61746.262 | H7: =+E7*25% -> 44104.473
A8: ECOGAS | D8: 21858193 | E8: 51054.34 | F8: =+E8*40% -> 20421.736 | G8: =+E8*35% -> 17869.019 | H8: =+E8*25% -> 12763.585
A9: WIFI -CLARO | D9: 21316865904 | E9: 56911.77 | F9: =+E9*40% -> 22764.708 | G9: =+E9*35% -> 19919.119 | H9: =+E9*25% -> 14227.942
A10: COBERTURA DE ÁREA PROTEGIDA | D10: E407041 | E10: 75000 | F10: =+E10*40% -> 30000 | G10: =+E10*35% -> 26250 | H10: =+E10*25% -> 18750
A11: EPEC | D11: 1421037 / 0050866107 | E11: 479036.6 | F11: =+E11*40% -> 191614.64 | G11: =+E11*35% -> 167662.81 | H11: =+E11*25% -> 119759.15
A12: TOTAL | E12: =SUM(E4:E11) -> 3019568.8 | F12: =SUM(F4:F11) -> 1207827.5 | G12: =SUM(G4:G11) -> 1056849.1 | H12: =SUM(H4:H11) -> 754892.21
A14: GASTO POR EMPRESA | C14: =+H2 -> AGOSTO | D14: Porcentaje
A15: GALARA | C15: =+F12 -> 1207827.5 | D15: 0.4
A16: JUAN PABLO | C16: =+G12 -> 1056849.1 | D16: 0.35
A17: ENJOY | C17: =+H12 -> 754892.21 | D17: 0.25
A18: TOTALES | C18: =SUM(C15:C17) -> 3019568.8 | D18: =SUM(D15:D17) -> 1

Sheet AJUSTES
A2: MES DE ENERO 2026
A3: EMPRESA | B3: % DE APORTE | C3: APORTE EN $ | D3: GALARA | E3: JUAN PABLO | F3: ENJOY | G3: APORTADO | H3: TOTAL
A4: GALARA | B4: 0.4 | C4: =+ENERO!F12 -> 1007437 | D4: =+C14 -> 29966.667 | H4: =SUM(C4:G4) -> 1037403.7
A5: JUAN PABLO | B5: 0.35 | C5: =+ENERO!G12 -> 881507.37 | E5: =+D14 -> 29966.667 | H5: =SUM(C5:G5) -> 911474.04
A6: ENJOY | B6: 0.25 | C6: =+ENERO!H12 -> 629648.12 | F6: =+E14 -> 29966.667 | G6: =-B12-B13 -> -89900 | H6: =SUM(C6:G6) -> 569714.79
B7: 1 | C7: =SUM(C4:C6) -> 2518592.5 | H7: =SUM(H4:H6) -> 2518592.5
A10: APORTE ENJOY
A11: DETALLE | B11: MONTO | C11: GALARA (33%) | D11: JUAN PABLO (33%) | E11: ENJOY (33%)
A12: LIMPIEZA | B12: 65600 | C12: =+B12/3 -> 21866.667 | D12: =+B12/3 -> 21866.667 | E12: =+B12/3 -> 21866.667
A13: SEGURIDAD ELECTRÓNICA | B13: 24300 | C13: =+B13/3 -> 8100 | D13: =+B13/3 -> 8100 | E13: =+B13/3 -> 8100
A14: TOTAL | B14: =SUM(B12:B13) -> 89900 | C14: =SUM(C12:C13) -> 29966.667 | D14: =SUM(D12:D13) -> 29966.667 | E14: =SUM(E12:E13) -> 29966.667
A16: GASTOS COWORKING DICIEMBRE 2025
A17: FECHA | B17: GASTO | C17: MONTO | D17: EMPRESA
A18: 46361 | B18: Limpieza | C18: 32800 | D18: Enjoy
A19: 46369 | B19: Limpieza | C19: 32800 | D19: Enjoy
B20: TOTAL | C20: =SUM(C18:C19) -> 65600
A22: MES DE FEBRERO 2026
A23: EMPRESA | B23: % DE APORTE | C23: APORTE EN $ | D23: GALARA | E23: JUAN PABLO | F23: ENJOY | G23: APORTADO | H23: TOTAL
A24: GALARA | B24: 0.4 | C24: =+FEBRERO!F12 -> 1034214.4 | D24: =+C34 -> 35766.667 | H24: =SUM(C24:G24) -> 1069981
A25: JUAN PABLO | B25: 0.35 | C25: =+FEBRERO!G12 -> 904937.56 | E25: =+D34 -> 35766.667 | H25: =SUM(C25:G25) -> 940704.23
A26: ENJOY | B26: 0.25 | C26: =+FEBRERO!H12 -> 646383.98 | F26: =+E34 -> 35766.667 | G26: =-B32-B33 -> -107300 | H26: =SUM(C26:G26) -> 574850.64
B27: 1 | C27: =SUM(C24:C26) -> 2585535.9 | H27: =SUM(H24:H26) -> 2585535.9
A30: APORTE ENJOY
A31: DETALLE | B31: MONTO | C31: GALARA (33%) | D31: JUAN PABLO (33%) | E31: ENJOY (33%)
A32: LIMPIEZA | B32: 83000 | C32: =+B32/3 -> 27666.667 | D32: =+B32/3 -> 27666.667 | E32: =+B32/3 -> 27666.667
A33: SEGURIDAD ELECTRÓNICA | B33: 24300 | C33: =+B33/3 -> 8100 | D33: =+B33/3 -> 8100 | E33: =+B33/3 -> 8100
A34: TOTAL | B34: =SUM(B32:B33) -> 107300 | C34: =SUM(C32:C33) -> 35766.667 | D34: =SUM(D32:D33) -> 35766.667 | E34: =SUM(E32:E33) -> 35766.667
A36: GASTOS COWORKING ENERO 2026
A37: FECHA | B37: GASTO | C37: MONTO | D37: EMPRESA
A38: 46035 | B38: Detergente, perfumina y lavandina | C38: 13600 | D38: Enjoy
A39: 46036 | B39: Limpieza Coworking | C39: 34800 | D39: Enjoy
A40: 46044 | B40: Limpieza Coworking | C40: 34600 | D40: Enjoy
B41: TOTAL | C41: =SUM(C38:C40) -> 83000
A43: MES DE MARZO 2026
A44: EMPRESA | B44: % DE APORTE | C44: APORTE EN $ | D44: GALARA | E44: JUAN PABLO | F44: ENJOY | G44: APORTADO | H44: TOTAL
A45: GALARA | B45: 0.4 | C45: =+MARZO!F12 -> 1041037.3 | D45: =+C57 -> 130966.67 | H45: =SUM(C45:G45) -> 1172004
A46: JUAN PABLO | B46: 0.35 | C46: =+MARZO!G12 -> 910907.64 | E46: =+D57 -> 130966.67 | G46: =-B55 -> -130000 | H46: =SUM(C46:G46) -> 911874.3
A47: ENJOY | B47: 0.25 | C47: =+MARZO!H12 -> 650648.31 | F47: =+E57 -> 130966.67 | G47: =-B53-B54-B56 -> -262900 | H47: =SUM(C47:G47) -> 518714.98
B48: 1 | C48: =SUM(C45:C47) -> 2602593.3 | H48: =SUM(H45:H47) -> 2602593.2
A51: APORTE ENJOY
...
