Workbook

Sheet PAÑOL TÉCNICO
A1: F | B1: PAÑOL TÉCNICO
A3: Codigo Producto | B3: Descripción | C3: Entradas | D3: Salidas | E3: Stock Actual | F3: Observación | G3: N° Pañol
A4: P-1 | B4: Alicate | C4: =IFERROR(SUMIF(ENTRADAS!A:A,A4,ENTRADAS!C:C)) -> 3 | D4: =SUMIF(SALIDAS!A:A,A4,SALIDAS!C:C) -> 0 | E4: =C4-D4 -> 3 | F4: 2 kempes,1 aleman no devolvio
A5: P-2 | B5: Arnes con cola de mono | C5: =IFERROR(SUMIF(ENTRADAS!A:A,A5,ENTRADAS!C:C)) -> 40 | D5: =SUMIF(SALIDAS!A:A,A5,SALIDAS!C:C) -> 0 | E5: =C5-D5 -> 40 | F5: 15 kempes, 3 fausto,14 depo
A6: P-3 | B6: Arnes sin cola de mono | C6: =IFERROR(SUMIF(ENTRADAS!A:A,A6,ENTRADAS!C:C)) -> 12 | D6: =SUMIF(SALIDAS!A:A,A6,SALIDAS!C:C) -> 0 | E6: =C6-D6 -> 12 | F6: 0
A7: P-4 | B7: Anteojo dual transparente Libus | C7: =IFERROR(SUMIF(ENTRADAS!A:A,A7,ENTRADAS!C:C)) -> 4 | D7: =SUMIF(SALIDAS!A:A,A7,SALIDAS!C:C) -> 1 | E7: =C7-D7 -> 3 | F7: 1
A8: P-5 | B8: Anteojo de protección | C8: =IFERROR(SUMIF(ENTRADAS!A:A,A8,ENTRADAS!C:C)) -> 7 | D8: =SUMIF(SALIDAS!A:A,A8,SALIDAS!C:C) -> 0 | E8: =C8-D8 -> 7 | F8: 63
A9: P-6 | B9: Atornilladora inalámbrica DeWalt (amarilla) | C9: =IFERROR(SUMIF(ENTRADAS!A:A,A9,ENTRADAS!C:C)) -> 5 | D9: =SUMIF(SALIDAS!A:A,A9,SALIDAS!C:C) -> 0 | E9: =C9-D9 -> 5 | F9: 2 depo, 2 kempes,1 fausto
A10: P-7 | B10: Atornilladora inalámbrica Hamilton (naranja) | C10: =IFERROR(SUMIF(ENTRADAS!A:A,A10,ENTRADAS!C:C)) -> 1 | D10: =SUMIF(SALIDAS!A:A,A10,SALIDAS!C:C) -> 0 | E10: =C10-D10 -> 1 | F10: 1
A11: P-8 | B11: Abrazadera p/tubo | C11: =IFERROR(SUMIF(ENTRADAS!A:A,A11,ENTRADAS!C:C)) -> 3 | D11: =SUMIF(SALIDAS!A:A,A11,SALIDAS!C:C) -> 0 | E11: =C11-D11 -> 3 | F11: 3
A12: P-9 | B12: Adaptador | C12: =IFERROR(SUMIF(ENTRADAS!A:A,A12,ENTRADAS!C:C)) -> 2 | D12: =SUMIF(SALIDAS!A:A,A12,SALIDAS!C:C) -> 0 | E12: =C12-D12 -> 2 | F12: 0
A13: P-10 | B13: Angulo para estantería | C13: =IFERROR(SUMIF(ENTRADAS!A:A,A13,ENTRADAS!C:C)) -> 6 | D13: =SUMIF(SALIDAS!A:A,A13,SALIDAS!C:C) -> 0 | E13: =C13-D13 -> 6 | F13: 6
A14: P-11 | B14: Arandela | C14: =IFERROR(SUMIF(ENTRADAS!A:A,A14,ENTRADAS!C:C)) -> 530 | D14: =SUMIF(SALIDAS!A:A,A14,SALIDAS!C:C) -> 0 | E14: =C14-D14 -> 530
A15: P-12 | B15: Arandela grande | C15: =IFERROR(SUMIF(ENTRADAS!A:A,A15,ENTRADAS!C:C)) -> 206 | D15: =SUMIF(SALIDAS!A:A,A15,SALIDAS!C:C) -> 0 | E15: =C15-D15 -> 206
A16: P-13 | B16: Aspiradora pequeña | C16: =IFERROR(SUMIF(ENTRADAS!A:A,A16,ENTRADAS!C:C)) -> 1 | D16: =SUMIF(SALIDAS!A:A,A16,SALIDAS!C:C) -> 0 | E16: =C16-D16 -> 1 | F16: 1
A17: P-14 | B17: Bandera argentina | C17: =IFERROR(SUMIF(ENTRADAS!A:A,A17,ENTRADAS!C:C)) -> 18 | D17: =SUMIF(SALIDAS!A:A,A17,SALIDAS!C:C) -> 0 | E17: =C17-D17 -> 18
A18: P-15 | B18: Bidon vacío cortado | C18: =IFERROR(SUMIF(ENTRADAS!A:A,A18,ENTRADAS!C:C)) -> 3 | D18: =SUMIF(SALIDAS!A:A,A18,SALIDAS!C:C) -> 0 | E18: =C18-D18 -> 3 | F18: 1
A19: P-16 | B19: Batería ultimate 12V 1.5 AMP Hamilton (Máquina chica) | C19: =IFERROR(SUMIF(ENTRADAS!A:A,A19,ENTRADAS!C:C)) -> 1 | D19: =SUMIF(SALIDAS!A:A,A19,SALIDAS!C:C) -> 0 | E19: =C19-D19 -> 1 | F19: 2
A20: P-17 | B20: Bidon vacío sin cortar | C20: =IFERROR(SUMIF(ENTRADAS!A:A,A20,ENTRADAS!C:C)) -> 7 | D20: =SUMIF(SALIDAS!A:A,A20,SALIDAS!C:C) -> 0 | E20: =C20-D20 -> 7 | F20: 7
A21: P-18 | B21: Bolsa de tornillos autoperforante punta fisher 8x12" x 400u | C21: =IFERROR(SUMIF(ENTRADAS!A:A,A21,ENTRADAS!C:C)) -> 2 | D21: =SUMIF(SALIDAS!A:A,A21,SALIDAS!C:C) -> 0 | E21: =C21-D21 -> 2
A22: P-19 | B22: Bolsa de tornillos autoperforante punta fisher x 250u | C22: =IFERROR(SUMIF(ENTRADAS!A:A,A22,ENTRADAS!C:C)) -> 3 | D22: =SUMIF(SALIDAS!A:A,A22,SALIDAS!C:C) -> 0 | E22: =C22-D22 -> 3
A23: P-20 | B23: Bomba centrífuga | C23: =IFERROR(SUMIF(ENTRADAS!A:A,A23,ENTRADAS!C:C)) -> 1 | D23: =SUMIF(SALIDAS!A:A,A23,SALIDAS!C:C) -> 0 | E23: =C23-D23 -> 1
A24: P-21 | B24: Par de botas de lluvia | C24: =IFERROR(SUMIF(ENTRADAS!A:A,A24,ENTRADAS!C:C)) -> 11 | D24: =SUMIF(SALIDAS!A:A,A24,SALIDAS!C:C) -> 0 | E24: =C24-D24 -> 11 | F24: 11
A25: P-22 | B25: Bulón de techo | C25: =IFERROR(SUMIF(ENTRADAS!A:A,A25,ENTRADAS!C:C)) -> 61 | D25: =SUMIF(SALIDAS!A:A,A25,SALIDAS!C:C) -> 0 | E25: =C25-D25 -> 61
A26: P-23 | B26: Bulones de techo de tramo | C26: =IFERROR(SUMIF(ENTRADAS!A:A,A26,ENTRADAS!C:C)) -> 275 | D26: =SUMIF(SALIDAS!A:A,A26,SALIDAS!C:C) -> 0 | E26: =C26-D26 -> 275
A27: P-24 | B27: Bulones de techo de tramo pequeños | C27: =IFERROR(SUMIF(ENTRADAS!A:A,A27,ENTRADAS!C:C)) -> 101 | D27: =SUMIF(SALIDAS!A:A,A27,SALIDAS!C:C) -> 0 | E27: =C27-D27 -> 101
A28: P-25 | B28: Bulón grande de unión para techo | C28: =IFERROR(SUMIF(ENTRADAS!A:A,A28,ENTRADAS!C:C)) -> 2 | D28: =SUMIF(SALIDAS!A:A,A28,SALIDAS!C:C) -> 0 | E28: =C28-D28 -> 2
A29: P-26 | B29: Bulón de unión para techo | C29: =IFERROR(SUMIF(ENTRADAS!A:A,A29,ENTRADAS!C:C)) -> 71 | D29: =SUMIF(SALIDAS!A:A,A29,SALIDAS!C:C) -> 0 | E29: =C29-D29 -> 71
A30: P-27 | B30: Cable puente para batería reforzado (Taos) | C30: =IFERROR(SUMIF(ENTRADAS!A:A,A30,ENTRADAS!C:C)) -> 4 | D30: =SUMIF(SALIDAS!A:A,A30,SALIDAS!C:C) -> 0 | E30: =C30-D30 -> 4 | F30: 3 Y 1 TALLER MEC
A31: P-28 | B31: Chaleco refractario | C31: =IFERROR(SUMIF(ENTRADAS!A:A,A31,ENTRADAS!C:C)) -> 13 | D31: =SUMIF(SALIDAS!A:A,A31,SALIDAS!C:C) -> 0 | E31: =C31-D31 -> 13 | F31: 13 kempes
A32: P-29 | B32: Cable acerado | C32: =IFERROR(SUMIF(ENTRADAS!A:A,A32,ENTRADAS!C:C)) -> 1 | D32: =SUMIF(SALIDAS!A:A,A32,SALIDAS!C:C) -> 0 | E32: =C32-D32 -> 1
A33: P-30 | B33: Cargador de batería ultimate 12v Hamilton (Máquina chica) | C33: =IFERROR(SUMIF(ENTRADAS!A:A,A33,ENTRADAS!C:C)) -> 1 | D33: =SUMIF(SALIDAS!A:A,A33,SALIDAS!C:C) -> 0 | E33: =C33-D33 -> 1 | F33: 1
A34: P-31 | B34: Cadena | C34: =IFERROR(SUMIF(ENTRADAS!A:A,A34,ENTRADAS!C:C)) -> 8 | D34: =SUMIF(SALIDAS!A:A,A34,SALIDAS!C:C) -> 0 | E34: =C34-D34 -> 8
A35: P-32 | B35: Cinta métrica 50mts (fibra de vidrio) | C35: =IFERROR(SUMIF(ENTRADAS!A:A,A35,ENTRADAS!C:C)) -> 3 | D35: =SUMIF(SALIDAS!A:A,A35,SALIDAS!C:C) -> 0 | E35: =C35-D35 -> 3 | F35: 4
A36: P-33 | B36: Caja de herrramientas para autolevador | C36: =IFERROR(SUMIF(ENTRADAS!A:A,A36,ENTRADAS!C:C)) -> 3 | D36: =SUMIF(SALIDAS!A:A,A36,SALIDAS!C:C) -> 0 | E36: =C36-D36 -> 3
A37: P-34 | B37: Casco de Altura | C37: =IFERROR(SUMIF(ENTRADAS!A:A,A37,ENTRADAS!C:C)) -> 36 | D37: =SUMIF(SALIDAS!A:A,A37,SALIDAS!C:C) -> 0 | E37: =C37-D37 -> 36 | F37: 20 DEPO,3 FAUS,20 KEMPES
A38: P-35 | B38: Casco de Obra/Piso | C38: =IFERROR(SUMIF(ENTRADAS!A:A,A38,ENTRADAS!C:C)) -> 49 | D38: =SUMIF(SALIDAS!A:A,A38,SALIDAS!C:C) -> 0 | E38: =C38-D38 -> 49
A39: P-36 | B39: Curva de techo de layher | C39: =IFERROR(SUMIF(ENTRADAS!A:A,A39,ENTRADAS!C:C)) -> 6 | D39: =SUMIF(SALIDAS!A:A,A39,SALIDAS!C:C) -> 0 | E39: =C39-D39 -> 6
A40: P-37 | B40: Cono naranja | C40: =IFERROR(SUMIF(ENTRADAS!A:A,A40,ENTRADAS!C:C)) -> 2 | D40: =SUMIF(SALIDAS!A:A,A40,SALIDAS!C:C) -> 0 | E40: =C40-D40 -> 2
A41: P-38 | B41: Cinta larga | C41: =IFERROR(SUMIF(ENTRADAS!A:A,A41,ENTRADAS!C:C)) -> 2 | D41: =SUMIF(SALIDAS!A:A,A41,SALIDAS!C:C) -> 0 | E41: =C41-D41 -> 2
...

Sheet ENTRADAS
A1: Z | B1: ENTRADAS
A3: Código | B3: Descripción | C3: Cantidad | D3: Observación | E3: N° Pañol
A4: P-1 | B4: =IFERROR(VLOOKUP(A4,'PAÑOL TÉCNICO'!A4:B1000,2,0)) -> Alicate | C4: 3
A5: P-2 | B5: =IFERROR(VLOOKUP(A5,'PAÑOL TÉCNICO'!A5:B1000,2,0)) -> Arnes con cola de mono | C5: 40
A6: P-3 | B6: =IFERROR(VLOOKUP(A6,'PAÑOL TÉCNICO'!A6:B1000,2,0)) -> Arnes sin cola de mono | C6: 12
A7: P-4 | B7: =IFERROR(VLOOKUP(A7,'PAÑOL TÉCNICO'!A7:B1000,2,0)) -> Anteojo dual transparente Libus | C7: 4
A8: P-5 | B8: =IFERROR(VLOOKUP(A8,'PAÑOL TÉCNICO'!A8:B1000,2,0)) -> Anteojo de protección | C8: 7
A9: P-6 | B9: =IFERROR(VLOOKUP(A9,'PAÑOL TÉCNICO'!A9:B1000,2,0)) -> Atornilladora inalámbrica DeWalt (amarilla) | C9: 5
A10: P-7 | B10: =IFERROR(VLOOKUP(A10,'PAÑOL TÉCNICO'!A10:B1000,2,0)) -> Atornilladora inalámbrica Hamilton (naranja) | C10: 1
A11: P-8 | B11: =IFERROR(VLOOKUP(A11,'PAÑOL TÉCNICO'!A11:B1000,2,0)) -> Abrazadera p/tubo | C11: 3
A12: P-9 | B12: =IFERROR(VLOOKUP(A12,'PAÑOL TÉCNICO'!A12:B1000,2,0)) -> Adaptador | C12: 2
A13: P-10 | B13: =IFERROR(VLOOKUP(A13,'PAÑOL TÉCNICO'!A13:B1000,2,0)) -> Angulo para estantería | C13: 6
A14: P-11 | B14: =IFERROR(VLOOKUP(A14,'PAÑOL TÉCNICO'!A14:B1000,2,0)) -> Arandela | C14: 530
A15: P-12 | B15: =IFERROR(VLOOKUP(A15,'PAÑOL TÉCNICO'!A15:B1000,2,0)) -> Arandela grande | C15: 206
A16: P-13 | B16: =IFERROR(VLOOKUP(A16,'PAÑOL TÉCNICO'!A16:B1000,2,0)) -> Aspiradora pequeña | C16: 1
A17: P-14 | B17: =IFERROR(VLOOKUP(A17,'PAÑOL TÉCNICO'!A17:B1000,2,0)) -> Bandera argentina | C17: 18
A18: P-15 | B18: =IFERROR(VLOOKUP(A18,'PAÑOL TÉCNICO'!A18:B1000,2,0)) -> Bidon vacío cortado | C18: 3
A19: P-16 | B19: =IFERROR(VLOOKUP(A19,'PAÑOL TÉCNICO'!A19:B1000,2,0)) -> Batería ultimate 12V 1.5 AMP Hamilton (Máquina chica) | C19: 1
A20: P-17 | B20: =IFERROR(VLOOKUP(A20,'PAÑOL TÉCNICO'!A20:B1000,2,0)) -> Bidon vacío sin cortar | C20: 7
A21: P-18 | B21: =IFERROR(VLOOKUP(A21,'PAÑOL TÉCNICO'!A21:B1000,2,0)) -> Bolsa de tornillos autoperforante punta fisher 8x12" x 400u | C21: 2
A22: P-19 | B22: =IFERROR(VLOOKUP(A22,'PAÑOL TÉCNICO'!A22:B1000,2,0)) -> Bolsa de tornillos autoperforante punta fisher x 250u | C22: 3
A23: P-20 | B23: =IFERROR(VLOOKUP(A23,'PAÑOL TÉCNICO'!A23:B1000,2,0)) -> Bomba centrífuga | C23: 1
A24: P-21 | B24: =IFERROR(VLOOKUP(A24,'PAÑOL TÉCNICO'!A24:B1000,2,0)) -> Par de botas de lluvia | C24: 11
A25: P-22 | B25: =IFERROR(VLOOKUP(A25,'PAÑOL TÉCNICO'!A25:B1000,2,0)) -> Bulón de techo | C25: 61
A26: P-23 | B26: =IFERROR(VLOOKUP(A26,'PAÑOL TÉCNICO'!A26:B1000,2,0)) -> Bulones de techo de tramo | C26: 275
A27: P-24 | B27: =IFERROR(VLOOKUP(A27,'PAÑOL TÉCNICO'!A27:B1000,2,0)) -> Bulones de techo de tramo pequeños | C27: 101
A28: P-25 | B28: =IFERROR(VLOOKUP(A28,'PAÑOL TÉCNICO'!A28:B1000,2,0)) -> Bulón grande de unión para techo | C28: 2
A29: P-26 | B29: =IFERROR(VLOOKUP(A29,'PAÑOL TÉCNICO'!A29:B1000,2,0)) -> Bulón de unión para techo | C29: 71
A30: P-27 | B30: =IFERROR(VLOOKUP(A30,'PAÑOL TÉCNICO'!A30:B1000,2,0)) -> Cable puente para batería reforzado (Taos) | C30: 4
A31: P-28 | B31: =IFERROR(VLOOKUP(A31,'PAÑOL TÉCNICO'!A31:B1000,2,0)) -> Chaleco refractario | C31: 13
A32: P-29 | B32: =IFERROR(VLOOKUP(A32,'PAÑOL TÉCNICO'!A32:B1000,2,0)) -> Cable acerado | C32: 1
A33: P-30 | B33: =IFERROR(VLOOKUP(A33,'PAÑOL TÉCNICO'!A33:B1000,2,0)) -> Cargador de batería ultimate 12v Hamilton (Máquina chica) | C33: 1
A34: P-31 | B34: =IFERROR(VLOOKUP(A34,'PAÑOL TÉCNICO'!A34:B1000,2,0)) -> Cadena | C34: 8
A35: P-32 | B35: =IFERROR(VLOOKUP(A35,'PAÑOL TÉCNICO'!A35:B1000,2,0)) -> Cinta métrica 50mts (fibra de vidrio) | C35: 3
A36: P-33 | B36: =IFERROR(VLOOKUP(A36,'PAÑOL TÉCNICO'!A36:B1000,2,0)) -> Caja de herrramientas para autolevador | C36: 3
A37: P-34 | B37: =IFERROR(VLOOKUP(A37,'PAÑOL TÉCNICO'!A37:B1000,2,0)) -> Casco de Altura | C37: 36
A38: P-35 | B38: =IFERROR(VLOOKUP(A38,'PAÑOL TÉCNICO'!A38:B1000,2,0)) -> Casco de Obra/Piso | C38: 49
A39: P-36 | B39: =IFERROR(VLOOKUP(A39,'PAÑOL TÉCNICO'!A39:B1000,2,0)) -> Curva de techo de layher | C39: 6
A40: P-37 | B40: =IFERROR(VLOOKUP(A40,'PAÑOL TÉCNICO'!A40:B1000,2,0)) -> Cono naranja | C40: 2
A41: P-38 | B41: =IFERROR(VLOOKUP(A41,'PAÑOL TÉCNICO'!A41:B1000,2,0)) -> Cinta larga | C41: 2
...

Sheet SALIDAS
B1: SALIDAS
A3: Código | B3: Descripción | C3: Cantidad | D3: Observación | E3: N° Pañol
A4: P-1 | B4: =IFERROR(VLOOKUP(A4,'PAÑOL TÉCNICO'!A4:B1000,2,0)) -> Alicate | C4: =SUMIF(DIARIOS!D:D,A4,DIARIOS!F:F) -> 0
A5: P-2 | B5: =IFERROR(VLOOKUP(A5,'PAÑOL TÉCNICO'!A5:B1000,2,0)) -> Arnes con cola de mono | C5: =SUMIF(DIARIOS!D:D,A5,DIARIOS!F:F) -> 0
A6: P-3 | B6: =IFERROR(VLOOKUP(A6,'PAÑOL TÉCNICO'!A6:B1000,2,0)) -> Arnes sin cola de mono | C6: =SUMIF(DIARIOS!D:D,A6,DIARIOS!F:F) -> 0
A7: P-4 | B7: =IFERROR(VLOOKUP(A7,'PAÑOL TÉCNICO'!A7:B1000,2,0)) -> Anteojo dual transparente Libus | C7: =SUMIF(DIARIOS!D:D,A7,DIARIOS!F:F) -> 1
A8: P-5 | B8: =IFERROR(VLOOKUP(A8,'PAÑOL TÉCNICO'!A8:B1000,2,0)) -> Anteojo de protección | C8: =SUMIF(DIARIOS!D:D,A8,DIARIOS!F:F) -> 0
A9: P-6 | B9: =IFERROR(VLOOKUP(A9,'PAÑOL TÉCNICO'!A9:B1000,2,0)) -> Atornilladora inalámbrica DeWalt (amarilla) | C9: =SUMIF(DIARIOS!D:D,A9,DIARIOS!F:F) -> 0
A10: P-7 | B10: =IFERROR(VLOOKUP(A10,'PAÑOL TÉCNICO'!A10:B1000,2,0)) -> Atornilladora inalámbrica Hamilton (naranja) | C10: =SUMIF(DIARIOS!D:D,A10,DIARIOS!F:F) -> 0
A11: P-8 | B11: =IFERROR(VLOOKUP(A11,'PAÑOL TÉCNICO'!A11:B1000,2,0)) -> Abrazadera p/tubo | C11: =SUMIF(DIARIOS!D:D,A11,DIARIOS!F:F) -> 0
A12: P-9 | B12: =IFERROR(VLOOKUP(A12,'PAÑOL TÉCNICO'!A12:B1000,2,0)) -> Adaptador | C12: =SUMIF(DIARIOS!D:D,A12,DIARIOS!F:F) -> 0
A13: P-10 | B13: =IFERROR(VLOOKUP(A13,'PAÑOL TÉCNICO'!A13:B1000,2,0)) -> Angulo para estantería | C13: =SUMIF(DIARIOS!D:D,A13,DIARIOS!F:F) -> 0
A14: P-11 | B14: =IFERROR(VLOOKUP(A14,'PAÑOL TÉCNICO'!A14:B1000,2,0)) -> Arandela | C14: =SUMIF(DIARIOS!D:D,A14,DIARIOS!F:F) -> 0
A15: P-12 | B15: =IFERROR(VLOOKUP(A15,'PAÑOL TÉCNICO'!A15:B1000,2,0)) -> Arandela grande | C15: =SUMIF(DIARIOS!D:D,A15,DIARIOS!F:F) -> 0
A16: P-13 | B16: =IFERROR(VLOOKUP(A16,'PAÑOL TÉCNICO'!A16:B1000,2,0)) -> Aspiradora pequeña | C16: =SUMIF(DIARIOS!D:D,A16,DIARIOS!F:F) -> 0
A17: P-14 | B17: =IFERROR(VLOOKUP(A17,'PAÑOL TÉCNICO'!A17:B1000,2,0)) -> Bandera argentina | C17: =SUMIF(DIARIOS!D:D,A17,DIARIOS!F:F) -> 0
A18: P-15 | B18: =IFERROR(VLOOKUP(A18,'PAÑOL TÉCNICO'!A18:B1000,2,0)) -> Bidon vacío cortado | C18: =SUMIF(DIARIOS!D:D,A18,DIARIOS!F:F) -> 0
A19: P-16 | B19: =IFERROR(VLOOKUP(A19,'PAÑOL TÉCNICO'!A19:B1000,2,0)) -> Batería ultimate 12V 1.5 AMP Hamilton (Máquina chica) | C19: =SUMIF(DIARIOS!D:D,A19,DIARIOS!F:F) -> 0
A20: P-17 | B20: =IFERROR(VLOOKUP(A20,'PAÑOL TÉCNICO'!A20:B1000,2,0)) -> Bidon vacío sin cortar | C20: =SUMIF(DIARIOS!D:D,A20,DIARIOS!F:F) -> 0
A21: P-18 | B21: =IFERROR(VLOOKUP(A21,'PAÑOL TÉCNICO'!A21:B1000,2,0)) -> Bolsa de tornillos autoperforante punta fisher 8x12" x 400u | C21: =SUMIF(DIARIOS!D:D,A21,DIARIOS!F:F) -> 0
A22: P-19 | B22: =IFERROR(VLOOKUP(A22,'PAÑOL TÉCNICO'!A22:B1000,2,0)) -> Bolsa de tornillos autoperforante punta fisher x 250u | C22: =SUMIF(DIARIOS!D:D,A22,DIARIOS!F:F) -> 0
A23: P-20 | B23: =IFERROR(VLOOKUP(A23,'PAÑOL TÉCNICO'!A23:B1000,2,0)) -> Bomba centrífuga | C23: =SUMIF(DIARIOS!D:D,A23,DIARIOS!F:F) -> 0
A24: P-21 | B24: =IFERROR(VLOOKUP(A24,'PAÑOL TÉCNICO'!A24:B1000,2,0)) -> Par de botas de lluvia | C24: =SUMIF(DIARIOS!D:D,A24,DIARIOS!F:F) -> 0
A25: P-22 | B25: =IFERROR(VLOOKUP(A25,'PAÑOL TÉCNICO'!A25:B1000,2,0)) -> Bulón de techo | C25: =SUMIF(DIARIOS!D:D,A25,DIARIOS!F:F) -> 0
A26: P-23 | B26: =IFERROR(VLOOKUP(A26,'PAÑOL TÉCNICO'!A26:B1000,2,0)) -> Bulones de techo de tramo | C26: =SUMIF(DIARIOS!D:D,A26,DIARIOS!F:F) -> 0
A27: P-24 | B27: =IFERROR(VLOOKUP(A27,'PAÑOL TÉCNICO'!A27:B1000,2,0)) -> Bulones de techo de tramo pequeños | C27: =SUMIF(DIARIOS!D:D,A27,DIARIOS!F:F) -> 0
A28: P-25 | B28: =IFERROR(VLOOKUP(A28,'PAÑOL TÉCNICO'!A28:B1000,2,0)) -> Bulón grande de unión para techo | C28: =SUMIF(DIARIOS!D:D,A28,DIARIOS!F:F) -> 0
A29: P-26 | B29: =IFERROR(VLOOKUP(A29,'PAÑOL TÉCNICO'!A29:B1000,2,0)) -> Bulón de unión para techo | C29: =SUMIF(DIARIOS!D:D,A29,DIARIOS!F:F) -> 0
A30: P-27 | B30: =IFERROR(VLOOKUP(A30,'PAÑOL TÉCNICO'!A30:B1000,2,0)) -> Cable puente para batería reforzado (Taos) | C30: =SUMIF(DIARIOS!D:D,A30,DIARIOS!F:F) -> 0
A31: P-28 | B31: =IFERROR(VLOOKUP(A31,'PAÑOL TÉCNICO'!A31:B1000,2,0)) -> Chaleco refractario | C31: =SUMIF(DIARIOS!D:D,A31,DIARIOS!F:F) -> 0
A32: P-29 | B32: =IFERROR(VLOOKUP(A32,'PAÑOL TÉCNICO'!A32:B1000,2,0)) -> Cable acerado | C32: =SUMIF(DIARIOS!D:D,A32,DIARIOS!F:F) -> 0
A33: P-30 | B33: =IFERROR(VLOOKUP(A33,'PAÑOL TÉCNICO'!A33:B1000,2,0)) -> Cargador de batería ultimate 12v Hamilton (Máquina chica) | C33: =SUMIF(DIARIOS!D:D,A33,DIARIOS!F:F) -> 0
A34: P-31 | B34: =IFERROR(VLOOKUP(A34,'PAÑOL TÉCNICO'!A34:B1000,2,0)) -> Cadena | C34: =SUMIF(DIARIOS!D:D,A34,DIARIOS!F:F) -> 0
A35: P-32 | B35: =IFERROR(VLOOKUP(A35,'PAÑOL TÉCNICO'!A35:B1000,2,0)) -> Cinta métrica 50mts (fibra de vidrio) | C35: =SUMIF(DIARIOS!D:D,A35,DIARIOS!F:F) -> 0
A36: P-33 | B36: =IFERROR(VLOOKUP(A36,'PAÑOL TÉCNICO'!A36:B1000,2,0)) -> Caja de herrramientas para autolevador | C36: =SUMIF(DIARIOS!D:D,A36,DIARIOS!F:F) -> 0
A37: P-34 | B37: =IFERROR(VLOOKUP(A37,'PAÑOL TÉCNICO'!A37:B1000,2,0)) -> Casco de Altura | C37: =SUMIF(DIARIOS!D:D,A37,DIARIOS!F:F) -> 0
A38: P-35 | B38: =IFERROR(VLOOKUP(A38,'PAÑOL TÉCNICO'!A38:B1000,2,0)) -> Casco de Obra/Piso | C38: =SUMIF(DIARIOS!D:D,A38,DIARIOS!F:F) -> 0
A39: P-36 | B39: =IFERROR(VLOOKUP(A39,'PAÑOL TÉCNICO'!A39:B1000,2,0)) -> Curva de techo de layher | C39: =SUMIF(DIARIOS!D:D,A39,DIARIOS!F:F) -> 0
A40: P-37 | B40: =IFERROR(VLOOKUP(A40,'PAÑOL TÉCNICO'!A40:B1000,2,0)) -> Cono naranja | C40: =SUMIF(DIARIOS!D:D,A40,DIARIOS!F:F) -> 0
A41: P-38 | B41: =IFERROR(VLOOKUP(A41,'PAÑOL TÉCNICO'!A41:B1000,2,0)) -> Cinta larga | C41: =SUMIF(DIARIOS!D:D,A41,DIARIOS!F:F) -> 0
...

Sheet DIARIOS
A1: CDF | B1: DIARIO
A3: Fecha de retiro | B3: Responsable | C3: Retirado por | D3: Codigo Producto | E3: Descripción | F3: Cant | G3: Destino | H3: Fecha de devolución | I3: Observación
A4: 45138 | B4: Furia | C4: Furia | D4: P-6 | E4: =IFERROR(VLOOKUP(D4,'PAÑOL TÉCNICO'!A4:B1000,2,0)) -> Atornilladora inalámbrica DeWalt (amarilla) | F4: 0 | G4: Jesús María | H4: 45148
A5: 45138 | B5: Furia | C5: Furia | D5: P-205 | E5: Soga con gancho (23mts) (Rafa) | F5: 0 | G5: Jesús María | H5: 45148
A6: 45138 | B6: Furia | C6: Furia | D6: P-206 | E6: Soga con gancho (25mts) (Rafa) | F6: 0 | G6: Jesús María | H6: 45148
A7: 45138 | B7: Furia | C7: Furia | D7: P-35 | E7: Casco de Obra/Piso | F7: 0 | G7: Jesús María | H7: 45148
A8: 45138 | B8: Furia | C8: Furia | D8: P-149 | E8: Rachet 3mts. | F8: 0 | G8: Jesús María | H8: 45146
A9: 45138 | B9: Furia | C9: Furia | D9: P-150 | E9: Rachet 1mts. | F9: 0 | G9: Jesús María | H9: 45146
A10: 45138 | B10: Furia | C10: Furia | D10: P-207 | E10: Conservadora roja | F10: 0 | G10: Jesús María | H10: 45146
A11: 45138 | B11: Furia | C11: Furia | D11: P-32 | E11: Cinta métrica 50mts (fibra de vidrio) | F11: 0 | G11: Jesús María | H11: LA TIENE MARIO
A12: 45138 | B12: Furia | C12: Furia | D12: P-49 | E12: Colita de chancho | F12: 0 | G12: Jesús María
A13: 45139 | B13: Furia | C13: Furia | D13: P-148 | E13: Rachet 9mts. | F13: 0 | G13: Jesús María | H13: 45148
A14: 45141 | B14: Furia | C14: Furia | D14: P-166 | E14: Sierra circular | F14: 0 | G14: Jesús María | H14: 45145
A15: 45141 | B15: Furia | C15: Furia | D15: P-129 | E15: Prolongación 20mts | F15: 0 | G15: Jesús María | H15: 45145
A16: 45141 | B16: Furia | C16: Furia | D16: P-150 | E16: Rachet 1mts. | F16: 0 | G16: Jesús María | H16: 45148
A17: 45141 | B17: Furia | C17: Furia | D17: P-34 | E17: Casco de Altura | F17: 0 | G17: Jesús María | H17: 45148
A18: 45141 | B18: Furia | C18: Furia | D18: P-2 | E18: Arnes con cola de mono | F18: 0 | G18: Jesús María | H18: 45148
A19: 45141 | B19: Furia | C19: Furia | D19: P-175 | E19: Sogin negro | F19: 0 | G19: Jesús María
A20: 45141 | B20: Furia | C20: Furia | D20: P-149 | E20: Rachet 3mts. | F20: 0 | G20: Jesús María | H20: 45148
A21: 45142 | B21: Furia | C21: Furia | D21: P-150 | E21: Rachet 1mts. | F21: 0 | G21: Jesús María | H21: 45145
A22: 45142 | B22: Furia | C22: Furia | D22: P-148 | E22: Rachet 9mts. | F22: 0 | G22: Jesús María | H22: 45148
A23: 45142 | B23: Furia | C23: Furia | D23: P-177 | E23: Soga | F23: 0 | G23: Jesús María | H23: 45148
A24: 45142 | B24: Furia | C24: Furia | D24: P-119 | E24: Nivel de mano regular | F24: 0 | G24: Jesús María
A25: 45142 | B25: Furia | C25: Furia | D25: P-100 | E25: Masa p/estaca de 1mts (naranja) | F25: 0 | G25: Jesús María | H25: 45145
A26: 45142 | B26: Furia | C26: Furia | D26: P-225 | E26: Tubo 17 | F26: 0 | G26: Jesús María | H26: 45148
A27: 45142 | B27: Furia | C27: Furia | D27: P-191 | E27: Tornillo autoperforante cabeza philip (suelto) | F27: 30 | G27: Jesús María | H27: 45148
A28: 45142 | B28: Furia | C28: Furia | D28: P-27 | E28: Cable puente para batería reforzado (Taos) | F28: 0 | G28: Jesús María | H28: 45145
A29: 45142 | B29: Furia | C29: Furia | D29: P-121 | E29: Nudo con pin | F29: 0 | G29: Jesús María | H29: 45146
A30: 45145 | B30: Furia | C30: Furia | D30: P-34 | E30: Casco de altura | F30: 0 | G30: Jesús María | H30: 45148
A31: 45145 | B31: Furia | C31: Furia | D31: P-3 | E31: Arnes sin cola de mono | F31: 0 | G31: Jesús María | H31: 45148
A32: 45141 | B32: Mario López + Veck Salerno | C32: Mario López + Veck Salerno | D32: P-2 | E32: Arnes con cola de mono | F32: 0 | G32: Kempes | I32: FALTA UNA COLA DE MONO
A33: 45141 | B33: Mario López + Veck Salerno | C33: Mario López + Veck Salerno | D33: P-34 | E33: Casco de altura | F33: 0 | G33: Kempes
A34: 45141 | B34: Mario López + Veck Salerno | C34: Mario López + Veck Salerno | D34: P-149 | E34: Rachet 3mts. | F34: 0 | G34: Kempes | H34: 45148
A35: 45142 | B35: Mario López + Veck Salerno | C35: Mario López + Veck Salerno | D35: P-189 | E35: Tenaza | F35: 0 | G35: Kempes | H35: 45145
A36: 45141 | B36: Mario López + Veck Salerno | C36: Mario López + Veck Salerno | D36: P-6 | E36: Atornilladora inalámbrica DeWalt (amarilla) | F36: 0 | G36: Kempes | H36: 45148
A37: 45142 | B37: Mario López + Veck Salerno | C37: Mario López + Veck Salerno | D37: P-43 | E37: Cutter | F37: 0 | G37: Kempes | H37: 45145
A38: 45142 | B38: Mario López + Veck Salerno | C38: Mario López + Veck Salerno | D38: P-148 | E38: Rachet 9mts. | F38: 0 | G38: Kempes | H38: 45148
A39: 45142 | B39: Mario López + Veck Salerno | C39: Mario López + Veck Salerno | D39: P-46 | E39: Caja de herramientas | F39: 0 | G39: Kempes | H39: 45148
A40: 45142 | B40: Mario López + Veck Salerno | C40: Mario López + Veck Salerno | D40: P-71 | E40: Gazebo completo | F40: 0 | G40: Kempes | H40: 45145
A41: 45142 | B41: Mario López + Veck Salerno | C41: Mario López + Veck Salerno | D41: P-1 | E41: Alicate | F41: 0 | G41: Kempes | H41: 45148
...

Sheet COMPRAS
B1: compras
A3: Fecha de ingreso | B3: Descripción | C3: Cantidad | D3: N° de comprobante | E3: Observación | F3: N° Pañol
A4: 45135 | B4: latas de pintura gris espacial por 20l | C4: 15 | D4: F 1376
A5: 45143 | B5: gunates moteados blancos | C5: 48 | D5: R 15561
A6: 45143 | B6: guantes de nitrilo descartables | C6: 300 | D6: R 15561
A7: 45143 | B7: papel higienico chico | C7: 18 | D7: R 15561
A8: 45146 | B8: Blister repuesto cutter | C8: 2 | D8: S/F
A9: 45146 | B9: Cinta ducktape negra 3M | C9: 6 | D9: S/F
A10: 45146 | B10: Caja de grampa 5/16 | C10: 10 | D10: S/F
A11: 45146 | B11: 1900g Arandela plana | C11: 500 | D11: S/F
A12: 45146 | B12: Pack de bolsas 90x120 (10u) | C12: 10 | D12: S/F
A13: 45146 | B13: Detergente lavavajillas x 5L | C13: 1 | D13: S/F
A14: 45146 | B14: Lavandina x 5L | C14: 4 | D14: S/F
A15: 45146 | B15: Rachet completo 9mts | C15: 20 | D15: S/F
... A29: 45169 | B29: Llave 24 | C29: 2 | D29: R 00015711

Sheet hoja para borrar
B1: EVENTOS
A3: Fecha de retiro | B3: Responsable del evento | C3: Codigo Producto | D3: Descripción | E3: Cant | F3: Evento | G3: Fecha de devolución | H3: Observación
A4: 45138 | B4: furia | D4: alambre por kilo | E4: 1 | F4: jesus maria
A5: 45138 | B5: furia | D5: sogas con gancho 23 | E5: 1 | F5: jesus maria
A6: 45138 | B6: furia | D6: soga con gancho 25 | E6: 1 | F6: jesus maria
A7: 45138 | B7: furia | D7: arneces | E7: 20 | F7: jesus maria
A8: 45138 | B8: furia | D8: cinta metrica 50mts | E8: 1 | F8: jesus maria
A9: 45138 | B9: furia | D9: colitas de chancho | E9: 178 | F9: jesus maria
A10: 45139 | B10: furia | D10: paquetes de precintos | E10: 6 | F10: jesus maria
A11: 45139 | B11: furia | D11: guantes moteados | E11: 12 | F11: jesus maria
A12: 45141 | B12: furia | D12: rachet 1mts | E12: 2 | F12: jesus maria
A13: 45141 | B13: furia | D13: alambre por kilo | E13: 1 | F13: jesus maria
A14: 45141 | B14: furia | D14: arneces nuevos | E14: 4 | F14: jesus maria
A15: 45141 | B15: furia | D15: soguines varios | E15: 30 | F15: jesus maria
... A19: 45142 | B19: furia | D19: soga 27mts | E19: 1 | F19: jesus maria
A20: 45142 | B20: furia | D20: rocetas moviles | E20: 12 | F20: jesus maria | G20: 45146
A21: 45142 | B21: furia | D21: guantes moteados | E21: 12 | F21: jesus maria
A22: 45142 | B22: furia | D22: nivel de mano hammilton | E22: 1 | F22: jesus maria
A23: 45142 | B23: furia | D23: lubicante en aerosol | E23: 1 | F23: jesus maria | G23: 45145
A24: 45142 | B24: furia | D24: brocas para free | E24: 40 | F24: jesus maria | G24: 45145 | H24: volvieron 9
A25: 45142 | B25: furia | D25: tubo 17 para criquet | E25: 1 | F25: jesus maria
A26: 45142 | B26: furia | D26: autoperforante aleta | E26: 30 | F26: jesus maria
A27: 45142 | B27: furia | D27: precintos | E27: 4 | F27: jesus maria | G27: 45146
A29: 45141 | B29: mario y veck | D29: arneces | E29: 16 | F29: kempes
A30: 45141 | B30: mario y veck | D30: cascos | E30: 16 | F30: kempes
A31: 45141 | B31: mario y veck | D31: guantes moteados | E31: 30 | F31: kempes | G31: 45145 | H31: volvieron 10
A32: 45141 | B32: mario y veck | D32: rachet 3mts | E32: 12 | F32: kempes
A33: 45141 | B33: mario y veck | D33: atornilladora 1 bateria | E33: 2 | F33: kempes
A34: 45141 | B34: mario y veck | D34: tornillos madera (mover las cajas a descartables) | E34: 2000 | F34: kempes
A35: 45142 | B35: mario y veck | D35: hojas tricheta | E35: 1 | F35: kempes
A36: 45142 | B36: mario y veck | D36: rachet 9mts | E36: 4 | F36: kempes
A37: 45142 | B37: mario y veck | D37: caja de herramientas | E37: 1 | F37: kempes
A38: 45142 | B38: mario y veck | D38: candado con llave | E38: 1 | F38: kempes
A39: 45142 | B39: mario y veck | D39: alambre por kilo | E39: 1 | F39: kempes
A40: 45142 | B40: mario y veck | D40: cinta papel negra | E40: 2 | F40: kempes
A41: 45142 | B41: mario y veck | D41: rollo de tanza | E41: 1 | F41: kempes | G41: 45145
A42: 45142 | B42: mario y veck | D42: aerosol verde | E42: 1 | F42: kempes | G42: 45145
A43: 45142 | B43: mario y veck | D43: tinner | E43: 2 | F43: kempes | G43: 45145
A44: 45142 | B44: mario y veck | D44: cinta de embalar | E44: 3 | F44: kempes | G44: 45145
A45: 45142 | B45: mario y veck | D45: alicate | E45: 1 | F45: kempes
...

Sheet Hoja 3
A1: F | B1: PAÑOL TÉCNICO
A3: Codigo Producto | B3: Descripción | C3: Existencia
C4: Total | D4: Pañol | E4: Evento | F4: Observación | G4: N° Pañol | H4: CHECK 22/1
A5: P-1 | B5: Alicate | C5: 3 | D5: 1 | E5: 2 | F5: 2 kempes,1 aleman no devolvio | H5: 1
A6: P-2 | B6: Arnes con cola de mono | C6: 40 | D6: 0 | E6: 40 | F6: 15 kempes, 3 fausto,14 depo
A7: P-3 | B7: Arnes sin cola de mono | C7: 12 | D7: 0 | E7: 12 | F7: 0
A8: P-4 | B8: Anteojo dual transparente Libus | C8: 4 | D8: 1 | E8: 3 | F8: 1
A9: P-5 | B9: Anteojo de protección | C9: 7 | D9: 0 | E9: 7 | F9: 63
A10: P-6 | B10: Atornilladora inalámbrica DeWalt (amarilla) | C10: 5 | D10: 0 | E10: 5 | F10: 2 depo, 2 kempes,1 fausto
A11: P-7 | B11: Atornilladora inalámbrica Hamilton (naranja) | C11: 1 | D11: 0 | E11: 1 | F11: 1
A12: P-8 | B12: Abrazadera p/tubo | C12: 3 | D12: 0 | E12: 3 | F12: 3
A13: P-9 | B13: Adaptador | C13: 2 | D13: 0 | E13: 2 | F13: 0
A14: P-10 | B14: Angulo para estantería | C14: 6 | D14: 0 | E14: 6 | F14: 6
A15: P-11 | B15: Arandela | C15: 530 | D15: 0 | E15: 530
A16: P-12 | B16: Arandela grande | C16: 206 | D16: 0 | E16: 206
A17: P-13 | B17: Aspiradora pequeña | C17: 1 | D17: 0 | E17: 1 | F17: 1 | H17: 1
A18: P-14 | B18: Bandera argentina | C18: 18 | D18: 0 | E18: 18
A19: P-15 | B19: Bidon vacío cortado | C19: 3 | D19: 0 | E19: 3 | F19: 1
A20: P-16 | B20: Batería ultimate 12V 1.5 AMP Hamilton (Máquina chica) | C20: 1 | D20: 0 | E20: 1 | F20: 2
A21: P-17 | B21: Bidon vacío sin cortar | C21: 7 | D21: 0 | E21: 7 | F21: 7
A22: P-18 | B22: Bolsa de tornillos autoperforante punta fisher 8x12" x 400u | C22: 2 | D22: 0 | E22: 2
A23: P-19 | B23: Bolsa de tornillos autoperforante punta fisher x 250u | C23: 3 | D23: 0 | E23: 3
A24: P-20 | B24: Bomba centrífuga | C24: 1 | D24: 0 | E24: 1
A25: P-21 | B25: Par de botas de lluvia | C25: 11 | D25: 0 | E25: 11 | F25: 11 | H25: 13
A26: P-22 | B26: Bulón de techo | C26: 61 | D26: 0 | E26: 61
A27: P-23 | B27: Bulones de techo de tramo | C27: 275 | D27: 0 | E27: 275
A28: P-24 | B28: Bulones de techo de tramo pequeños | C28: 101 | D28: 0 | E28: 101
A29: P-25 | B29: Bulón grande de unión para techo | C29: 2 | D29: 0 | E29: 2
A30: P-26 | B30: Bulón de unión para techo | C30: 71 | D30: 0 | E30: 71
A31: P-27 | B31: Cable puente para batería reforzado (Taos) | C31: 4 | D31: 0 | E31: 4 | F31: 3 Y 1 TALLER MEC | H31: 3
A32: P-28 | B32: Chaleco refractario | C32: 13 | D32: 0 | E32: 13 | F32: 13 kempes
A33: P-29 | B33: Cable acerado | C33: 1 | D33: 0 | E33: 1 | H33: 1
A34: P-30 | B34: Cargador de batería ultimate 12v Hamilton (Máquina chica) | C34: 1 | D34: 0 | E34: 1 | F34: 1
A35: P-31 | B35: Cadena | C35: 8 | D35: 0 | E35: 8
A36: P-32 | B36: Cinta métrica 50mts (fibra de vidrio) | C36: 3 | D36: 0 | E36: 3 | F36: 4
A37: P-33 | B37: Caja de herrramientas para autolevador | C37: 3 | D37: 0 | E37: 3
A38: P-34 | B38: Casco de Altura | C38: 36 | D38: 0 | E38: 36 | F38: 20 DEPO,3 FAUS,20 KEMPES
A39: P-35 | B39: Casco de Obra/Piso | C39: 49 | D39: 0 | E39: 49
A40: P-36 | B40: Curva de techo de layher | C40: 6 | D40: 0 | E40: 6
A41: P-37 | B41: Cono naranja | C41: 2 | D41: 0 | E41: 2 | H41: 2
...
